Workbook

Sheet Guidance
B2: Al Reef Al Janoubi — System Usage Guide
B4: STEP | C4: Register Your Properties
C5: • Go to the "Property Registry" tab
C6: • Enter each unit: Unit ID, Building, Floor, Unit Type, Size, Monthly Rent
C7: • Municipality Fee auto-calculates at 5% of Monthly Rent
C8: • Set Status: Rented, Vacant, Under Maintenance, or Reserved
C9: • For rented units, fill Current Tenant, Contract Start, and Contract End
B11: STEP | C11: Set Up Tenant Profiles
C12: • Go to the "Tenants" tab
C13: • Enter tenant details: Name, Phone, Email, Unit ID
C14: • Monthly Rent auto-fills from Property Registry via VLOOKUP
C15: • Fill in Lease Start, Lease End, Security Deposit, Payment Method
C16: • Contract Duration auto-calculates
C17: • LEASE END ALERTS: Cells turn RED if lease expired, AMBER if within 30 days of expiry
B19: STEP | C19: Track Monthly Rent Collection
C20: • Go to "Rent Collection" at the start of each month
C21: • Enter each rented unit's payment details
C22: • Outstanding and Payment Status auto-calculate
C23: • DAYS LATE auto-calculates for unpaid/partial payments
C24: • Use the Collection Summary at the bottom to track overall performance
B26: STEP | C26: Monitor Payment Alerts (By the 5th of Each Month) ★ CRITICAL
C27: • This is the CRITICAL step for cash flow management
C28: • On or before the 5th of each month, review "Rent Collection" tab
C29: • Any tenant showing "Unpaid" or "Partial" status should be listed in "Payment Alerts"
C30: • Copy their Unit ID, Name, Phone, Rent, and Due Date to the Payment Alerts tab
C31: • Then MANUALLY send SMS, WhatsApp, or call each tenant
C32: • Mark "Contacted?" as "Yes" after reaching out
C33: • Set a Follow-up Date for a second check
C34: • IMPORTANT: This system does NOT send SMS automatically. It is a tracking tool that tells you WHO to contact and WHEN. You must manually reach out to tenants using their phone numbers listed here.
B36: STEP | C36: Log Maintenance Requests
C37: • Go to "Maintenance" tab whenever a repair is needed
C38: • Log the request with Unit ID, Category, Description, Priority
C39: • Track Estimated vs Actual Cost
C40: • Status options: Open, In Progress, Completed, Cancelled
B42: STEP | C42: Record Operating Expenses
C43: • Go to "Expenses" tab regularly
C44: • Log ALL expenses: Manpower, Municipality Fees, Maintenance, Leasing, Insurance, Utilities, etc.
C45: • Mark recurring expenses for easy identification
C46: • The Expense Summary at the bottom auto-calculates totals by category
B48: STEP | C48: Review Revenue & Profit
...

Sheet Dashboard
B2: Al Reef Al Janoubi — Real Estate Dashboard
B5: =IFERROR(COUNTA('Property Registry'!B5:B154)-COUNTBLANK('Property Registry'!B5:B154),0) | D5: =IFERROR(COUNTIF('Property Registry'!I5:I154,"Rented"),0) | F5: =IFERROR(COUNTIF('Property Registry'!I5:I154,"Vacant"),0) | H5: =IFERROR(COUNTIF('Property Registry'!I5:I154,"Rented")/COUNTA('Property Registry'!B5:B154),0) | J5: =IFERROR(SUM('Property Registry'!G5:G154),0) | L5: =IFERROR('Profit & Loss'!C32,0)
B6: Total Units | D6: Occupied Units | F6: Vacant Units | H6: Occupancy Rate | J6: Monthly Revenue | L6: Net Profit
B8: Building | C8: Occupancy Rate
B9: Building A | C9: =IFERROR(COUNTIF('Property Registry'!C5:C154,"Building A")/COUNTIF('Property Registry'!C5:C154,"Building A"),0)
B10: Building B | C10: =IFERROR(COUNTIF('Property Registry'!C5:C154,"Building B")/COUNTIF('Property Registry'!C5:C154,"Building B"),0)
B11: Building C | C11: =IFERROR(COUNTIF('Property Registry'!C5:C154,"Building C")/COUNTIF('Property Registry'!C5:C154,"Building C"),0)
B12: Building D | C12: =IFERROR(COUNTIF('Property Registry'!C5:C154,"Building D")/COUNTIF('Property Registry'!C5:C154,"Building D"),0)
B15: Month | C15: Revenue
B16: Jan | C16: =IFERROR('Revenue Analysis'!C5,0)
B17: Feb | C17: =IFERROR('Revenue Analysis'!C6,0)
B18: Mar | C18: =IFERROR('Revenue Analysis'!C7,0)
B19: Apr | C19: =IFERROR('Revenue Analysis'!C8,0)
B20: May | C20: =IFERROR('Revenue Analysis'!C9,0)
B21: Jun | C21: =IFERROR('Revenue Analysis'!C10,0)
B22: Jul | C22: =IFERROR('Revenue Analysis'!C11,0)
B23: Aug | C23: =IFERROR('Revenue Analysis'!C12,0)
B24: Sep | C24: =IFERROR('Revenue Analysis'!C13,0)
B25: Oct | C25: =IFERROR('Revenue Analysis'!C14,0)
B26: Nov | C26: =IFERROR('Revenue Analysis'!C15,0)
B27: Dec | C27: =IFERROR('Revenue Analysis'!C16,0)
B29: Category | C29: Amount
B30: Manpower/Staff | C30: =IFERROR(SUMPRODUCT(('Expenses'!C5:C304="Manpower/Staff")*('Expenses'!E5:E304)),0)
B31: Municipality Fees | C31: =IFERROR(SUMPRODUCT(('Expenses'!C5:C304="Municipality Fees")*('Expenses'!E5:E304)),0)
B32: Maintenance | C32: =IFERROR(SUMPRODUCT(('Expenses'!C5:C304="Maintenance")*('Expenses'!E5:E304)),0)
B33: Leasing Commission | C33: =IFERROR(SUMPRODUCT(('Expenses'!C5:C304="Leasing Commission")*('Expenses'!E5:E304)),0)
B34: Insurance | C34: =IFERROR(SUMPRODUCT(('Expenses'!C5:C304="Insurance")*('Expenses'!E5:E304)),0)
B35: Utilities | C35: =IFERROR(SUMPRODUCT(('Expenses'!C5:C304="Utilities")*('Expenses'!E5:E304)),0)
B36: Marketing | C36: =IFERROR(SUMPRODUCT(('Expenses'!C5:C304="Marketing")*('Expenses'!E5:E304)),0)
B37: Legal | C37: =IFERROR(SUMPRODUCT(('Expenses'!C5:C304="Legal")*('Expenses'!E5:E304)),0)
B38: Cleaning | C38: =IFERROR(SUMPRODUCT(('Expenses'!C5:C304="Cleaning")*('Expenses'!E5:E304)),0)
B39: Security | C39: =IFERROR(SUMPRODUCT(('Expenses'!C5:C304="Security")*('Expenses'!E5:E304)),0)
B40: Pest Control | C40: =IFERROR(SUMPRODUCT(('Expenses'!C5:C304="Pest Control")*('Expenses'!E5:E304)),0)
B41: Elevator Service | C41: =IFERROR(SUMPRODUCT(('Expenses'!C5:C304="Elevator Service")*('Expenses'!E5:E304)),0)
B42: Other | C42: =IFERROR(SUMPRODUCT(('Expenses'!C5:C304="Other")*('Expenses'!E5:E304)),0)
B44: Unit Type | C44: Count
B45: Studio | C45: =IFERROR(COUNTIF('Property Registry'!E5:E154,"Studio"),0)
B46: 1 Bedroom | C46: =IFERROR(COUNTIF('Property Registry'!E5:E154,"1 Bedroom"),0)
B47: 2 Bedroom | C47: =IFERROR(COUNTIF('Property Registry'!E5:E154,"2 Bedroom"),0)
B48: 3 Bedroom | C48: =IFERROR(COUNTIF('Property Registry'!E5:E154,"3 Bedroom"),0)
...

Sheet Property Registry
B2: Property Registry — Unit Master List
B4: Unit ID | C4: Building | D4: Floor | E4: Unit Type | F4: Size (sqft) | G4: Monthly Rent (AED) | H4: Municipality Fee (AED) | I4: Status | J4: Current Tenant | K4: Contract Start | L4: Contract End | M4: Notes
H5: =IFERROR(G5*0.05,0)
H6: =IFERROR(G6*0.05,0)
H7: =IFERROR(G7*0.05,0)
H8: =IFERROR(G8*0.05,0)
H9: =IFERROR(G9*0.05,0)
H10: =IFERROR(G10*0.05,0)
H11: =IFERROR(G11*0.05,0)
H12: =IFERROR(G12*0.05,0)
H13: =IFERROR(G13*0.05,0)
H14: =IFERROR(G14*0.05,0)
H15: =IFERROR(G15*0.05,0)
H16: =IFERROR(G16*0.05,0)
... H154: =IFERROR(G154*0.05,0)
B155: TOTALS | F155: =IFERROR(SUM(F5:F154),0) | G155: =IFERROR(SUM(G5:G154),0) | H155: =IFERROR(SUM(H5:H154),0) | I155: =IFERROR(COUNTA(B5:B154)-COUNTBLANK(B5:B154),0)&" units"

Sheet Tenants
B2: Tenant Directory
B4: Tenant ID | C4: Tenant Name | D4: Phone | E4: Email | F4: Unit ID | G4: Unit Type | H4: Lease Start | I4: Lease End | J4: Contract Duration (months) | K4: Monthly Rent | L4: Security Deposit | M4: Payment Method | N4: Nationality | O4: Employer | P4: Emergency Contact
J5: =IFERROR((I5-H5)/30,0) | K5: =IFERROR(VLOOKUP(F5,'Property Registry'!B5:G154,6,FALSE),0)
J6: =IFERROR((I6-H6)/30,0) | K6: =IFERROR(VLOOKUP(F6,'Property Registry'!B5:G154,6,FALSE),0)
J7: =IFERROR((I7-H7)/30,0) | K7: =IFERROR(VLOOKUP(F7,'Property Registry'!B5:G154,6,FALSE),0)
J8: =IFERROR((I8-H8)/30,0) | K8: =IFERROR(VLOOKUP(F8,'Property Registry'!B5:G154,6,FALSE),0)
J9: =IFERROR((I9-H9)/30,0) | K9: =IFERROR(VLOOKUP(F9,'Property Registry'!B5:G154,6,FALSE),0)
J10: =IFERROR((I10-H10)/30,0) | K10: =IFERROR(VLOOKUP(F10,'Property Registry'!B5:G154,6,FALSE),0)
J11: =IFERROR((I11-H11)/30,0) | K11: =IFERROR(VLOOKUP(F11,'Property Registry'!B5:G154,6,FALSE),0)
J12: =IFERROR((I12-H12)/30,0) | K12: =IFERROR(VLOOKUP(F12,'Property Registry'!B5:G154,6,FALSE),0)
J13: =IFERROR((I13-H13)/30,0) | K13: =IFERROR(VLOOKUP(F13,'Property Registry'!B5:G154,6,FALSE),0)
J14: =IFERROR((I14-H14)/30,0) | K14: =IFERROR(VLOOKUP(F14,'Property Registry'!B5:G154,6,FALSE),0)
J15: =IFERROR((I15-H15)/30,0) | K15: =IFERROR(VLOOKUP(F15,'Property Registry'!B5:G154,6,FALSE),0)
J16: =IFERROR((I16-H16)/30,0) | K16: =IFERROR(VLOOKUP(F16,'Property Registry'!B5:G154,6,FALSE),0)
J17: =IFERROR((I17-H17)/30,0) | K17: =IFERROR(VLOOKUP(F17,'Property Registry'!B5:G154,6,FALSE),0)
J18: =IFERROR((I18-H18)/30,0) | K18: =IFERROR(VLOOKUP(F18,'Property Registry'!B5:G154,6,FALSE),0)
J19: =IFERROR((I19-H19)/30,0) | K19: =IFERROR(VLOOKUP(F19,'Property Registry'!B5:G154,6,FALSE),0)
J20: =IFERROR((I20-H20)/30,0) | K20: =IFERROR(VLOOKUP(F20,'Property Registry'!B5:G154,6,FALSE),0)
J21: =IFERROR((I21-H21)/30,0) | K21: =IFERROR(VLOOKUP(F21,'Property Registry'!B5:G154,6,FALSE),0)
J22: =IFERROR((I22-H22)/30,0) | K22: =IFERROR(VLOOKUP(F22,'Property Registry'!B5:G154,6,FALSE),0)
J23: =IFERROR((I23-H23)/30,0) | K23: =IFERROR(VLOOKUP(F23,'Property Registry'!B5:G154,6,FALSE),0)
J24: =IFERROR((I24-H24)/30,0) | K24: =IFERROR(VLOOKUP(F24,'Property Registry'!B5:G154,6,FALSE),0)
J25: =IFERROR((I25-H25)/30,0) | K25: =IFERROR(VLOOKUP(F25,'Property Registry'!B5:G154,6,FALSE),0)
J26: =IFERROR((I26-H26)/30,0) | K26: =IFERROR(VLOOKUP(F26,'Property Registry'!B5:G154,6,FALSE),0)
J27: =IFERROR((I27-H27)/30,0) | K27: =IFERROR(VLOOKUP(F27,'Property Registry'!B5:G154,6,FALSE),0)
J28: =IFERROR((I28-H28)/30,0) | K28: =IFERROR(VLOOKUP(F28,'Property Registry'!B5:G154,6,FALSE),0)
J29: =IFERROR((I29-H29)/30,0) | K29: =IFERROR(VLOOKUP(F29,'Property Registry'!B5:G154,6,FALSE),0)
J30: =IFERROR((I30-H30)/30,0) | K30: =IFERROR(VLOOKUP(F30,'Property Registry'!B5:G154,6,FALSE),0)
J31: =IFERROR((I31-H31)/30,0) | K31: =IFERROR(VLOOKUP(F31,'Property Registry'!B5:G154,6,FALSE),0)
J32: =IFERROR((I32-H32)/30,0) | K32: =IFERROR(VLOOKUP(F32,'Property Registry'!B5:G154,6,FALSE),0)
J33: =IFERROR((I33-H33)/30,0) | K33: =IFERROR(VLOOKUP(F33,'Property Registry'!B5:G154,6,FALSE),0)
J34: =IFERROR((I34-H34)/30,0) | K34: =IFERROR(VLOOKUP(F34,'Property Registry'!B5:G154,6,FALSE),0)
J35: =IFERROR((I35-H35)/30,0) | K35: =IFERROR(VLOOKUP(F35,'Property Registry'!B5:G154,6,FALSE),0)
J36: =IFERROR((I36-H36)/30,0) | K36: =IFERROR(VLOOKUP(F36,'Property Registry'!B5:G154,6,FALSE),0)
J37: =IFERROR((I37-H37)/30,0) | K37: =IFERROR(VLOOKUP(F37,'Property Registry'!B5:G154,6,FALSE),0)
J38: =IFERROR((I38-H38)/30,0) | K38: =IFERROR(VLOOKUP(F38,'Property Registry'!B5:G154,6,FALSE),0)
J39: =IFERROR((I39-H39)/30,0) | K39: =IFERROR(VLOOKUP(F39,'Property Registry'!B5:G154,6,FALSE),0)
J40: =IFERROR((I40-H40)/30,0) | K40: =IFERROR(VLOOKUP(F40,'Property Registry'!B5:G154,6,FALSE),0)
J41: =IFERROR((I41-H41)/30,0) | K41: =IFERROR(VLOOKUP(F41,'Property Registry'!B5:G154,6,FALSE),0)
J42: =IFERROR((I42-H42)/30,0) | K42: =IFERROR(VLOOKUP(F42,'Property Registry'!B5:G154,6,FALSE),0)
...

Sheet Rent Collection
B2: Rent Collection — [Month/Year]
B4: Unit ID | C4: Tenant Name | D4: Monthly Rent | E4: Due Date | F4: Payment Date | G4: Amount Paid | H4: Outstanding | I4: Payment Status | J4: Days Late | K4: Payment Method | L4: Receipt # | M4: Notes
H5: =IFERROR(D5-G5,0) | I5: =IF(G5>=D5,"Paid",IF(G5>0,"Partial","Unpaid")) | J5: =IFERROR(IF(I5="Unpaid",MAX(0,TODAY()-E5),IF(I5="Partial",MAX(0,TODAY()-E5),0)),0)
H6: =IFERROR(D6-G6,0) | I6: =IF(G6>=D6,"Paid",IF(G6>0,"Partial","Unpaid")) | J6: =IFERROR(IF(I6="Unpaid",MAX(0,TODAY()-E6),IF(I6="Partial",MAX(0,TODAY()-E6),0)),0)
H7: =IFERROR(D7-G7,0) | I7: =IF(G7>=D7,"Paid",IF(G7>0,"Partial","Unpaid")) | J7: =IFERROR(IF(I7="Unpaid",MAX(0,TODAY()-E7),IF(I7="Partial",MAX(0,TODAY()-E7),0)),0)
H8: =IFERROR(D8-G8,0) | I8: =IF(G8>=D8,"Paid",IF(G8>0,"Partial","Unpaid")) | J8: =IFERROR(IF(I8="Unpaid",MAX(0,TODAY()-E8),IF(I8="Partial",MAX(0,TODAY()-E8),0)),0)
H9: =IFERROR(D9-G9,0) | I9: =IF(G9>=D9,"Paid",IF(G9>0,"Partial","Unpaid")) | J9: =IFERROR(IF(I9="Unpaid",MAX(0,TODAY()-E9),IF(I9="Partial",MAX(0,TODAY()-E9),0)),0)
H10: =IFERROR(D10-G10,0) | I10: =IF(G10>=D10,"Paid",IF(G10>0,"Partial","Unpaid")) | J10: =IFERROR(IF(I10="Unpaid",MAX(0,TODAY()-E10),IF(I10="Partial",MAX(0,TODAY()-E10),0)),0)
H11: =IFERROR(D11-G11,0) | I11: =IF(G11>=D11,"Paid",IF(G11>0,"Partial","Unpaid")) | J11: =IFERROR(IF(I11="Unpaid",MAX(0,TODAY()-E11),IF(I11="Partial",MAX(0,TODAY()-E11),0)),0)
H12: =IFERROR(D12-G12,0) | I12: =IF(G12>=D12,"Paid",IF(G12>0,"Partial","Unpaid")) | J12: =IFERROR(IF(I12="Unpaid",MAX(0,TODAY()-E12),IF(I12="Partial",MAX(0,TODAY()-E12),0)),0)
H13: =IFERROR(D13-G13,0) | I13: =IF(G13>=D13,"Paid",IF(G13>0,"Partial","Unpaid")) | J13: =IFERROR(IF(I13="Unpaid",MAX(0,TODAY()-E13),IF(I13="Partial",MAX(0,TODAY()-E13),0)),0)
H14: =IFERROR(D14-G14,0) | I14: =IF(G14>=D14,"Paid",IF(G14>0,"Partial","Unpaid")) | J14: =IFERROR(IF(I14="Unpaid",MAX(0,TODAY()-E14),IF(I14="Partial",MAX(0,TODAY()-E14),0)),0)
H15: =IFERROR(D15-G15,0) | I15: =IF(G15>=D15,"Paid",IF(G15>0,"Partial","Unpaid")) | J15: =IFERROR(IF(I15="Unpaid",MAX(0,TODAY()-E15),IF(I15="Partial",MAX(0,TODAY()-E15),0)),0)
H16: =IFERROR(D16-G16,0) | I16: =IF(G16>=D16,"Paid",IF(G16>0,"Partial","Unpaid")) | J16: =IFERROR(IF(I16="Unpaid",MAX(0,TODAY()-E16),IF(I16="Partial",MAX(0,TODAY()-E16),0)),0)
... H154: =IFERROR(D154-G154,0) | I154: =IF(G154>=D154,"Paid",IF(G154>0,"Partial","Unpaid")) | J154: =IFERROR(IF(I154="Unpaid",MAX(0,TODAY()-E154),IF(I154="Partial",MAX(0,TODAY()-E154),0)),0)
B157: COLLECTION SUMMARY
B158: Total Expected Rent | D158: =IFERROR(SUM(D5:D154),0)
B159: Total Collected | D159: =IFERROR(SUM(G5:G154),0)
B160: Total Outstanding | D160: =IFERROR(SUM(H5:H154),0)
B161: Collection Rate % | D161: =IFERROR(SUM(G5:G154)/SUM(D5:D154),0)
B162: # Paid | D162: =IFERROR(COUNTIF(I5:I154,"Paid"),0)
B163: # Partial | D163: =IFERROR(COUNTIF(I5:I154,"Partial"),0)
B164: # Unpaid | D164: =IFERROR(COUNTIF(I5:I154,"Unpaid"),0)

Sheet Payment Alerts
B2: Payment Alerts — Tenants Who Haven't Paid by the 5th
B3: IMPORTANT: This sheet does NOT send SMS automatically. It is a tracking tool. By the 5th of each month, review the Rent Collection sheet for unpaid tenants, copy their details here, then manually send SMS/WhatsApp/call them. Mark 'Contacted' as Yes once done.
B4: Unit ID | C4: Tenant Name | D4: Phone | E4: Monthly Rent | F4: Due Date | G4: Days Late | H4: Contacted? | I4: Follow-up Date | J4: Notes

Sheet Maintenance
B2: Maintenance Log & Cost Tracker
B4: Request ID | C4: Date | D4: Unit ID | E4: Category | F4: Description | G4: Vendor/Technician | H4: Estimated Cost | I4: Actual Cost | J4: Status | K4: Priority | L4: Completion Date | M4: Notes
B205: TOTALS | H205: =IFERROR(SUM(H5:H204),0) | I205: =IFERROR(SUM(I5:I204),0) | J205: Variance: | K205: =IFERROR(H205-I205,0)

Sheet Expenses
B2: Operating Expenses — Monthly Tracker
B4: Date | C4: Category | D4: Description | E4: Amount (AED) | F4: Payment Method | G4: Vendor/Payee | H4: Invoice # | I4: Recurring? | J4: Building | K4: Notes
B307: EXPENSE SUMMARY BY CATEGORY
B308: Category | C308: Total (AED)
B309: Manpower/Staff | C309: =IFERROR(SUMPRODUCT((C5:C304="Manpower/Staff")*(E5:E304)),0)
B310: Municipality Fees | C310: =IFERROR(SUMPRODUCT((C5:C304="Municipality Fees")*(E5:E304)),0)
B311: Maintenance | C311: =IFERROR(SUMPRODUCT((C5:C304="Maintenance")*(E5:E304)),0)
B312: Leasing Commission | C312: =IFERROR(SUMPRODUCT((C5:C304="Leasing Commission")*(E5:E304)),0)
B313: Insurance | C313: =IFERROR(SUMPRODUCT((C5:C304="Insurance")*(E5:E304)),0)
B314: Utilities | C314: =IFERROR(SUMPRODUCT((C5:C304="Utilities")*(E5:E304)),0)
B315: Marketing | C315: =IFERROR(SUMPRODUCT((C5:C304="Marketing")*(E5:E304)),0)
B316: Legal | C316: =IFERROR(SUMPRODUCT((C5:C304="Legal")*(E5:E304)),0)
B317: Cleaning | C317: =IFERROR(SUMPRODUCT((C5:C304="Cleaning")*(E5:E304)),0)
B318: Security | C318: =IFERROR(SUMPRODUCT((C5:C304="Security")*(E5:E304)),0)
B319: Pest Control | C319: =IFERROR(SUMPRODUCT((C5:C304="Pest Control")*(E5:E304)),0)
B320: Elevator Service | C320: =IFERROR(SUMPRODUCT((C5:C304="Elevator Service")*(E5:E304)),0)
B321: Other | C321: =IFERROR(SUMPRODUCT((C5:C304="Other")*(E5:E304)),0)
B322: GRAND TOTAL | C322: =IFERROR(SUM(C309:C321),0)

Sheet Revenue Analysis
B2: Revenue Analysis — Annual Overview
B4: Revenue Line Item | C4: Jan | D4: Feb | E4: Mar | F4: Apr | G4: May | H4: Jun | I4: Jul | J4: Aug | K4: Sep | L4: Oct | M4: Nov | N4: Dec | O4: Annual Total
B5: Rental Income | C5: =IFERROR(SUMPRODUCT(('Property Registry'!I5:I154="Rented")*('Property Registry'!G5:G154)),0) | D5: =IFERROR(SUMPRODUCT(('Property Registry'!I5:I154="Rented")*('Property Registry'!G5:G154)),0) | E5: =IFERROR(SUMPRODUCT(('Property Registry'!I5:I154="Rented")*('Property Registry'!G5:G154)),0) | F5: =IFERROR(SUMPRODUCT(('Property Registry'!I5:I154="Rented")*('Property Registry'!G5:G154)),0) | G5: =IFERROR(SUMPRODUCT(('Property Registry'!I5:I154="Rented")*('Property Registry'!G5:G154)),0) | H5: =IFERROR(SUMPRODUCT(('Property Registry'!I5:I154="Rented")*('Property Registry'!G5:G154)),0) | I5: =IFERROR(SUMPRODUCT(('Property Registry'!I5:I154="Rented")*('Property Registry'!G5:G154)),0) | J5: =IFERROR(SUMPRODUCT(('Property Registry'!I5:I154="Rented")*('Property Registry'!G5:G154)),0) | K5: =IFERROR(SUMPRODUCT(('Property Registry'!I5:I154="Rented")*('Property Registry'!G5:G154)),0) | L5: =IFERROR(SUMPRODUCT(('Property Registry'!I5:I154="Rented")*('Property Registry'!G5:G154)),0) | M5: =IFERROR(SUMPRODUCT(('Property Registry'!I5:I154="Rented")*('Property Registry'!G5:G154)),0) | N5: =IFERROR(SUMPRODUCT(('Property Registry'!I5:I154="Rented")*('Property Registry'!G5:G154)),0) | O5: =IFERROR(SUM(C5:N5),0)
B6: Municipality Fees Collected | C6: =IFERROR(SUM('Property Registry'!H5:H154),0) | D6: =IFERROR(SUM('Property Registry'!H5:H154),0) | E6: =IFERROR(SUM('Property Registry'!H5:H154),0) | F6: =IFERROR(SUM('Property Registry'!H5:H154),0) | G6: =IFERROR(SUM('Property Registry'!H5:H154),0) | H6: =IFERROR(SUM('Property Registry'!H5:H154),0) | I6: =IFERROR(SUM('Property Registry'!H5:H154),0) | J6: =IFERROR(SUM('Property Registry'!H5:H154),0) | K6: =IFERROR(SUM('Property Registry'!H5:H154),0) | L6: =IFERROR(SUM('Property Registry'!H5:H154),0) | M6: =IFERROR(SUM('Property Registry'!H5:H154),0) | N6: =IFERROR(SUM('Property Registry'!H5:H154),0) | O6: =IFERROR(SUM(C6:N6),0)
B7: Other Income | C7: 0 | D7: 0 | E7: 0 | F7: 0 | G7: 0 | H7: 0 | I7: 0 | J7: 0 | K7: 0 | L7: 0 | M7: 0 | N7: 0 | O7: =IFERROR(SUM(C7:N7),0)
B8: GROSS REVENUE | C8: =IFERROR(SUM(C5:C7),0) | D8: =IFERROR(SUM(D5:D7),0) | E8: =IFERROR(SUM(E5:E7),0) | F8: =IFERROR(SUM(F5:F7),0) | G8: =IFERROR(SUM(G5:G7),0) | H8: =IFERROR(SUM(H5:H7),0) | I8: =IFERROR(SUM(I5:I7),0) | J8: =IFERROR(SUM(J5:J7),0) | ... O8: =IFERROR(SUM(O5:O7),0)
B9: Less: Vacancy Loss | C9: =IFERROR(-SUMPRODUCT(('Property Registry'!I5:I154="Vacant")*('Property Registry'!G5:G154)),0) | D9: =IFERROR(-SUMPRODUCT(('Property Registry'!I5:I154="Vacant")*('Property Registry'!G5:G154)),0) | E9: =IFERROR(-SUMPRODUCT(('Property Registry'!I5:I154="Vacant")*('Property Registry'!G5:G154)),0) | F9: =IFERROR(-SUMPRODUCT(('Property Registry'!I5:I154="Vacant")*('Property Registry'!G5:G154)),0) | G9: =IFERROR(-SUMPRODUCT(('Property Registry'!I5:I154="Vacant")*('Property Registry'!G5:G154)),0) | H9: =IFERROR(-SUMPRODUCT(('Property Registry'!I5:I154="Vacant")*('Property Registry'!G5:G154)),0) | I9: =IFERROR(-SUMPRODUCT(('Property Registry'!I5:I154="Vacant")*('Property Registry'!G5:G154)),0) | J9: =IFERROR(-SUMPRODUCT(('Property Registry'!I5:I154="Vacant")*('Property Registry'!G5:G154)),0) | K9: =IFERROR(-SUMPRODUCT(('Property Registry'!I5:I154="Vacant")*('Property Registry'!G5:G154)),0) | L9: =IFERROR(-SUMPRODUCT(('Property Registry'!I5:I154="Vacant")*('Property Registry'!G5:G154)),0) | M9: =IFERROR(-SUMPRODUCT(('Property Registry'!I5:I154="Vacant")*('Property Registry'!G5:G154)),0) | N9: =IFERROR(-SUMPRODUCT(('Property Registry'!I5:I154="Vacant")*('Property Registry'!G5:G154)),0) | O9: =IFERROR(SUM(C9:N9),0)
B10: Less: Bad Debt/Unpaid | C10: =IFERROR(-SUM('Rent Collection'!H5:H154),0) | D10: =IFERROR(-SUM('Rent Collection'!H5:H154),0) | E10: =IFERROR(-SUM('Rent Collection'!H5:H154),0) | F10: =IFERROR(-SUM('Rent Collection'!H5:H154),0) | G10: =IFERROR(-SUM('Rent Collection'!H5:H154),0) | H10: =IFERROR(-SUM('Rent Collection'!H5:H154),0) | I10: =IFERROR(-SUM('Rent Collection'!H5:H154),0) | J10: =IFERROR(-SUM('Rent Collection'!H5:H154),0) | K10: =IFERROR(-SUM('Rent Collection'!H5:H154),0) | L10: =IFERROR(-SUM('Rent Collection'!H5:H154),0) | M10: =IFERROR(-SUM('Rent Collection'!H5:H154),0) | N10: =IFERROR(-SUM('Rent Collection'!H5:H154),0) | O10: =IFERROR(SUM(C10:N10),0)
B11: NET REVENUE | C11: =IFERROR(C8+C9+C10,0) | D11: =IFERROR(D8+D9+D10,0) | E11: =IFERROR(E8+E9+E10,0) | F11: =IFERROR(F8+F9+F10,0) | G11: =IFERROR(G8+G9+G10,0) | H11: =IFERROR(H8+H9+H10,0) | I11: =IFERROR(I8+I9+I10,0) | J11: =IFERROR(J8+J9+J10,0) | ... O11: =IFERROR(O8+O9+O10,0)
B14: Category | C14: Amount
B15: Gross Revenue | C15: =O8
B16: Vacancy Loss | C16: =O9
B17: Bad Debt | C17: =O10
B18: Net Revenue | C18: =O11

Sheet Profit & Loss
B2: Profit & Loss Statement — Al Reef Al Janoubi
B5: REVENUE
B6: Rental Income | C6: =IFERROR('Revenue Analysis'!O5,0)
B7: Other Income | C7: =IFERROR('Revenue Analysis'!O7,0)
B8: Total Revenue | C8: =IFERROR(SUM(C6:C7),0)
B10: COST OF OPERATIONS
B11: Manpower/Staff Costs | C11: =IFERROR(SUMPRODUCT(('Expenses'!C5:C304="Manpower/Staff")*('Expenses'!E5:E304)),0)
B12: Maintenance Costs | C12: =IFERROR(SUMPRODUCT(('Expenses'!C5:C304="Maintenance")*('Expenses'!E5:E304)),0)
B13: Municipality Fees | C13: =IFERROR(SUMPRODUCT(('Expenses'!C5:C304="Municipality Fees")*('Expenses'!E5:E304)),0)
B14: Leasing Commissions | C14: =IFERROR(SUMPRODUCT(('Expenses'!C5:C304="Leasing Commission")*('Expenses'!E5:E304)),0)
B15: Insurance | C15: =IFERROR(SUMPRODUCT(('Expenses'!C5:C304="Insurance")*('Expenses'!E5:E304)),0)
B16: Utilities | C16: =IFERROR(SUMPRODUCT(('Expenses'!C5:C304="Utilities")*('Expenses'!E5:E304)),0)
B17: Total Cost of Operations | C17: =IFERROR(SUM(C11:C16),0)
B19: Gross Profit | C19: =IFERROR(C8-C17,0)
B20: Gross Margin % | C20: =IFERROR(C19/C8,0)
B22: OPERATING EXPENSES
B23: Marketing | C23: =IFERROR(SUMPRODUCT(('Expenses'!C5:C304="Marketing")*('Expenses'!E5:E304)),0)
B24: Legal & Professional | C24: =IFERROR(SUMPRODUCT(('Expenses'!C5:C304="Legal")*('Expenses'!E5:E304)),0)
B25: Cleaning & Security | C25: =IFERROR(SUMPRODUCT(('Expenses'!C5:C304="Cleaning")*('Expenses'!E5:E304)),0)
B26: Security Costs | C26: =IFERROR(SUMPRODUCT(('Expenses'!C5:C304="Security")*('Expenses'!E5:E304)),0)
B27: Pest Control | C27: =IFERROR(SUMPRODUCT(('Expenses'!C5:C304="Pest Control")*('Expenses'!E5:E304)),0)
B28: Elevator Service | C28: =IFERROR(SUMPRODUCT(('Expenses'!C5:C304="Elevator Service")*('Expenses'!E5:E304)),0)
B29: Other | C29: =IFERROR(SUMPRODUCT(('Expenses'!C5:C304="Other")*('Expenses'!E5:E304)),0)
B30: Total Operating Expenses | C30: =IFERROR(SUM(C23:C29),0)
B32: Net Profit | C32: =IFERROR(C19-C30,0)
B33: Net Margin % | C33: =IFERROR(C32/C8,0)
B36: WATERFALL SUMMARY
B37: Total Revenue | C37: =C8
B38: Less: Cost of Operations | C38: =-C17
B39: Gross Profit | C39: =C19
B40: Less: Operating Expenses | C40: =-C30
B41: Net Profit | C41: =C32

Sheet Contract Tracker
B2: Lease Contract Tracker
B4: Unit ID | C4: Tenant | D4: Phone | E4: Building | F4: Unit Type | G4: Lease Start | H4: Lease End | I4: Days Until Expiry | J4: Renewal Status | K4: New Rent (AED) | L4: Notes
I5: =IFERROR(MAX(0,H5-TODAY()),0)
I6: =IFERROR(MAX(0,H6-TODAY()),0)
I7: =IFERROR(MAX(0,H7-TODAY()),0)
I8: =IFERROR(MAX(0,H8-TODAY()),0)
I9: =IFERROR(MAX(0,H9-TODAY()),0)
I10: =IFERROR(MAX(0,H10-TODAY()),0)
I11: =IFERROR(MAX(0,H11-TODAY()),0)
I12: =IFERROR(MAX(0,H12-TODAY()),0)
I13: =IFERROR(MAX(0,H13-TODAY()),0)
I14: =IFERROR(MAX(0,H14-TODAY()),0)
I15: =IFERROR(MAX(0,H15-TODAY()),0)
I16: =IFERROR(MAX(0,H16-TODAY()),0)
... I154: =IFERROR(MAX(0,H154-TODAY()),0)
B157: CONTRACT SUMMARY
B158: # Active | D158: =IFERROR(COUNTIF(J5:J154,"Active"),0)
B159: # Expiring Soon | D159: =IFERROR(COUNTIF(J5:J154,"Expiring Soon"),0)
B160: # Expired | D160: =IFERROR(COUNTIF(J5:J154,"Expired"),0)
B161: # Renewed | D161: =IFERROR(COUNTIF(J5:J154,"Renewed"),0)
B162: # Not Renewed | D162: =IFERROR(COUNTIF(J5:J154,"Not Renewed"),0)
B163: # Total | D163: =IFERROR(COUNTA(B5:B154)-COUNTBLANK(B5:B154),0)
