Workbook

Sheet Sales Entry
B2: Sales Entry — Al Noor Supermarket
B4: Date | C4: Invoice # | D4: Item/Service | E4: Category | F4: Qty | G4: Unit Price | H4: Total | I4: Payment Method | J4: Staff Name | K4: Customer Name | L4: Notes
B5: 45689 | C5: INV-1001 | D5: Biscuits (200g) | E5: Snacks | F5: 3 | G5: 4 | H5: 12 | I5: Cash | J5: Ahmed | K5: Walk-in
B6: 45689 | C6: INV-1002 | D6: Butter (200g) | E6: Dairy | F6: 4 | G6: 11 | H6: 44 | I6: Cash | J6: Ahmed | K6: Regular Customer
B7: 45689 | C7: INV-1003 | D7: Tea (25 bags) | E7: Beverages | F7: 5 | G7: 10 | H7: 50 | I7: Cash | J7: Fatima | K7: Online Customer
B8: 45689 | C8: INV-1003 | D8: Chocolate Bar | E8: Snacks | F8: 5 | G8: 7 | H8: 35 | I8: Card | J8: Fatima | K8: Walk-in | L8: Bulk
B9: 45689 | C9: INV-1004 | D9: Canned Beans | E9: Grains | F9: 1 | G9: 3 | H9: 3 | I9: Cash | J9: Khalid | K9: Regular Customer
B10: 45689 | C10: INV-1004 | D10: Pasta (500g) | E10: Grains | F10: 2 | G10: 4 | H10: 8 | I10: Cash | J10: Khalid | K10: Regular Customer
B11: 45689 | C11: INV-1004 | D11: Bread | E11: Bakery | F11: 4 | G11: 5 | H11: 20 | I11: Cash | J11: Khalid | K11: Regular Customer
B12: 45689 | C12: INV-1005 | D12: Canned Beans | E12: Grains | F12: 1 | G12: 3 | H12: 3 | I12: Online | J12: Khalid | K12: Regular Customer | L12: Express
B13: 45689 | C13: INV-1005 | D13: Eggs (12pc) | E13: Dairy | F13: 4 | G13: 12 | H13: 48 | I13: Cash | J13: Khalid | K13: Online Customer
B14: 45689 | C14: INV-1005 | D14: Lamb (kg) | E14: Meat | F14: 5 | G14: 55 | H14: 275 | I14: Card | J14: Khalid | K14: Online Customer
B15: 45690 | C15: INV-1006 | D15: Chips (150g) | E15: Snacks | F15: 2 | G15: 5 | H15: 10 | I15: Card | J15: Ahmed | K15: Regular Customer
B16: 45690 | C16: INV-1007 | D16: Pasta (500g) | E16: Grains | F16: 4 | G16: 4 | H16: 16 | I16: Online | J16: Ahmed | K16: Regular Customer
B17: 45690 | C17: INV-1007 | D17: Onions (kg) | E17: Produce | F17: 3 | G17: 3 | H17: 9 | I17: Cash | J17: Ahmed | K17: Regular Customer
B18: 45690 | C18: INV-1007 | D18: Chips (150g) | E18: Snacks | F18: 1 | G18: 5 | H18: 5 | I18: Online | J18: Ahmed | K18: Walk-in | L18: Express
B19: 45690 | C19: INV-1007 | D19: Biscuits (200g) | E19: Snacks | F19: 2 | G19: 4 | H19: 8 | I19: Cash | J19: Ahmed | K19: Regular Customer | L19: Bulk
B20: 45690 | C20: INV-1008 | D20: Chips (150g) | E20: Snacks | F20: 3 | G20: 5 | H20: 15 | I20: Cash | J20: Omar | K20: Walk-in
B21: 45690 | C21: INV-1008 | D21: Canned Beans | E21: Grains | F21: 3 | G21: 3 | H21: 9 | I21: Card | J21: Omar | K21: Regular Customer
B22: 45690 | C22: INV-1009 | D22: Water (6pk) | E22: Beverages | F22: 4 | G22: 2 | H22: 8 | I22: Card | J22: Fatima | K22: Regular Customer
B23: 45690 | C23: INV-1009 | D23: Pasta (500g) | E23: Grains | F23: 2 | G23: 4 | H23: 8 | I23: Cash | J23: Fatima | K23: Online Customer | L23: Express
B24: 45690 | C24: INV-1009 | D24: Pasta (500g) | E24: Grains | F24: 5 | G24: 4 | H24: 20 | I24: Card | J24: Fatima | K24: Online Customer | L24: Bulk
B25: 45690 | C25: INV-1010 | D25: Chicken (kg) | E25: Meat | F25: 5 | G25: 28 | H25: 140 | I25: Card | J25: Omar | K25: Regular Customer
B26: 45690 | C26: INV-1010 | D26: Fish (kg) | E26: Meat | F26: 1 | G26: 32 | H26: 32 | I26: Cash | J26: Omar | K26: Walk-in
B27: 45691 | C27: INV-1011 | D27: Cheese (200g) | E27: Dairy | F27: 4 | G27: 15 | H27: 60 | I27: Online | J27: Khalid | K27: Regular Customer | L27: Express
B28: 45691 | C28: INV-1012 | D28: Chips (150g) | E28: Snacks | F28: 1 | G28: 5 | H28: 5 | I28: Online | J28: Omar | K28: Online Customer
B29: 45691 | C29: INV-1013 | D29: Tomatoes (kg) | E29: Produce | F29: 4 | G29: 6 | H29: 24 | I29: Cash | J29: Omar | K29: Regular Customer
B30: 45691 | C30: INV-1014 | D30: Tea (25 bags) | E30: Beverages | F30: 1 | G30: 10 | H30: 10 | I30: Online | J30: Omar | K30: Regular Customer
B31: 45691 | C31: INV-1014 | D31: Tea (25 bags) | E31: Beverages | F31: 5 | G31: 10 | H31: 50 | I31: Cash | J31: Omar | K31: Walk-in
B32: 45692 | C32: INV-1015 | D32: Detergent (1L) | E32: Cleaning | F32: 3 | G32: 14 | H32: 42 | I32: Card | J32: Khalid | K32: Regular Customer
B33: 45692 | C33: INV-1016 | D33: Orange Juice (1L) | E33: Beverages | F33: 1 | G33: 6 | H33: 6 | I33: Cash | J33: Omar | K33: Online Customer
B34: 45692 | C34: INV-1016 | D34: Bread | E34: Bakery | F34: 4 | G34: 5 | H34: 20 | I34: Cash | J34: Omar | K34: Online Customer
B35: 45692 | C35: INV-1016 | D35: Chicken (kg) | E35: Meat | F35: 4 | G35: 28 | H35: 112 | I35: Online | J35: Omar | K35: Walk-in
B36: 45692 | C36: INV-1017 | D36: Water (6pk) | E36: Beverages | F36: 5 | G36: 2 | H36: 10 | I36: Online | J36: Khalid | K36: Walk-in
B37: 45692 | C37: INV-1017 | D37: Tomatoes (kg) | E37: Produce | F37: 4 | G37: 6 | H37: 24 | I37: Online | J37: Khalid | K37: Regular Customer | L37: Bulk
B38: 45692 | C38: INV-1017 | D38: Tea (25 bags) | E38: Beverages | F38: 4 | G38: 10 | H38: 40 | I38: Cash | J38: Khalid | K38: Walk-in
B39: 45692 | C39: INV-1017 | D39: Bread | E39: Bakery | F39: 3 | G39: 5 | H39: 15 | I39: Cash | J39: Khalid | K39: Online Customer | L39: Express
B40: 45693 | C40: INV-1018 | D40: Rice (5kg) | E40: Grains | F40: 1 | G40: 35 | H40: 35 | I40: Online | J40: Khalid | K40: Regular Customer
B41: 45693 | C41: INV-1018 | D41: Bread | E41: Bakery | F41: 1 | G41: 5 | H41: 5 | I41: Card | J41: Khalid | K41: Regular Customer | L41: Express
B42: 45693 | C42: INV-1019 | D42: Chips (150g) | E42: Snacks | F42: 4 | G42: 5 | H42: 20 | I42: Cash | J42: Fatima | K42: Online Customer
...

Sheet Daily Summary
B2: Daily Summary — February 2025
B4: Date | C4: Total Sales | D4: # Transactions | E4: Avg Transaction | F4: Cash Total | G4: Card Total | H4: Online Total | I4: # Items Sold
B5: 45689 | C5: =SUMPRODUCT(('Sales Entry'!B5:B89=B5)*('Sales Entry'!H5:H89)) | D5: =SUMPRODUCT(('Sales Entry'!B5:B89=B5)*1) | E5: =IFERROR(C5/D5,0) | F5: =SUMPRODUCT(('Sales Entry'!B5:B89=B5)*('Sales Entry'!I5:I89="Cash")*('Sales Entry'!H5:H89)) | G5: =SUMPRODUCT(('Sales Entry'!B5:B89=B5)*('Sales Entry'!I5:I89="Card")*('Sales Entry'!H5:H89)) | H5: =SUMPRODUCT(('Sales Entry'!B5:B89=B5)*('Sales Entry'!I5:I89="Online")*('Sales Entry'!H5:H89)) | I5: =SUMPRODUCT(('Sales Entry'!B5:B89=B5)*('Sales Entry'!F5:F89))
B6: 45690 | C6: =SUMPRODUCT(('Sales Entry'!B5:B89=B6)*('Sales Entry'!H5:H89)) | D6: =SUMPRODUCT(('Sales Entry'!B5:B89=B6)*1) | E6: =IFERROR(C6/D6,0) | F6: =SUMPRODUCT(('Sales Entry'!B5:B89=B6)*('Sales Entry'!I5:I89="Cash")*('Sales Entry'!H5:H89)) | G6: =SUMPRODUCT(('Sales Entry'!B5:B89=B6)*('Sales Entry'!I5:I89="Card")*('Sales Entry'!H5:H89)) | H6: =SUMPRODUCT(('Sales Entry'!B5:B89=B6)*('Sales Entry'!I5:I89="Online")*('Sales Entry'!H5:H89)) | I6: =SUMPRODUCT(('Sales Entry'!B5:B89=B6)*('Sales Entry'!F5:F89))
B7: 45691 | C7: =SUMPRODUCT(('Sales Entry'!B5:B89=B7)*('Sales Entry'!H5:H89)) | D7: =SUMPRODUCT(('Sales Entry'!B5:B89=B7)*1) | E7: =IFERROR(C7/D7,0) | F7: =SUMPRODUCT(('Sales Entry'!B5:B89=B7)*('Sales Entry'!I5:I89="Cash")*('Sales Entry'!H5:H89)) | G7: =SUMPRODUCT(('Sales Entry'!B5:B89=B7)*('Sales Entry'!I5:I89="Card")*('Sales Entry'!H5:H89)) | H7: =SUMPRODUCT(('Sales Entry'!B5:B89=B7)*('Sales Entry'!I5:I89="Online")*('Sales Entry'!H5:H89)) | I7: =SUMPRODUCT(('Sales Entry'!B5:B89=B7)*('Sales Entry'!F5:F89))
B8: 45692 | C8: =SUMPRODUCT(('Sales Entry'!B5:B89=B8)*('Sales Entry'!H5:H89)) | D8: =SUMPRODUCT(('Sales Entry'!B5:B89=B8)*1) | E8: =IFERROR(C8/D8,0) | F8: =SUMPRODUCT(('Sales Entry'!B5:B89=B8)*('Sales Entry'!I5:I89="Cash")*('Sales Entry'!H5:H89)) | G8: =SUMPRODUCT(('Sales Entry'!B5:B89=B8)*('Sales Entry'!I5:I89="Card")*('Sales Entry'!H5:H89)) | H8: =SUMPRODUCT(('Sales Entry'!B5:B89=B8)*('Sales Entry'!I5:I89="Online")*('Sales Entry'!H5:H89)) | I8: =SUMPRODUCT(('Sales Entry'!B5:B89=B8)*('Sales Entry'!F5:F89))
B9: 45693 | C9: =SUMPRODUCT(('Sales Entry'!B5:B89=B9)*('Sales Entry'!H5:H89)) | D9: =SUMPRODUCT(('Sales Entry'!B5:B89=B9)*1) | E9: =IFERROR(C9/D9,0) | F9: =SUMPRODUCT(('Sales Entry'!B5:B89=B9)*('Sales Entry'!I5:I89="Cash")*('Sales Entry'!H5:H89)) | G9: =SUMPRODUCT(('Sales Entry'!B5:B89=B9)*('Sales Entry'!I5:I89="Card")*('Sales Entry'!H5:H89)) | H9: =SUMPRODUCT(('Sales Entry'!B5:B89=B9)*('Sales Entry'!I5:I89="Online")*('Sales Entry'!H5:H89)) | I9: =SUMPRODUCT(('Sales Entry'!B5:B89=B9)*('Sales Entry'!F5:F89))
B10: 45694 | C10: =SUMPRODUCT(('Sales Entry'!B5:B89=B10)*('Sales Entry'!H5:H89)) | D10: =SUMPRODUCT(('Sales Entry'!B5:B89=B10)*1) | E10: =IFERROR(C10/D10,0) | F10: =SUMPRODUCT(('Sales Entry'!B5:B89=B10)*('Sales Entry'!I5:I89="Cash")*('Sales Entry'!H5:H89)) | G10: =SUMPRODUCT(('Sales Entry'!B5:B89=B10)*('Sales Entry'!I5:I89="Card")*('Sales Entry'!H5:H89)) | H10: =SUMPRODUCT(('Sales Entry'!B5:B89=B10)*('Sales Entry'!I5:I89="Online")*('Sales Entry'!H5:H89)) | I10: =SUMPRODUCT(('Sales Entry'!B5:B89=B10)*('Sales Entry'!F5:F89))
B11: 45695 | C11: =SUMPRODUCT(('Sales Entry'!B5:B89=B11)*('Sales Entry'!H5:H89)) | D11: =SUMPRODUCT(('Sales Entry'!B5:B89=B11)*1) | E11: =IFERROR(C11/D11,0) | F11: =SUMPRODUCT(('Sales Entry'!B5:B89=B11)*('Sales Entry'!I5:I89="Cash")*('Sales Entry'!H5:H89)) | G11: =SUMPRODUCT(('Sales Entry'!B5:B89=B11)*('Sales Entry'!I5:I89="Card")*('Sales Entry'!H5:H89)) | H11: =SUMPRODUCT(('Sales Entry'!B5:B89=B11)*('Sales Entry'!I5:I89="Online")*('Sales Entry'!H5:H89)) | I11: =SUMPRODUCT(('Sales Entry'!B5:B89=B11)*('Sales Entry'!F5:F89))
B12: 45696 | C12: =SUMPRODUCT(('Sales Entry'!B5:B89=B12)*('Sales Entry'!H5:H89)) | D12: =SUMPRODUCT(('Sales Entry'!B5:B89=B12)*1) | E12: =IFERROR(C12/D12,0) | F12: =SUMPRODUCT(('Sales Entry'!B5:B89=B12)*('Sales Entry'!I5:I89="Cash")*('Sales Entry'!H5:H89)) | G12: =SUMPRODUCT(('Sales Entry'!B5:B89=B12)*('Sales Entry'!I5:I89="Card")*('Sales Entry'!H5:H89)) | H12: =SUMPRODUCT(('Sales Entry'!B5:B89=B12)*('Sales Entry'!I5:I89="Online")*('Sales Entry'!H5:H89)) | I12: =SUMPRODUCT(('Sales Entry'!B5:B89=B12)*('Sales Entry'!F5:F89))
B13: 45697 | C13: =SUMPRODUCT(('Sales Entry'!B5:B89=B13)*('Sales Entry'!H5:H89)) | D13: =SUMPRODUCT(('Sales Entry'!B5:B89=B13)*1) | E13: =IFERROR(C13/D13,0) | F13: =SUMPRODUCT(('Sales Entry'!B5:B89=B13)*('Sales Entry'!I5:I89="Cash")*('Sales Entry'!H5:H89)) | G13: =SUMPRODUCT(('Sales Entry'!B5:B89=B13)*('Sales Entry'!I5:I89="Card")*('Sales Entry'!H5:H89)) | H13: =SUMPRODUCT(('Sales Entry'!B5:B89=B13)*('Sales Entry'!I5:I89="Online")*('Sales Entry'!H5:H89)) | I13: =SUMPRODUCT(('Sales Entry'!B5:B89=B13)*('Sales Entry'!F5:F89))
B14: 45698 | C14: =SUMPRODUCT(('Sales Entry'!B5:B89=B14)*('Sales Entry'!H5:H89)) | D14: =SUMPRODUCT(('Sales Entry'!B5:B89=B14)*1) | E14: =IFERROR(C14/D14,0) | F14: =SUMPRODUCT(('Sales Entry'!B5:B89=B14)*('Sales Entry'!I5:I89="Cash")*('Sales Entry'!H5:H89)) | G14: =SUMPRODUCT(('Sales Entry'!B5:B89=B14)*('Sales Entry'!I5:I89="Card")*('Sales Entry'!H5:H89)) | H14: =SUMPRODUCT(('Sales Entry'!B5:B89=B14)*('Sales Entry'!I5:I89="Online")*('Sales Entry'!H5:H89)) | I14: =SUMPRODUCT(('Sales Entry'!B5:B89=B14)*('Sales Entry'!F5:F89))
B15: 45699 | C15: =SUMPRODUCT(('Sales Entry'!B5:B89=B15)*('Sales Entry'!H5:H89)) | D15: =SUMPRODUCT(('Sales Entry'!B5:B89=B15)*1) | E15: =IFERROR(C15/D15,0) | F15: =SUMPRODUCT(('Sales Entry'!B5:B89=B15)*('Sales Entry'!I5:I89="Cash")*('Sales Entry'!H5:H89)) | G15: =SUMPRODUCT(('Sales Entry'!B5:B89=B15)*('Sales Entry'!I5:I89="Card")*('Sales Entry'!H5:H89)) | H15: =SUMPRODUCT(('Sales Entry'!B5:B89=B15)*('Sales Entry'!I5:I89="Online")*('Sales Entry'!H5:H89)) | I15: =SUMPRODUCT(('Sales Entry'!B5:B89=B15)*('Sales Entry'!F5:F89))
B16: 45700 | C16: =SUMPRODUCT(('Sales Entry'!B5:B89=B16)*('Sales Entry'!H5:H89)) | D16: =SUMPRODUCT(('Sales Entry'!B5:B89=B16)*1) | E16: =IFERROR(C16/D16,0) | F16: =SUMPRODUCT(('Sales Entry'!B5:B89=B16)*('Sales Entry'!I5:I89="Cash")*('Sales Entry'!H5:H89)) | G16: =SUMPRODUCT(('Sales Entry'!B5:B89=B16)*('Sales Entry'!I5:I89="Card")*('Sales Entry'!H5:H89)) | H16: =SUMPRODUCT(('Sales Entry'!B5:B89=B16)*('Sales Entry'!I5:I89="Online")*('Sales Entry'!H5:H89)) | I16: =SUMPRODUCT(('Sales Entry'!B5:B89=B16)*('Sales Entry'!F5:F89))
B17: 45701 | C17: =SUMPRODUCT(('Sales Entry'!B5:B89=B17)*('Sales Entry'!H5:H89)) | D17: =SUMPRODUCT(('Sales Entry'!B5:B89=B17)*1) | E17: =IFERROR(C17/D17,0) | F17: =SUMPRODUCT(('Sales Entry'!B5:B89=B17)*('Sales Entry'!I5:I89="Cash")*('Sales Entry'!H5:H89)) | G17: =SUMPRODUCT(('Sales Entry'!B5:B89=B17)*('Sales Entry'!I5:I89="Card")*('Sales Entry'!H5:H89)) | H17: =SUMPRODUCT(('Sales Entry'!B5:B89=B17)*('Sales Entry'!I5:I89="Online")*('Sales Entry'!H5:H89)) | I17: =SUMPRODUCT(('Sales Entry'!B5:B89=B17)*('Sales Entry'!F5:F89))
B18: 45702 | C18: =SUMPRODUCT(('Sales Entry'!B5:B89=B18)*('Sales Entry'!H5:H89)) | D18: =SUMPRODUCT(('Sales Entry'!B5:B89=B18)*1) | E18: =IFERROR(C18/D18,0) | F18: =SUMPRODUCT(('Sales Entry'!B5:B89=B18)*('Sales Entry'!I5:I89="Cash")*('Sales Entry'!H5:H89)) | G18: =SUMPRODUCT(('Sales Entry'!B5:B89=B18)*('Sales Entry'!I5:I89="Card")*('Sales Entry'!H5:H89)) | H18: =SUMPRODUCT(('Sales Entry'!B5:B89=B18)*('Sales Entry'!I5:I89="Online")*('Sales Entry'!H5:H89)) | I18: =SUMPRODUCT(('Sales Entry'!B5:B89=B18)*('Sales Entry'!F5:F89))
B19: 45703 | C19: =SUMPRODUCT(('Sales Entry'!B5:B89=B19)*('Sales Entry'!H5:H89)) | D19: =SUMPRODUCT(('Sales Entry'!B5:B89=B19)*1) | E19: =IFERROR(C19/D19,0) | F19: =SUMPRODUCT(('Sales Entry'!B5:B89=B19)*('Sales Entry'!I5:I89="Cash")*('Sales Entry'!H5:H89)) | G19: =SUMPRODUCT(('Sales Entry'!B5:B89=B19)*('Sales Entry'!I5:I89="Card")*('Sales Entry'!H5:H89)) | H19: =SUMPRODUCT(('Sales Entry'!B5:B89=B19)*('Sales Entry'!I5:I89="Online")*('Sales Entry'!H5:H89)) | I19: =SUMPRODUCT(('Sales Entry'!B5:B89=B19)*('Sales Entry'!F5:F89))
B20: 45704 | C20: =SUMPRODUCT(('Sales Entry'!B5:B89=B20)*('Sales Entry'!H5:H89)) | D20: =SUMPRODUCT(('Sales Entry'!B5:B89=B20)*1) | E20: =IFERROR(C20/D20,0) | F20: =SUMPRODUCT(('Sales Entry'!B5:B89=B20)*('Sales Entry'!I5:I89="Cash")*('Sales Entry'!H5:H89)) | G20: =SUMPRODUCT(('Sales Entry'!B5:B89=B20)*('Sales Entry'!I5:I89="Card")*('Sales Entry'!H5:H89)) | H20: =SUMPRODUCT(('Sales Entry'!B5:B89=B20)*('Sales Entry'!I5:I89="Online")*('Sales Entry'!H5:H89)) | I20: =SUMPRODUCT(('Sales Entry'!B5:B89=B20)*('Sales Entry'!F5:F89))
B21: 45705 | C21: =SUMPRODUCT(('Sales Entry'!B5:B89=B21)*('Sales Entry'!H5:H89)) | D21: =SUMPRODUCT(('Sales Entry'!B5:B89=B21)*1) | E21: =IFERROR(C21/D21,0) | F21: =SUMPRODUCT(('Sales Entry'!B5:B89=B21)*('Sales Entry'!I5:I89="Cash")*('Sales Entry'!H5:H89)) | G21: =SUMPRODUCT(('Sales Entry'!B5:B89=B21)*('Sales Entry'!I5:I89="Card")*('Sales Entry'!H5:H89)) | H21: =SUMPRODUCT(('Sales Entry'!B5:B89=B21)*('Sales Entry'!I5:I89="Online")*('Sales Entry'!H5:H89)) | I21: =SUMPRODUCT(('Sales Entry'!B5:B89=B21)*('Sales Entry'!F5:F89))
B22: 45706 | C22: =SUMPRODUCT(('Sales Entry'!B5:B89=B22)*('Sales Entry'!H5:H89)) | D22: =SUMPRODUCT(('Sales Entry'!B5:B89=B22)*1) | E22: =IFERROR(C22/D22,0) | F22: =SUMPRODUCT(('Sales Entry'!B5:B89=B22)*('Sales Entry'!I5:I89="Cash")*('Sales Entry'!H5:H89)) | G22: =SUMPRODUCT(('Sales Entry'!B5:B89=B22)*('Sales Entry'!I5:I89="Card")*('Sales Entry'!H5:H89)) | H22: =SUMPRODUCT(('Sales Entry'!B5:B89=B22)*('Sales Entry'!I5:I89="Online")*('Sales Entry'!H5:H89)) | I22: =SUMPRODUCT(('Sales Entry'!B5:B89=B22)*('Sales Entry'!F5:F89))
B23: 45707 | C23: =SUMPRODUCT(('Sales Entry'!B5:B89=B23)*('Sales Entry'!H5:H89)) | D23: =SUMPRODUCT(('Sales Entry'!B5:B89=B23)*1) | E23: =IFERROR(C23/D23,0) | F23: =SUMPRODUCT(('Sales Entry'!B5:B89=B23)*('Sales Entry'!I5:I89="Cash")*('Sales Entry'!H5:H89)) | G23: =SUMPRODUCT(('Sales Entry'!B5:B89=B23)*('Sales Entry'!I5:I89="Card")*('Sales Entry'!H5:H89)) | H23: =SUMPRODUCT(('Sales Entry'!B5:B89=B23)*('Sales Entry'!I5:I89="Online")*('Sales Entry'!H5:H89)) | I23: =SUMPRODUCT(('Sales Entry'!B5:B89=B23)*('Sales Entry'!F5:F89))
B24: 45708 | C24: =SUMPRODUCT(('Sales Entry'!B5:B89=B24)*('Sales Entry'!H5:H89)) | D24: =SUMPRODUCT(('Sales Entry'!B5:B89=B24)*1) | E24: =IFERROR(C24/D24,0) | F24: =SUMPRODUCT(('Sales Entry'!B5:B89=B24)*('Sales Entry'!I5:I89="Cash")*('Sales Entry'!H5:H89)) | G24: =SUMPRODUCT(('Sales Entry'!B5:B89=B24)*('Sales Entry'!I5:I89="Card")*('Sales Entry'!H5:H89)) | H24: =SUMPRODUCT(('Sales Entry'!B5:B89=B24)*('Sales Entry'!I5:I89="Online")*('Sales Entry'!H5:H89)) | I24: =SUMPRODUCT(('Sales Entry'!B5:B89=B24)*('Sales Entry'!F5:F89))
B25: 45709 | C25: =SUMPRODUCT(('Sales Entry'!B5:B89=B25)*('Sales Entry'!H5:H89)) | D25: =SUMPRODUCT(('Sales Entry'!B5:B89=B25)*1) | E25: =IFERROR(C25/D25,0) | F25: =SUMPRODUCT(('Sales Entry'!B5:B89=B25)*('Sales Entry'!I5:I89="Cash")*('Sales Entry'!H5:H89)) | G25: =SUMPRODUCT(('Sales Entry'!B5:B89=B25)*('Sales Entry'!I5:I89="Card")*('Sales Entry'!H5:H89)) | H25: =SUMPRODUCT(('Sales Entry'!B5:B89=B25)*('Sales Entry'!I5:I89="Online")*('Sales Entry'!H5:H89)) | I25: =SUMPRODUCT(('Sales Entry'!B5:B89=B25)*('Sales Entry'!F5:F89))
B26: 45710 | C26: =SUMPRODUCT(('Sales Entry'!B5:B89=B26)*('Sales Entry'!H5:H89)) | D26: =SUMPRODUCT(('Sales Entry'!B5:B89=B26)*1) | E26: =IFERROR(C26/D26,0) | F26: =SUMPRODUCT(('Sales Entry'!B5:B89=B26)*('Sales Entry'!I5:I89="Cash")*('Sales Entry'!H5:H89)) | G26: =SUMPRODUCT(('Sales Entry'!B5:B89=B26)*('Sales Entry'!I5:I89="Card")*('Sales Entry'!H5:H89)) | H26: =SUMPRODUCT(('Sales Entry'!B5:B89=B26)*('Sales Entry'!I5:I89="Online")*('Sales Entry'!H5:H89)) | I26: =SUMPRODUCT(('Sales Entry'!B5:B89=B26)*('Sales Entry'!F5:F89))
B27: 45711 | C27: =SUMPRODUCT(('Sales Entry'!B5:B89=B27)*('Sales Entry'!H5:H89)) | D27: =SUMPRODUCT(('Sales Entry'!B5:B89=B27)*1) | E27: =IFERROR(C27/D27,0) | F27: =SUMPRODUCT(('Sales Entry'!B5:B89=B27)*('Sales Entry'!I5:I89="Cash")*('Sales Entry'!H5:H89)) | G27: =SUMPRODUCT(('Sales Entry'!B5:B89=B27)*('Sales Entry'!I5:I89="Card")*('Sales Entry'!H5:H89)) | H27: =SUMPRODUCT(('Sales Entry'!B5:B89=B27)*('Sales Entry'!I5:I89="Online")*('Sales Entry'!H5:H89)) | I27: =SUMPRODUCT(('Sales Entry'!B5:B89=B27)*('Sales Entry'!F5:F89))
B28: 45712 | C28: =SUMPRODUCT(('Sales Entry'!B5:B89=B28)*('Sales Entry'!H5:H89)) | D28: =SUMPRODUCT(('Sales Entry'!B5:B89=B28)*1) | E28: =IFERROR(C28/D28,0) | F28: =SUMPRODUCT(('Sales Entry'!B5:B89=B28)*('Sales Entry'!I5:I89="Cash")*('Sales Entry'!H5:H89)) | G28: =SUMPRODUCT(('Sales Entry'!B5:B89=B28)*('Sales Entry'!I5:I89="Card")*('Sales Entry'!H5:H89)) | H28: =SUMPRODUCT(('Sales Entry'!B5:B89=B28)*('Sales Entry'!I5:I89="Online")*('Sales Entry'!H5:H89)) | I28: =SUMPRODUCT(('Sales Entry'!B5:B89=B28)*('Sales Entry'!F5:F89))
B29: 45713 | C29: =SUMPRODUCT(('Sales Entry'!B5:B89=B29)*('Sales Entry'!H5:H89)) | D29: =SUMPRODUCT(('Sales Entry'!B5:B89=B29)*1) | E29: =IFERROR(C29/D29,0) | F29: =SUMPRODUCT(('Sales Entry'!B5:B89=B29)*('Sales Entry'!I5:I89="Cash")*('Sales Entry'!H5:H89)) | G29: =SUMPRODUCT(('Sales Entry'!B5:B89=B29)*('Sales Entry'!I5:I89="Card")*('Sales Entry'!H5:H89)) | H29: =SUMPRODUCT(('Sales Entry'!B5:B89=B29)*('Sales Entry'!I5:I89="Online")*('Sales Entry'!H5:H89)) | I29: =SUMPRODUCT(('Sales Entry'!B5:B89=B29)*('Sales Entry'!F5:F89))
B30: 45714 | C30: =SUMPRODUCT(('Sales Entry'!B5:B89=B30)*('Sales Entry'!H5:H89)) | D30: =SUMPRODUCT(('Sales Entry'!B5:B89=B30)*1) | E30: =IFERROR(C30/D30,0) | F30: =SUMPRODUCT(('Sales Entry'!B5:B89=B30)*('Sales Entry'!I5:I89="Cash")*('Sales Entry'!H5:H89)) | G30: =SUMPRODUCT(('Sales Entry'!B5:B89=B30)*('Sales Entry'!I5:I89="Card")*('Sales Entry'!H5:H89)) | H30: =SUMPRODUCT(('Sales Entry'!B5:B89=B30)*('Sales Entry'!I5:I89="Online")*('Sales Entry'!H5:H89)) | I30: =SUMPRODUCT(('Sales Entry'!B5:B89=B30)*('Sales Entry'!F5:F89))
B31: 45715 | C31: =SUMPRODUCT(('Sales Entry'!B5:B89=B31)*('Sales Entry'!H5:H89)) | D31: =SUMPRODUCT(('Sales Entry'!B5:B89=B31)*1) | E31: =IFERROR(C31/D31,0) | F31: =SUMPRODUCT(('Sales Entry'!B5:B89=B31)*('Sales Entry'!I5:I89="Cash")*('Sales Entry'!H5:H89)) | G31: =SUMPRODUCT(('Sales Entry'!B5:B89=B31)*('Sales Entry'!I5:I89="Card")*('Sales Entry'!H5:H89)) | H31: =SUMPRODUCT(('Sales Entry'!B5:B89=B31)*('Sales Entry'!I5:I89="Online")*('Sales Entry'!H5:H89)) | I31: =SUMPRODUCT(('Sales Entry'!B5:B89=B31)*('Sales Entry'!F5:F89))
B32: 45716 | C32: =SUMPRODUCT(('Sales Entry'!B5:B89=B32)*('Sales Entry'!H5:H89)) | D32: =SUMPRODUCT(('Sales Entry'!B5:B89=B32)*1) | E32: =IFERROR(C32/D32,0) | F32: =SUMPRODUCT(('Sales Entry'!B5:B89=B32)*('Sales Entry'!I5:I89="Cash")*('Sales Entry'!H5:H89)) | G32: =SUMPRODUCT(('Sales Entry'!B5:B89=B32)*('Sales Entry'!I5:I89="Card")*('Sales Entry'!H5:H89)) | H32: =SUMPRODUCT(('Sales Entry'!B5:B89=B32)*('Sales Entry'!I5:I89="Online")*('Sales Entry'!H5:H89)) | I32: =SUMPRODUCT(('Sales Entry'!B5:B89=B32)*('Sales Entry'!F5:F89))
B33: TOTAL | C33: =SUM(C5:C32) | D33: =SUM(D5:D32) | E33: =IFERROR(C33/D33,0) | F33: =SUM(F5:F32) | G33: =SUM(G5:G32) | H33: =SUM(H5:H32) | I33: =SUM(I5:I32)

Sheet Weekly Summary
B2: Weekly Summary — February 2025
B4: Week # | C4: Week Start | D4: Week End | E4: Total Sales | F4: # Transactions | G4: Avg Transaction | H4: Top Staff
B5: 1 | C5: 45689 | D5: 45695 | E5: =SUMPRODUCT(('Daily Summary'!B5:B32>=C5)*('Daily Summary'!B5:B32<=D5)*('Daily Summary'!C5:C32)) | F5: =SUMPRODUCT(('Daily Summary'!B5:B32>=C5)*('Daily Summary'!B5:B32<=D5)*('Daily Summary'!D5:D32)) | G5: =IFERROR(E5/F5,0) | H5: =IF(AND(SUMPRODUCT(('Sales Entry'!B5:B89>=C5)*('Sales Entry'!B5:B89<=D5)*('Sales Entry'!J5:J89="Ahmed")*('Sales Entry'!H5:H89))>=SUMPRODUCT(('Sales Entry'!B5:B89>=C5)*('Sales Entry'!B5:B89<=D5)*('Sales Entry'!J5:J89="Fatima")*('Sales Entry'!H5:H89)),SUMPRODUCT(('Sales Entry'!B5:B89>=C5)*('Sales Entry'!B5:B89<=D5)*('Sales Entry'!J5:J89="Ahmed")*('Sales Entry'!H5:H89))>=SUMPRODUCT(('Sales Entry'!B5:B89>=C5)*('Sales Entry'!B5:B89<=D5)*('Sales Entry'!J5:J89="Omar")*('Sales Entry'!H5:H89)),SUMPRODUCT(('Sales Entry'!B5:B89>=C5)*('Sales Entry'!B5:B89<=D5)*('Sales Entry'!J5:J89="Ahmed")*('Sales Entry'!H5:H89))>=SUMPRODUCT(('Sales Entry'!B5:B89>=C5)*('Sales Entry'!B5:B89<=D5)*('Sales Entry'!J5:J89="Sara")*('Sales Entry'!H5:H89)),SUMPRODUCT(('Sales Entry'!B5:B89>=C5)*('Sales Entry'!B5:B89<=D5)*('Sales Entry'!J5:J89="Ahmed")*('Sales Entry'!H5:H89))>=SUMPRODUCT(('Sales Entry'!B5:B89>=C5)*('Sales Entry'!B5:B89<=D5)*('Sales Entry'!J5:J89="Khalid")*('Sales Entry'!H5:H89))),"Ahmed",IF(AND(SUMPRODUCT(('Sales Entry'!B5:B89>=C5)*('Sales Entry'!B5:B89<=D5)*('Sales Entry'!J5:J89="Fatima")*('Sales Entry'!H5:H89))>=SUMPRODUCT(('Sales Entry'!B5:B89>=C5)*('Sales Entry'!B5:B89<=D5)*('Sales Entry'!J5:J89="Ahmed")*('Sales Entry'!H5:H89)),SUMPRODUCT(('Sales Entry'!B5:B89>=C5)*('Sales Entry'!B5:B89<=D5)*('Sales Entry'!J5:J89="Fatima")*('Sales Entry'!H5:H89))>=SUMPRODUCT(('Sales Entry'!B5:B89>=C5)*('Sales Entry'!B5:B89<=D5)*('Sales Entry'!J5:J89="Omar")*('Sales Entry'!H5:H89)),SUMPRODUCT(('Sales Entry'!B5:B89>=C5)*('Sales Entry'!B5:B89<=D5)*('Sales Entry'!J5:J89="Fatima")*('Sales Entry'!H5:H89))>=SUMPRODUCT(('Sales Entry'!B5:B89>=C5)*('Sales Entry'!B5:B89<=D5)*('Sales Entry'!J5:J89="Sara")*('Sales Entry'!H5:H89)),SUMPRODUCT(('Sales Entry'!B5:B89>=C5)*('Sales Entry'!B5:B89<=D5)*('Sales Entry'!J5:J89="Fatima")*('Sales Entry'!H5:H89))>=SUMPRODUCT(('Sales Entry'!B5:B89>=C5)*('Sales Entry'!B5:B89<=D5)*('Sales Entry'!J5:J89="Khalid")*('Sales Entry'!H5:H89))),"Fatima",IF(AND(SUMPRODUCT(('Sales Entry'!B5:B89>=C5)*('Sales Entry'!B5:B89<=D5)*('Sales Entry'!J5:J89="Omar")*('Sales Entry'!H5:H89))>=SUMPRODUCT(('Sales Entry'!B5:B89>=C5)*('Sales Entry'!B5:B89<=D5)*('Sales Entry'!J5:J89="Ahmed")*('Sales Entry'!H5:H89)),SUMPRODUCT(('Sales Entry'!B5:B89>=C5)*('Sales Entry'!B5:B89<=D5)*('Sales Entry'!J5:J89="Omar")*('Sales Entry'!H5:H89))>=SUMPRODUCT(('Sales Entry'!B5:B89>=C5)*('Sales Entry'!B5:B89<=D5)*('Sales Entry'!J5:J89="Fatima")*('Sales Entry'!H5:H89)),SUMPRODUCT(('Sales Entry'!B5:B89>=C5)*('Sales Entry'!B5:B89<=D5)*('Sales Entry'!J5:J89="Omar")*('Sales Entry'!H5:H89))>=SUMPRODUCT(('Sales Entry'!B5:B89>=C5)*('Sales Entry'!B5:B89<=D5)*('Sales Entry'!J5:J89="Sara")*('Sales Entry'!H5:H89)),SUMPRODUCT(('Sales Entry'!B5:B89>=C5)*('Sales Entry'!B5:B89<=D5)*('Sales Entry'!J5:J89="Omar")*('Sales Entry'!H5:H89))>=SUMPRODUCT(('Sales Entry'!B5:B89>=C5)*('Sales Entry'!B5:B89<=D5)*('Sales Entry'!J5:J89="Khalid")*('Sales Entry'!H5:H89))),"Omar",IF(AND(SUMPRODUCT(('Sales Entry'!B5:B89>=C5)*('Sales Entry'!B5:B89<=D5)*('Sales Entry'!J5:J89="Sara")*('Sales Entry'!H5:H89))>=SUMPRODUCT(('Sales Entry'!B5:B89>=C5)*('Sales Entry'!B5:B89<=D5)*('Sales Entry'!J5:J89="Ahmed")*('Sales Entry'!H5:H89)),SUMPRODUCT(('Sales Entry'!B5:B89>=C5)*('Sales Entry'!B5:B89<=D5)*('Sales Entry'!J5:J89="Sara")*('Sales Entry'!H5:H89))>=SUMPRODUCT(('Sales Entry'!B5:B89>=C5)*('Sales Entry'!B5:B89<=D5)*('Sales Entry'!J5:J89="Fatima")*('Sales Entry'!H5:H89)),SUMPRODUCT(('Sales Entry'!B5:B89>=C5)*('Sales Entry'!B5:B89<=D5)*('Sales Entry'!J5:J89="Sara")*('Sales Entry'!H5:H89))>=SUMPRODUCT(('Sales Entry'!B5:B89>=C5)*('Sales Entry'!B5:B89<=D5)*('Sales Entry'!J5:J89="Omar")*('Sales Entry'!H5:H89)),SUMPRODUCT(('Sales Entry'!B5:B89>=C5)*('Sales Entry'!B5:B89<=D5)*('Sales Entry'!J5:J89="Sara")*('Sales Entry'!H5:H89))>=SUMPRODUCT(('Sales Entry'!B5:B89>=C5)*('Sales Entry'!B5:B89<=D5)*('Sales Entry'!J5:J89="Khalid")*('Sales Entry'!H5:H89))),"Sara","Khalid"))))
B6: 2 | C6: 45696 | D6: 45702 | E6: =SUMPRODUCT(('Daily Summary'!B5:B32>=C6)*('Daily Summary'!B5:B32<=D6)*('Daily Summary'!C5:C32)) | F6: =SUMPRODUCT(('Daily Summary'!B5:B32>=C6)*('Daily Summary'!B5:B32<=D6)*('Daily Summary'!D5:D32)) | G6: =IFERROR(E6/F6,0) | H6: =IF(AND(SUMPRODUCT(('Sales Entry'!B5:B89>=C6)*('Sales Entry'!B5:B89<=D6)*('Sales Entry'!J5:J89="Ahmed")*('Sales Entry'!H5:H89))>=SUMPRODUCT(('Sales Entry'!B5:B89>=C6)*('Sales Entry'!B5:B89<=D6)*('Sales Entry'!J5:J89="Fatima")*('Sales Entry'!H5:H89)),SUMPRODUCT(('Sales Entry'!B5:B89>=C6)*('Sales Entry'!B5:B89<=D6)*('Sales Entry'!J5:J89="Ahmed")*('Sales Entry'!H5:H89))>=SUMPRODUCT(('Sales Entry'!B5:B89>=C6)*('Sales Entry'!B5:B89<=D6)*('Sales Entry'!J5:J89="Omar")*('Sales Entry'!H5:H89)),SUMPRODUCT(('Sales Entry'!B5:B89>=C6)*('Sales Entry'!B5:B89<=D6)*('Sales Entry'!J5:J89="Ahmed")*('Sales Entry'!H5:H89))>=SUMPRODUCT(('Sales Entry'!B5:B89>=C6)*('Sales Entry'!B5:B89<=D6)*('Sales Entry'!J5:J89="Sara")*('Sales Entry'!H5:H89)),SUMPRODUCT(('Sales Entry'!B5:B89>=C6)*('Sales Entry'!B5:B89<=D6)*('Sales Entry'!J5:J89="Ahmed")*('Sales Entry'!H5:H89))>=SUMPRODUCT(('Sales Entry'!B5:B89>=C6)*('Sales Entry'!B5:B89<=D6)*('Sales Entry'!J5:J89="Khalid")*('Sales Entry'!H5:H89))),"Ahmed",IF(AND(SUMPRODUCT(('Sales Entry'!B5:B89>=C6)*('Sales Entry'!B5:B89<=D6)*('Sales Entry'!J5:J89="Fatima")*('Sales Entry'!H5:H89))>=SUMPRODUCT(('Sales Entry'!B5:B89>=C6)*('Sales Entry'!B5:B89<=D6)*('Sales Entry'!J5:J89="Ahmed")*('Sales Entry'!H5:H89)),SUMPRODUCT(('Sales Entry'!B5:B89>=C6)*('Sales Entry'!B5:B89<=D6)*('Sales Entry'!J5:J89="Fatima")*('Sales Entry'!H5:H89))>=SUMPRODUCT(('Sales Entry'!B5:B89>=C6)*('Sales Entry'!B5:B89<=D6)*('Sales Entry'!J5:J89="Omar")*('Sales Entry'!H5:H89)),SUMPRODUCT(('Sales Entry'!B5:B89>=C6)*('Sales Entry'!B5:B89<=D6)*('Sales Entry'!J5:J89="Fatima")*('Sales Entry'!H5:H89))>=SUMPRODUCT(('Sales Entry'!B5:B89>=C6)*('Sales Entry'!B5:B89<=D6)*('Sales Entry'!J5:J89="Sara")*('Sales Entry'!H5:H89)),SUMPRODUCT(('Sales Entry'!B5:B89>=C6)*('Sales Entry'!B5:B89<=D6)*('Sales Entry'!J5:J89="Fatima")*('Sales Entry'!H5:H89))>=SUMPRODUCT(('Sales Entry'!B5:B89>=C6)*('Sales Entry'!B5:B89<=D6)*('Sales Entry'!J5:J89="Khalid")*('Sales Entry'!H5:H89))),"Fatima",IF(AND(SUMPRODUCT(('Sales Entry'!B5:B89>=C6)*('Sales Entry'!B5:B89<=D6)*('Sales Entry'!J5:J89="Omar")*('Sales Entry'!H5:H89))>=SUMPRODUCT(('Sales Entry'!B5:B89>=C6)*('Sales Entry'!B5:B89<=D6)*('Sales Entry'!J5:J89="Ahmed")*('Sales Entry'!H5:H89)),SUMPRODUCT(('Sales Entry'!B5:B89>=C6)*('Sales Entry'!B5:B89<=D6)*('Sales Entry'!J5:J89="Omar")*('Sales Entry'!H5:H89))>=SUMPRODUCT(('Sales Entry'!B5:B89>=C6)*('Sales Entry'!B5:B89<=D6)*('Sales Entry'!J5:J89="Fatima")*('Sales Entry'!H5:H89)),SUMPRODUCT(('Sales Entry'!B5:B89>=C6)*('Sales Entry'!B5:B89<=D6)*('Sales Entry'!J5:J89="Omar")*('Sales Entry'!H5:H89))>=SUMPRODUCT(('Sales Entry'!B5:B89>=C6)*('Sales Entry'!B5:B89<=D6)*('Sales Entry'!J5:J89="Sara")*('Sales Entry'!H5:H89)),SUMPRODUCT(('Sales Entry'!B5:B89>=C6)*('Sales Entry'!B5:B89<=D6)*('Sales Entry'!J5:J89="Omar")*('Sales Entry'!H5:H89))>=SUMPRODUCT(('Sales Entry'!B5:B89>=C6)*('Sales Entry'!B5:B89<=D6)*('Sales Entry'!J5:J89="Khalid")*('Sales Entry'!H5:H89))),"Omar",IF(AND(SUMPRODUCT(('Sales Entry'!B5:B89>=C6)*('Sales Entry'!B5:B89<=D6)*('Sales Entry'!J5:J89="Sara")*('Sales Entry'!H5:H89))>=SUMPRODUCT(('Sales Entry'!B5:B89>=C6)*('Sales Entry'!B5:B89<=D6)*('Sales Entry'!J5:J89="Ahmed")*('Sales Entry'!H5:H89)),SUMPRODUCT(('Sales Entry'!B5:B89>=C6)*('Sales Entry'!B5:B89<=D6)*('Sales Entry'!J5:J89="Sara")*('Sales Entry'!H5:H89))>=SUMPRODUCT(('Sales Entry'!B5:B89>=C6)*('Sales Entry'!B5:B89<=D6)*('Sales Entry'!J5:J89="Fatima")*('Sales Entry'!H5:H89)),SUMPRODUCT(('Sales Entry'!B5:B89>=C6)*('Sales Entry'!B5:B89<=D6)*('Sales Entry'!J5:J89="Sara")*('Sales Entry'!H5:H89))>=SUMPRODUCT(('Sales Entry'!B5:B89>=C6)*('Sales Entry'!B5:B89<=D6)*('Sales Entry'!J5:J89="Omar")*('Sales Entry'!H5:H89)),SUMPRODUCT(('Sales Entry'!B5:B89>=C6)*('Sales Entry'!B5:B89<=D6)*('Sales Entry'!J5:J89="Sara")*('Sales Entry'!H5:H89))>=SUMPRODUCT(('Sales Entry'!B5:B89>=C6)*('Sales Entry'!B5:B89<=D6)*('Sales Entry'!J5:J89="Khalid")*('Sales Entry'!H5:H89))),"Sara","Khalid"))))
B7: 3 | C7: 45703 | D7: 45709 | E7: =SUMPRODUCT(('Daily Summary'!B5:B32>=C7)*('Daily Summary'!B5:B32<=D7)*('Daily Summary'!C5:C32)) | F7: =SUMPRODUCT(('Daily Summary'!B5:B32>=C7)*('Daily Summary'!B5:B32<=D7)*('Daily Summary'!D5:D32)) | G7: =IFERROR(E7/F7,0) | H7: =IF(AND(SUMPRODUCT(('Sales Entry'!B5:B89>=C7)*('Sales Entry'!B5:B89<=D7)*('Sales Entry'!J5:J89="Ahmed")*('Sales Entry'!H5:H89))>=SUMPRODUCT(('Sales Entry'!B5:B89>=C7)*('Sales Entry'!B5:B89<=D7)*('Sales Entry'!J5:J89="Fatima")*('Sales Entry'!H5:H89)),SUMPRODUCT(('Sales Entry'!B5:B89>=C7)*('Sales Entry'!B5:B89<=D7)*('Sales Entry'!J5:J89="Ahmed")*('Sales Entry'!H5:H89))>=SUMPRODUCT(('Sales Entry'!B5:B89>=C7)*('Sales Entry'!B5:B89<=D7)*('Sales Entry'!J5:J89="Omar")*('Sales Entry'!H5:H89)),SUMPRODUCT(('Sales Entry'!B5:B89>=C7)*('Sales Entry'!B5:B89<=D7)*('Sales Entry'!J5:J89="Ahmed")*('Sales Entry'!H5:H89))>=SUMPRODUCT(('Sales Entry'!B5:B89>=C7)*('Sales Entry'!B5:B89<=D7)*('Sales Entry'!J5:J89="Sara")*('Sales Entry'!H5:H89)),SUMPRODUCT(('Sales Entry'!B5:B89>=C7)*('Sales Entry'!B5:B89<=D7)*('Sales Entry'!J5:J89="Ahmed")*('Sales Entry'!H5:H89))>=SUMPRODUCT(('Sales Entry'!B5:B89>=C7)*('Sales Entry'!B5:B89<=D7)*('Sales Entry'!J5:J89="Khalid")*('Sales Entry'!H5:H89))),"Ahmed",IF(AND(SUMPRODUCT(('Sales Entry'!B5:B89>=C7)*('Sales Entry'!B5:B89<=D7)*('Sales Entry'!J5:J89="Fatima")*('Sales Entry'!H5:H89))>=SUMPRODUCT(('Sales Entry'!B5:B89>=C7)*('Sales Entry'!B5:B89<=D7)*('Sales Entry'!J5:J89="Ahmed")*('Sales Entry'!H5:H89)),SUMPRODUCT(('Sales Entry'!B5:B89>=C7)*('Sales Entry'!B5:B89<=D7)*('Sales Entry'!J5:J89="Fatima")*('Sales Entry'!H5:H89))>=SUMPRODUCT(('Sales Entry'!B5:B89>=C7)*('Sales Entry'!B5:B89<=D7)*('Sales Entry'!J5:J89="Omar")*('Sales Entry'!H5:H89)),SUMPRODUCT(('Sales Entry'!B5:B89>=C7)*('Sales Entry'!B5:B89<=D7)*('Sales Entry'!J5:J89="Fatima")*('Sales Entry'!H5:H89))>=SUMPRODUCT(('Sales Entry'!B5:B89>=C7)*('Sales Entry'!B5:B89<=D7)*('Sales Entry'!J5:J89="Sara")*('Sales Entry'!H5:H89)),SUMPRODUCT(('Sales Entry'!B5:B89>=C7)*('Sales Entry'!B5:B89<=D7)*('Sales Entry'!J5:J89="Fatima")*('Sales Entry'!H5:H89))>=SUMPRODUCT(('Sales Entry'!B5:B89>=C7)*('Sales Entry'!B5:B89<=D7)*('Sales Entry'!J5:J89="Khalid")*('Sales Entry'!H5:H89))),"Fatima",IF(AND(SUMPRODUCT(('Sales Entry'!B5:B89>=C7)*('Sales Entry'!B5:B89<=D7)*('Sales Entry'!J5:J89="Omar")*('Sales Entry'!H5:H89))>=SUMPRODUCT(('Sales Entry'!B5:B89>=C7)*('Sales Entry'!B5:B89<=D7)*('Sales Entry'!J5:J89="Ahmed")*('Sales Entry'!H5:H89)),SUMPRODUCT(('Sales Entry'!B5:B89>=C7)*('Sales Entry'!B5:B89<=D7)*('Sales Entry'!J5:J89="Omar")*('Sales Entry'!H5:H89))>=SUMPRODUCT(('Sales Entry'!B5:B89>=C7)*('Sales Entry'!B5:B89<=D7)*('Sales Entry'!J5:J89="Fatima")*('Sales Entry'!H5:H89)),SUMPRODUCT(('Sales Entry'!B5:B89>=C7)*('Sales Entry'!B5:B89<=D7)*('Sales Entry'!J5:J89="Omar")*('Sales Entry'!H5:H89))>=SUMPRODUCT(('Sales Entry'!B5:B89>=C7)*('Sales Entry'!B5:B89<=D7)*('Sales Entry'!J5:J89="Sara")*('Sales Entry'!H5:H89)),SUMPRODUCT(('Sales Entry'!B5:B89>=C7)*('Sales Entry'!B5:B89<=D7)*('Sales Entry'!J5:J89="Omar")*('Sales Entry'!H5:H89))>=SUMPRODUCT(('Sales Entry'!B5:B89>=C7)*('Sales Entry'!B5:B89<=D7)*('Sales Entry'!J5:J89="Khalid")*('Sales Entry'!H5:H89))),"Omar",IF(AND(SUMPRODUCT(('Sales Entry'!B5:B89>=C7)*('Sales Entry'!B5:B89<=D7)*('Sales Entry'!J5:J89="Sara")*('Sales Entry'!H5:H89))>=SUMPRODUCT(('Sales Entry'!B5:B89>=C7)*('Sales Entry'!B5:B89<=D7)*('Sales Entry'!J5:J89="Ahmed")*('Sales Entry'!H5:H89)),SUMPRODUCT(('Sales Entry'!B5:B89>=C7)*('Sales Entry'!B5:B89<=D7)*('Sales Entry'!J5:J89="Sara")*('Sales Entry'!H5:H89))>=SUMPRODUCT(('Sales Entry'!B5:B89>=C7)*('Sales Entry'!B5:B89<=D7)*('Sales Entry'!J5:J89="Fatima")*('Sales Entry'!H5:H89)),SUMPRODUCT(('Sales Entry'!B5:B89>=C7)*('Sales Entry'!B5:B89<=D7)*('Sales Entry'!J5:J89="Sara")*('Sales Entry'!H5:H89))>=SUMPRODUCT(('Sales Entry'!B5:B89>=C7)*('Sales Entry'!B5:B89<=D7)*('Sales Entry'!J5:J89="Omar")*('Sales Entry'!H5:H89)),SUMPRODUCT(('Sales Entry'!B5:B89>=C7)*('Sales Entry'!B5:B89<=D7)*('Sales Entry'!J5:J89="Sara")*('Sales Entry'!H5:H89))>=SUMPRODUCT(('Sales Entry'!B5:B89>=C7)*('Sales Entry'!B5:B89<=D7)*('Sales Entry'!J5:J89="Khalid")*('Sales Entry'!H5:H89))),"Sara","Khalid"))))
B8: 4 | C8: 45710 | D8: 45716 | E8: =SUMPRODUCT(('Daily Summary'!B5:B32>=C8)*('Daily Summary'!B5:B32<=D8)*('Daily Summary'!C5:C32)) | F8: =SUMPRODUCT(('Daily Summary'!B5:B32>=C8)*('Daily Summary'!B5:B32<=D8)*('Daily Summary'!D5:D32)) | G8: =IFERROR(E8/F8,0) | H8: =IF(AND(SUMPRODUCT(('Sales Entry'!B5:B89>=C8)*('Sales Entry'!B5:B89<=D8)*('Sales Entry'!J5:J89="Ahmed")*('Sales Entry'!H5:H89))>=SUMPRODUCT(('Sales Entry'!B5:B89>=C8)*('Sales Entry'!B5:B89<=D8)*('Sales Entry'!J5:J89="Fatima")*('Sales Entry'!H5:H89)),SUMPRODUCT(('Sales Entry'!B5:B89>=C8)*('Sales Entry'!B5:B89<=D8)*('Sales Entry'!J5:J89="Ahmed")*('Sales Entry'!H5:H89))>=SUMPRODUCT(('Sales Entry'!B5:B89>=C8)*('Sales Entry'!B5:B89<=D8)*('Sales Entry'!J5:J89="Omar")*('Sales Entry'!H5:H89)),SUMPRODUCT(('Sales Entry'!B5:B89>=C8)*('Sales Entry'!B5:B89<=D8)*('Sales Entry'!J5:J89="Ahmed")*('Sales Entry'!H5:H89))>=SUMPRODUCT(('Sales Entry'!B5:B89>=C8)*('Sales Entry'!B5:B89<=D8)*('Sales Entry'!J5:J89="Sara")*('Sales Entry'!H5:H89)),SUMPRODUCT(('Sales Entry'!B5:B89>=C8)*('Sales Entry'!B5:B89<=D8)*('Sales Entry'!J5:J89="Ahmed")*('Sales Entry'!H5:H89))>=SUMPRODUCT(('Sales Entry'!B5:B89>=C8)*('Sales Entry'!B5:B89<=D8)*('Sales Entry'!J5:J89="Khalid")*('Sales Entry'!H5:H89))),"Ahmed",IF(AND(SUMPRODUCT(('Sales Entry'!B5:B89>=C8)*('Sales Entry'!B5:B89<=D8)*('Sales Entry'!J5:J89="Fatima")*('Sales Entry'!H5:H89))>=SUMPRODUCT(('Sales Entry'!B5:B89>=C8)*('Sales Entry'!B5:B89<=D8)*('Sales Entry'!J5:J89="Ahmed")*('Sales Entry'!H5:H89)),SUMPRODUCT(('Sales Entry'!B5:B89>=C8)*('Sales Entry'!B5:B89<=D8)*('Sales Entry'!J5:J89="Fatima")*('Sales Entry'!H5:H89))>=SUMPRODUCT(('Sales Entry'!B5:B89>=C8)*('Sales Entry'!B5:B89<=D8)*('Sales Entry'!J5:J89="Omar")*('Sales Entry'!H5:H89)),SUMPRODUCT(('Sales Entry'!B5:B89>=C8)*('Sales Entry'!B5:B89<=D8)*('Sales Entry'!J5:J89="Fatima")*('Sales Entry'!H5:H89))>=SUMPRODUCT(('Sales Entry'!B5:B89>=C8)*('Sales Entry'!B5:B89<=D8)*('Sales Entry'!J5:J89="Sara")*('Sales Entry'!H5:H89)),SUMPRODUCT(('Sales Entry'!B5:B89>=C8)*('Sales Entry'!B5:B89<=D8)*('Sales Entry'!J5:J89="Fatima")*('Sales Entry'!H5:H89))>=SUMPRODUCT(('Sales Entry'!B5:B89>=C8)*('Sales Entry'!B5:B89<=D8)*('Sales Entry'!J5:J89="Khalid")*('Sales Entry'!H5:H89))),"Fatima",IF(AND(SUMPRODUCT(('Sales Entry'!B5:B89>=C8)*('Sales Entry'!B5:B89<=D8)*('Sales Entry'!J5:J89="Omar")*('Sales Entry'!H5:H89))>=SUMPRODUCT(('Sales Entry'!B5:B89>=C8)*('Sales Entry'!B5:B89<=D8)*('Sales Entry'!J5:J89="Ahmed")*('Sales Entry'!H5:H89)),SUMPRODUCT(('Sales Entry'!B5:B89>=C8)*('Sales Entry'!B5:B89<=D8)*('Sales Entry'!J5:J89="Omar")*('Sales Entry'!H5:H89))>=SUMPRODUCT(('Sales Entry'!B5:B89>=C8)*('Sales Entry'!B5:B89<=D8)*('Sales Entry'!J5:J89="Fatima")*('Sales Entry'!H5:H89)),SUMPRODUCT(('Sales Entry'!B5:B89>=C8)*('Sales Entry'!B5:B89<=D8)*('Sales Entry'!J5:J89="Omar")*('Sales Entry'!H5:H89))>=SUMPRODUCT(('Sales Entry'!B5:B89>=C8)*('Sales Entry'!B5:B89<=D8)*('Sales Entry'!J5:J89="Sara")*('Sales Entry'!H5:H89)),SUMPRODUCT(('Sales Entry'!B5:B89>=C8)*('Sales Entry'!B5:B89<=D8)*('Sales Entry'!J5:J89="Omar")*('Sales Entry'!H5:H89))>=SUMPRODUCT(('Sales Entry'!B5:B89>=C8)*('Sales Entry'!B5:B89<=D8)*('Sales Entry'!J5:J89="Khalid")*('Sales Entry'!H5:H89))),"Omar",IF(AND(SUMPRODUCT(('Sales Entry'!B5:B89>=C8)*('Sales Entry'!B5:B89<=D8)*('Sales Entry'!J5:J89="Sara")*('Sales Entry'!H5:H89))>=SUMPRODUCT(('Sales Entry'!B5:B89>=C8)*('Sales Entry'!B5:B89<=D8)*('Sales Entry'!J5:J89="Ahmed")*('Sales Entry'!H5:H89)),SUMPRODUCT(('Sales Entry'!B5:B89>=C8)*('Sales Entry'!B5:B89<=D8)*('Sales Entry'!J5:J89="Sara")*('Sales Entry'!H5:H89))>=SUMPRODUCT(('Sales Entry'!B5:B89>=C8)*('Sales Entry'!B5:B89<=D8)*('Sales Entry'!J5:J89="Fatima")*('Sales Entry'!H5:H89)),SUMPRODUCT(('Sales Entry'!B5:B89>=C8)*('Sales Entry'!B5:B89<=D8)*('Sales Entry'!J5:J89="Sara")*('Sales Entry'!H5:H89))>=SUMPRODUCT(('Sales Entry'!B5:B89>=C8)*('Sales Entry'!B5:B89<=D8)*('Sales Entry'!J5:J89="Omar")*('Sales Entry'!H5:H89)),SUMPRODUCT(('Sales Entry'!B5:B89>=C8)*('Sales Entry'!B5:B89<=D8)*('Sales Entry'!J5:J89="Sara")*('Sales Entry'!H5:H89))>=SUMPRODUCT(('Sales Entry'!B5:B89>=C8)*('Sales Entry'!B5:B89<=D8)*('Sales Entry'!J5:J89="Khalid")*('Sales Entry'!H5:H89))),"Sara","Khalid"))))
B9: TOTAL | E9: =SUM(E5:E8) | F9: =SUM(F5:F8) | G9: =IFERROR(E9/F9,0)

Sheet Monthly Summary
B2: Monthly Summary — February 2025
B4: Month | C4: Total Sales | D4: # Transactions | E4: Avg Transaction | F4: Best Day Sales | G4: Best Day Date
B5: February 2025 | C5: =SUM('Daily Summary'!C5:C32) | D5: =SUM('Daily Summary'!D5:D32) | E5: =IFERROR(C5/D5,0) | F5: =MAX('Daily Summary'!C5:C32) | G5: =INDEX('Daily Summary'!B5:B32,MATCH(F5,'Daily Summary'!C5:C32,0))
B6: TOTAL | C6: =C5 | D6: =D5 | E6: =IFERROR(C6/D6,0)

Sheet Invoice
B2: Al Noor Supermarket
B3: Your Neighbourhood Grocery — Dubai, UAE
B4: Tel: +971-4-XXX-XXXX | VAT: 10XXXXXX000X3
B7: Invoice #: | C7: INV-0085 | F7: Date: | G7: 10-Feb-2025
B8: Customer: | C8: Regular Customer | F8: Staff: | G8: Fatima
B9: Payment: | C9: Card
B11: # | C11: Item | D11: Category | E11: Qty | F11: Unit Price | G11: Total
B12: 1 | C12: Rice (5kg) | D12: Grains | E12: 2 | F12: 35 | G12: =E12*F12
B13: 2 | C13: Milk (1L) | D13: Dairy | E13: 3 | F13: 8 | G13: =E13*F13
B14: 3 | C14: Chicken (kg) | D14: Meat | E14: 1 | F14: 28 | G14: =E14*F14
B15: 4 | C15: Cooking Oil (1L) | D15: Grains | E15: 2 | F15: 22 | G15: =E15*F15
B16: 5 | C16: Eggs (12pc) | D16: Dairy | E16: 1 | F16: 12 | G16: =E16*F16
B17: 6 | C17: Orange Juice (1L) | D17: Beverages | E17: 2 | F17: 6 | G17: =E17*F17
E19: Subtotal: | G19: =SUM(G12:G17)
E20: VAT (5%): | G20: =G19*0.05
E21: Discount: | G21: -10
E22: Grand Total: | G22: =G19+G20+G21
B24: Thank you for shopping at Al Noor Supermarket!

Sheet Inventory
B2: Inventory — Al Noor Supermarket
B4: Product ID | C4: Item Name | D4: Category | E4: Unit Price | F4: Stock Qty | G4: Reorder Level | H4: Status | I4: Supplier | J4: Last Restocked
B5: PRD001 | C5: Rice (5kg) | D5: Grains | E5: 35 | F5: 120 | G5: 30 | H5: =IF(F5<=G5,"LOW STOCK","In Stock") | I5: Al Falaj | J5: 45708
B6: PRD002 | C6: Milk (1L) | D6: Dairy | E6: 8 | F6: 45 | G6: 50 | H6: =IF(F6<=G6,"LOW STOCK","In Stock") | I6: GCC Foods | J6: 45713
B7: PRD003 | C7: Bread | D7: Bakery | E7: 5 | F7: 80 | G7: 40 | H7: =IF(F7<=G7,"LOW STOCK","In Stock") | I7: Emirates Trading | J7: 45715
B8: PRD004 | C8: Eggs (12pc) | D8: Dairy | E8: 12 | F8: 35 | G8: 30 | H8: =IF(F8<=G8,"LOW STOCK","In Stock") | I8: GCC Foods | J8: 45710
B9: PRD005 | C9: Chicken (kg) | D9: Meat | E9: 28 | F9: 15 | G9: 20 | H9: =IF(F9<=G9,"LOW STOCK","In Stock") | I9: Al Falaj | J9: 45714
B10: PRD006 | C10: Cooking Oil (1L) | D10: Grains | E10: 22 | F10: 60 | G10: 25 | H10: =IF(F10<=G10,"LOW STOCK","In Stock") | I10: Emirates Trading | J10: 45706
B11: PRD007 | C11: Water (6pk) | D11: Beverages | E11: 2 | F11: 200 | G11: 100 | H11: =IF(F11<=G11,"LOW STOCK","In Stock") | I11: GCC Foods | J11: 45712
B12: PRD008 | C12: Orange Juice (1L) | D12: Beverages | E12: 6 | F12: 30 | G12: 25 | H12: =IF(F12<=G12,"LOW STOCK","In Stock") | I12: GCC Foods | J12: 45711
B13: PRD009 | C13: Pasta (500g) | D13: Grains | E13: 4 | F13: 90 | G13: 40 | H13: =IF(F13<=G13,"LOW STOCK","In Stock") | I13: Emirates Trading | J13: 45707
B14: PRD010 | C14: Tomatoes (kg) | D14: Produce | E14: 6 | F14: 8 | G14: 15 | H14: =IF(F14<=G14,"LOW STOCK","In Stock") | I14: Al Falaj | J14: 45713
B15: PRD011 | C15: Potatoes (kg) | D15: Produce | E15: 4 | F15: 50 | G15: 20 | H15: =IF(F15<=G15,"LOW STOCK","In Stock") | I15: Al Falaj | J15: 45709
B16: PRD012 | C16: Onions (kg) | D16: Produce | E16: 3 | F16: 55 | G16: 25 | H16: =IF(F16<=G16,"LOW STOCK","In Stock") | I16: Al Falaj | J16: 45709
... B32: PRD028 | C32: Fish (kg) | D32: Meat | E32: 32 | F32: 3 | G32: 5 | H32: =IF(F32<=G32,"LOW STOCK","In Stock") | I32: Al Falaj | J32: 45715

Sheet Staff Performance
B2: Staff Performance — February 2025
B4: Staff Name | C4: Total Sales | D4: # Transactions | E4: Avg Transaction | F4: Top Category | G4: Shift | H4: Commission (5%)
B5: Ahmed | C5: =SUMPRODUCT(('Sales Entry'!J5:J89="Ahmed")*('Sales Entry'!H5:H89)) | D5: =SUMPRODUCT(('Sales Entry'!J5:J89="Ahmed")*1) | E5: =IFERROR(C5/D5,0) | F5: =IF(AND(SUMPRODUCT(('Sales Entry'!J5:J89="Ahmed")*('Sales Entry'!E5:E89="Dairy")*('Sales Entry'!H5:H89))>=SUMPRODUCT(('Sales Entry'!J5:J89="Ahmed")*('Sales Entry'!E5:E89="Bakery")*('Sales Entry'!H5:H89)),SUMPRODUCT(('Sales Entry'!J5:J89="Ahmed")*('Sales Entry'!E5:E89="Dairy")*('Sales Entry'!H5:H89))>=SUMPRODUCT(('Sales Entry'!J5:J89="Ahmed")*('Sales Entry'!E5:E89="Meat")*('Sales Entry'!H5:H89)),SUMPRODUCT(('Sales Entry'!J5:J89="Ahmed")*('Sales Entry'!E5:E89="Dairy")*('Sales Entry'!H5:H89))>=SUMPRODUCT(('Sales Entry'!J5:J89="Ahmed")*('Sales Entry'!E5:E89="Beverages")*('Sales Entry'!H5:H89)),SUMPRODUCT(('Sales Entry'!J5:J89="Ahmed")*('Sales Entry'!E5:E89="Dairy")*('Sales Entry'!H5:H89))>=SUMPRODUCT(('Sales Entry'!J5:J89="Ahmed")*('Sales Entry'!E5:E89="Snacks")*('Sales Entry'!H5:H89)),SUMPRODUCT(('Sales Entry'!J5:J89="Ahmed")*('Sales Entry'!E5:E89="Dairy")*('Sales Entry'!H5:H89))>=SUMPRODUCT(('Sales Entry'!J5:J89="Ahmed")*('Sales Entry'!E5:E89="Cleaning")*('Sales Entry'!H5:H89)),SUMPRODUCT(('Sales Entry'!J5:J89="Ahmed")*('Sales Entry'!E5:E89="Dairy")*('Sales Entry'!H5:H89))>=SUMPRODUCT(('Sales Entry'!J5:J89="Ahmed")*('Sales Entry'!E5:E89="Produce")*('Sales Entry'!H5:H89)),SUMPRODUCT(('Sales Entry'!J5:J89="Ahmed")*('Sales Entry'!E5:E89="Dairy")*('Sales Entry'!H5:H89))>=SUMPRODUCT(('Sales Entry'!J5:J89="Ahmed")*('Sales Entry'!E5:E89="Grains")*('Sales Entry'!H5:H89))),"Dairy",IF(AND(SUMPRODUCT(('Sales Entry'!J5:J89="Ahmed")*('Sales Entry'!E5:E89="Bakery")*('Sales Entry'!H5:H89))>=SUMPRODUCT(('Sales Entry'!J5:J89="Ahmed")*('Sales Entry'!E5:E89="Dairy")*('Sales Entry'!H5:H89)),SUMPRODUCT(('Sales Entry'!J5:J89="Ahmed")*('Sales Entry'!E5:E89="Bakery")*('Sales Entry'!H5:H89))>=SUMPRODUCT(('Sales Entry'!J5:J89="Ahmed")*('Sales Entry'!E5:E89="Meat")*('Sales Entry'!H5:H89)),SUMPRODUCT(('Sales Entry'!J5:J89="Ahmed")*('Sales Entry'!E5:E89="Bakery")*('Sales Entry'!H5:H89))>=SUMPRODUCT(('Sales Entry'!J5:J89="Ahmed")*('Sales Entry'!E5:E89="Beverages")*('Sales Entry'!H5:H89)),SUMPRODUCT(('Sales Entry'!J5:J89="Ahmed")*('Sales Entry'!E5:E89="Bakery")*('Sales Entry'!H5:H89))>=SUMPRODUCT(('Sales Entry'!J5:J89="Ahmed")*('Sales Entry'!E5:E89="Snacks")*('Sales Entry'!H5:H89)),SUMPRODUCT(('Sales Entry'!J5:J89="Ahmed")*('Sales Entry'!E5:E89="Bakery")*('Sales Entry'!H5:H89))>=SUMPRODUCT(('Sales Entry'!J5:J89="Ahmed")*('Sales Entry'!E5:E89="Cleaning")*('Sales Entry'!H5:H89)),SUMPRODUCT(('Sales Entry'!J5:J89="Ahmed")*('Sales Entry'!E5:E89="Bakery")*('Sales Entry'!H5:H89))>=SUMPRODUCT(('Sales Entry'!J5:J89="Ahmed")*('Sales Entry'!E5:E89="Produce")*('Sales Entry'!H5:H89)),SUMPRODUCT(('Sales Entry'!J5:J89="Ahmed")*('Sales Entry'!E5:E89="Bakery")*('Sales Entry'!H5:H89))>=SUMPRODUCT(('Sales Entry'!J5:J89="Ahmed")*('Sales Entry'!E5:E89="Grains")*('Sales Entry'!H5:H89))),"Bakery",IF(AND(SUMPRODUCT(('Sales Entry'!J5:J89="Ahmed")*('Sales Entry'!E5:E89="Meat")*('Sales Entry'!H5:H89))>=SUMPRODUCT(('Sales Entry'!J5:J89="Ahmed")*('Sales Entry'!E5:E89="Dairy")*('Sales Entry'!H5:H89)),SUMPRODUCT(('Sales Entry'!J5:J89="Ahmed")*('Sales Entry'!E5:E89="Meat")*('Sales Entry'!H5:H89))>=SUMPRODUCT(('Sales Entry'!J5:J89="Ahmed")*('Sales Entry'!E5:E89="Bakery")*('Sales Entry'!H5:H89)),SUMPRODUCT(('Sales Entry'!J5:J89="Ahmed")*('Sales Entry'!E5:E89="Meat")*('Sales Entry'!H5:H89))>=SUMPRODUCT(('Sales Entry'!J5:J89="Ahmed")*('Sales Entry'!E5:E89="Beverages")*('Sales Entry'!H5:H89)),SUMPRODUCT(('Sales Entry'!J5:J89="Ahmed")*('Sales Entry'!E5:E89="Meat")*('Sales Entry'!H5:H89))>=SUMPRODUCT(('Sales Entry'!J5:J89="Ahmed")*('Sales Entry'!E5:E89="Snacks")*('Sales Entry'!H5:H89)),SUMPRODUCT(('Sales Entry'!J5:J89="Ahmed")*('Sales Entry'!E5:E89="Meat")*('Sales Entry'!H5:H89))>=SUMPRODUCT(('Sales Entry'!J5:J89="Ahmed")*('Sales Entry'!E5:E89="Cleaning")*('Sales Entry'!H5:H89)),SUMPRODUCT(('Sales Entry'!J5:J89="Ahmed")*('Sales Entry'!E5:E89="Meat")*('Sales Entry'!H5:H89))>=SUMPRODUCT(('Sales Entry'!J5:J89="Ahmed")*('Sales Entry'!E5:E89="Produce")*('Sales Entry'!H5:H89)),SUMPRODUCT(('Sales Entry'!J5:J89="Ahmed")*('Sales Entry'!E5:E89="Meat")*('Sales Entry'!H5:H89))>=SUMPRODUCT(('Sales Entry'!J5:J89="Ahmed")*('Sales Entry'!E5:E89="Grains")*('Sales Entry'!H5:H89))),"Meat",IF(AND(SUMPRODUCT(('Sales Entry'!J5:J89="Ahmed")*('Sales Entry'!E5:E89="Beverages")*('Sales Entry'!H5:H89))>=SUMPRODUCT(('Sales Entry'!J5:J89="Ahmed")*('Sales Entry'!E5:E89="Dairy")*('Sales Entry'!H5:H89)),SUMPRODUCT(('Sales Entry'!J5:J89="Ahmed")*('Sales Entry'!E5:E89="Beverages")*('Sales Entry'!H5:H89))>=SUMPRODUCT(('Sales Entry'!J5:J89="Ahmed")*('Sales Entry'!E5:E89="Bakery")*('Sales Entry'!H5:H89)),SUMPRODUCT(('Sales Entry'!J5:J89="Ahmed")*('Sales Entry'!E5:E89="Beverages")*('Sales Entry'!H5:H89))>=SUMPRODUCT(('Sales Entry'!J5:J89="Ahmed")*('Sales Entry'!E5:E89="Meat")*('Sales Entry'!H5:H89)),SUMPRODUCT(('Sales Entry'!J5:J89="Ahmed")*('Sales Entry'!E5:E89="Beverages")*('Sales Entry'!H5:H89))>=SUMPRODUCT(('Sales Entry'!J5:J89="Ahmed")*('Sales Entry'!E5:E89="Snacks")*('Sales Entry'!H5:H89)),SUMPRODUCT(('Sales Entry'!J5:J89="Ahmed")*('Sales Entry'!E5:E89="Beverages")*('Sales Entry'!H5:H89))>=SUMPRODUCT(('Sales Entry'!J5:J89="Ahmed")*('Sales Entry'!E5:E89="Cleaning")*('Sales Entry'!H5:H89)),SUMPRODUCT(('Sales Entry'!J5:J89="Ahmed")*('Sales Entry'!E5:E89="Beverages")*('Sales Entry'!H5:H89))>=SUMPRODUCT(('Sales Entry'!J5:J89="Ahmed")*('Sales Entry'!E5:E89="Produce")*('Sales Entry'!H5:H89)),SUMPRODUCT(('Sales Entry'!J5:J89="Ahmed")*('Sales Entry'!E5:E89="Beverages")*('Sales Entry'!H5:H89))>=SUMPRODUCT(('Sales Entry'!J5:J89="Ahmed")*('Sales Entry'!E5:E89="Grains")*('Sales Entry'!H5:H89))),"Beverages",IF(AND(SUMPRODUCT(('Sales Entry'!J5:J89="Ahmed")*('Sales Entry'!E5:E89="Snacks")*('Sales Entry'!H5:H89))>=SUMPRODUCT(('Sales Entry'!J5:J89="Ahmed")*('Sales Entry'!E5:E89="Dairy")*('Sales Entry'!H5:H89)),SUMPRODUCT(('Sales Entry'!J5:J89="Ahmed")*('Sales Entry'!E5:E89="Snacks")*('Sales Entry'!H5:H89))>=SUMPRODUCT(('Sales Entry'!J5:J89="Ahmed")*('Sales Entry'!E5:E89="Bakery")*('Sales Entry'!H5:H89)),SUMPRODUCT(('Sales Entry'!J5:J89="Ahmed")*('Sales Entry'!E5:E89="Snacks")*('Sales Entry'!H5:H89))>=SUMPRODUCT(('Sales Entry'!J5:J89="Ahmed")*('Sales Entry'!E5:E89="Meat")*('Sales Entry'!H5:H89)),SUMPRODUCT(('Sales Entry'!J5:J89="Ahmed")*('Sales Entry'!E5:E89="Snacks")*('Sales Entry'!H5:H89))>=SUMPRODUCT(('Sales Entry'!J5:J89="Ahmed")*('Sales Entry'!E5:E89="Beverages")*('Sales Entry'!H5:H89)),SUMPRODUCT(('Sales Entry'!J5:J89="Ahmed")*('Sales Entry'!E5:E89="Snacks")*('Sales Entry'!H5:H89))>=SUMPRODUCT(('Sales Entry'!J5:J89="Ahmed")*('Sales Entry'!E5:E89="Cleaning")*('Sales Entry'!H5:H89)),SUMPRODUCT(('Sales Entry'!J5:J89="Ahmed")*('Sales Entry'!E5:E89="Snacks")*('Sales Entry'!H5:H89))>=SUMPRODUCT(('Sales Entry'!J5:J89="Ahmed")*('Sales Entry'!E5:E89="Produce")*('Sales Entry'!H5:H89)),SUMPRODUCT(('Sales Entry'!J5:J89="Ahmed")*('Sales Entry'!E5:E89="Snacks")*('Sales Entry'!H5:H89))>=SUMPRODUCT(('Sales Entry'!J5:J89="Ahmed")*('Sales Entry'!E5:E89="Grains")*('Sales Entry'!H5:H89))),"Snacks",IF(AND(SUMPRODUCT(('Sales Entry'!J5:J89="Ahmed")*('Sales Entry'!E5:E89="Cleaning")*('Sales Entry'!H5:H89))>=SUMPRODUCT(('Sales Entry'!J5:J89="Ahmed")*('Sales Entry'!E5:E89="Dairy")*('Sales Entry'!H5:H89)),SUMPRODUCT(('Sales Entry'!J5:J89="Ahmed")*('Sales Entry'!E5:E89="Cleaning")*('Sales Entry'!H5:H89))>=SUMPRODUCT(('Sales Entry'!J5:J89="Ahmed")*('Sales Entry'!E5:E89="Bakery")*('Sales Entry'!H5:H89)),SUMPRODUCT(('Sales Entry'!J5:J89="Ahmed")*('Sales Entry'!E5:E89="Cleaning")*('Sales Entry'!H5:H89))>=SUMPRODUCT(('Sales Entry'!J5:J89="Ahmed")*('Sales Entry'!E5:E89="Meat")*('Sales Entry'!H5:H89)),SUMPRODUCT(('Sales Entry'!J5:J89="Ahmed")*('Sales Entry'!E5:E89="Cleaning")*('Sales Entry'!H5:H89))>=SUMPRODUCT(('Sales Entry'!J5:J89="Ahmed")*('Sales Entry'!E5:E89="Beverages")*('Sales Entry'!H5:H89)),SUMPRODUCT(('Sales Entry'!J5:J89="Ahmed")*('Sales Entry'!E5:E89="Cleaning")*('Sales Entry'!H5:H89))>=SUMPRODUCT(('Sales Entry'!J5:J89="Ahmed")*('Sales Entry'!E5:E89="Snacks")*('Sales Entry'!H5:H89)),SUMPRODUCT(('Sales Entry'!J5:J89="Ahmed")*('Sales Entry'!E5:E89="Cleaning")*('Sales Entry'!H5:H89))>=SUMPRODUCT(('Sales Entry'!J5:J89="Ahmed")*('Sales Entry'!E5:E89="Produce")*('Sales Entry'!H5:H89)),SUMPRODUCT(('Sales Entry'!J5:J89="Ahmed")*('Sales Entry'!E5:E89="Cleaning")*('Sales Entry'!H5:H89))>=SUMPRODUCT(('Sales Entry'!J5:J89="Ahmed")*('Sales Entry'!E5:E89="Grains")*('Sales Entry'!H5:H89))),"Cleaning",IF(AND(SUMPRODUCT(('Sales Entry'!J5:J89="Ahmed")*('Sales Entry'!E5:E89="Produce")*('Sales Entry'!H5:H89))>=SUMPRODUCT(('Sales Entry'!J5:J89="Ahmed")*('Sales Entry'!E5:E89="Dairy")*('Sales Entry'!H5:H89)),SUMPRODUCT(('Sales Entry'!J5:J89="Ahmed")*('Sales Entry'!E5:E89="Produce")*('Sales Entry'!H5:H89))>=SUMPRODUCT(('Sales Entry'!J5:J89="Ahmed")*('Sales Entry'!E5:E89="Bakery")*('Sales Entry'!H5:H89)),SUMPRODUCT(('Sales Entry'!J5:J89="Ahmed")*('Sales Entry'!E5:E89="Produce")*('Sales Entry'!H5:H89))>=SUMPRODUCT(('Sales Entry'!J5:J89="Ahmed")*('Sales Entry'!E5:E89="Meat")*('Sales Entry'!H5:H89)),SUMPRODUCT(('Sales Entry'!J5:J89="Ahmed")*('Sales Entry'!E5:E89="Produce")*('Sales Entry'!H5:H89))>=SUMPRODUCT(('Sales Entry'!J5:J89="Ahmed")*('Sales Entry'!E5:E89="Beverages")*('Sales Entry'!H5:H89)),SUMPRODUCT(('Sales Entry'!J5:J89="Ahmed")*('Sales Entry'!E5:E89="Produce")*('Sales Entry'!H5:H89))>=SUMPRODUCT(('Sales Entry'!J5:J89="Ahmed")*('Sales Entry'!E5:E89="Snacks")*('Sales Entry'!H5:H89)),SUMPRODUCT(('Sales Entry'!J5:J89="Ahmed")*('Sales Entry'!E5:E89="Produce")*('Sales Entry'!H5:H89))>=SUMPRODUCT(('Sales Entry'!J5:J89="Ahmed")*('Sales Entry'!E5:E89="Cleaning")*('Sales Entry'!H5:H89)),SUMPRODUCT(('Sales Entry'!J5:J89="Ahmed")*('Sales Entry'!E5:E89="Produce")*('Sales Entry'!H5:H89))>=SUMPRODUCT(('Sales Entry'!J5:J89="Ahmed")*('Sales Entry'!E5:E89="Grains")*('Sales Entry'!H5:H89))),"Produce","Grains")))))) | G5: Morning | H5: =C5*0.05
