Workbook

Sheet Sales Entry
B2: Sales Entry — Premium POS
B4: Date | C4: Invoice # | D4: Item/Service | E4: Category | F4: Qty | G4: Unit Price | H4: Total | I4: Payment Method | J4: Staff Name | K4: Customer Name | L4: Discount | M4: Net Total | N4: Notes
H5: =IFERROR(F5*G5,0) | M5: =H5-IFERROR(L5,0)
H6: =IFERROR(F6*G6,0) | M6: =H6-IFERROR(L6,0)
H7: =IFERROR(F7*G7,0) | M7: =H7-IFERROR(L7,0)
H8: =IFERROR(F8*G8,0) | M8: =H8-IFERROR(L8,0)
H9: =IFERROR(F9*G9,0) | M9: =H9-IFERROR(L9,0)
H10: =IFERROR(F10*G10,0) | M10: =H10-IFERROR(L10,0)
H11: =IFERROR(F11*G11,0) | M11: =H11-IFERROR(L11,0)
H12: =IFERROR(F12*G12,0) | M12: =H12-IFERROR(L12,0)
H13: =IFERROR(F13*G13,0) | M13: =H13-IFERROR(L13,0)
H14: =IFERROR(F14*G14,0) | M14: =H14-IFERROR(L14,0)
H15: =IFERROR(F15*G15,0) | M15: =H15-IFERROR(L15,0)
H16: =IFERROR(F16*G16,0) | M16: =H16-IFERROR(L16,0)
... H504: =IFERROR(F504*G504,0) | M504: =H504-IFERROR(L504,0)
B505: TOTAL | F505: =SUM(F5:F504) | H505: =SUM(H5:H504) | L505: =SUM(L5:L504) | M505: =SUM(M5:M504)

Sheet Daily Summary
B2: Daily Summary — Auto-Calculated
B4: Date | C4: Total Sales | D4: # Transactions | E4: Avg Transaction | F4: Cash | G4: Card | H4: Online | I4: Bank Transfer | J4: # Items Sold | K4: Total Discount Given
C5: =SUMPRODUCT(('Sales Entry'!B5:B504=B5)*('Sales Entry'!M5:M504)) | D5: =SUMPRODUCT(('Sales Entry'!B5:B504=B5)*1) | E5: =IFERROR(C5/D5,0) | F5: =SUMPRODUCT(('Sales Entry'!B5:B504=B5)*('Sales Entry'!I5:I504="Cash")*('Sales Entry'!M5:M504)) | G5: =SUMPRODUCT(('Sales Entry'!B5:B504=B5)*('Sales Entry'!I5:I504="Card")*('Sales Entry'!M5:M504)) | H5: =SUMPRODUCT(('Sales Entry'!B5:B504=B5)*('Sales Entry'!I5:I504="Online")*('Sales Entry'!M5:M504)) | I5: =SUMPRODUCT(('Sales Entry'!B5:B504=B5)*('Sales Entry'!I5:I504="Bank Transfer")*('Sales Entry'!M5:M504)) | J5: =SUMPRODUCT(('Sales Entry'!B5:B504=B5)*('Sales Entry'!F5:F504)) | K5: =SUMPRODUCT(('Sales Entry'!B5:B504=B5)*('Sales Entry'!L5:L504))
C6: =SUMPRODUCT(('Sales Entry'!B5:B504=B6)*('Sales Entry'!M5:M504)) | D6: =SUMPRODUCT(('Sales Entry'!B5:B504=B6)*1) | E6: =IFERROR(C6/D6,0) | F6: =SUMPRODUCT(('Sales Entry'!B5:B504=B6)*('Sales Entry'!I5:I504="Cash")*('Sales Entry'!M5:M504)) | G6: =SUMPRODUCT(('Sales Entry'!B5:B504=B6)*('Sales Entry'!I5:I504="Card")*('Sales Entry'!M5:M504)) | H6: =SUMPRODUCT(('Sales Entry'!B5:B504=B6)*('Sales Entry'!I5:I504="Online")*('Sales Entry'!M5:M504)) | I6: =SUMPRODUCT(('Sales Entry'!B5:B504=B6)*('Sales Entry'!I5:I504="Bank Transfer")*('Sales Entry'!M5:M504)) | J6: =SUMPRODUCT(('Sales Entry'!B5:B504=B6)*('Sales Entry'!F5:F504)) | K6: =SUMPRODUCT(('Sales Entry'!B5:B504=B6)*('Sales Entry'!L5:L504))
C7: =SUMPRODUCT(('Sales Entry'!B5:B504=B7)*('Sales Entry'!M5:M504)) | D7: =SUMPRODUCT(('Sales Entry'!B5:B504=B7)*1) | E7: =IFERROR(C7/D7,0) | F7: =SUMPRODUCT(('Sales Entry'!B5:B504=B7)*('Sales Entry'!I5:I504="Cash")*('Sales Entry'!M5:M504)) | G7: =SUMPRODUCT(('Sales Entry'!B5:B504=B7)*('Sales Entry'!I5:I504="Card")*('Sales Entry'!M5:M504)) | H7: =SUMPRODUCT(('Sales Entry'!B5:B504=B7)*('Sales Entry'!I5:I504="Online")*('Sales Entry'!M5:M504)) | I7: =SUMPRODUCT(('Sales Entry'!B5:B504=B7)*('Sales Entry'!I5:I504="Bank Transfer")*('Sales Entry'!M5:M504)) | J7: =SUMPRODUCT(('Sales Entry'!B5:B504=B7)*('Sales Entry'!F5:F504)) | K7: =SUMPRODUCT(('Sales Entry'!B5:B504=B7)*('Sales Entry'!L5:L504))
C8: =SUMPRODUCT(('Sales Entry'!B5:B504=B8)*('Sales Entry'!M5:M504)) | D8: =SUMPRODUCT(('Sales Entry'!B5:B504=B8)*1) | E8: =IFERROR(C8/D8,0) | F8: =SUMPRODUCT(('Sales Entry'!B5:B504=B8)*('Sales Entry'!I5:I504="Cash")*('Sales Entry'!M5:M504)) | G8: =SUMPRODUCT(('Sales Entry'!B5:B504=B8)*('Sales Entry'!I5:I504="Card")*('Sales Entry'!M5:M504)) | H8: =SUMPRODUCT(('Sales Entry'!B5:B504=B8)*('Sales Entry'!I5:I504="Online")*('Sales Entry'!M5:M504)) | I8: =SUMPRODUCT(('Sales Entry'!B5:B504=B8)*('Sales Entry'!I5:I504="Bank Transfer")*('Sales Entry'!M5:M504)) | J8: =SUMPRODUCT(('Sales Entry'!B5:B504=B8)*('Sales Entry'!F5:F504)) | K8: =SUMPRODUCT(('Sales Entry'!B5:B504=B8)*('Sales Entry'!L5:L504))
C9: =SUMPRODUCT(('Sales Entry'!B5:B504=B9)*('Sales Entry'!M5:M504)) | D9: =SUMPRODUCT(('Sales Entry'!B5:B504=B9)*1) | E9: =IFERROR(C9/D9,0) | F9: =SUMPRODUCT(('Sales Entry'!B5:B504=B9)*('Sales Entry'!I5:I504="Cash")*('Sales Entry'!M5:M504)) | G9: =SUMPRODUCT(('Sales Entry'!B5:B504=B9)*('Sales Entry'!I5:I504="Card")*('Sales Entry'!M5:M504)) | H9: =SUMPRODUCT(('Sales Entry'!B5:B504=B9)*('Sales Entry'!I5:I504="Online")*('Sales Entry'!M5:M504)) | I9: =SUMPRODUCT(('Sales Entry'!B5:B504=B9)*('Sales Entry'!I5:I504="Bank Transfer")*('Sales Entry'!M5:M504)) | J9: =SUMPRODUCT(('Sales Entry'!B5:B504=B9)*('Sales Entry'!F5:F504)) | K9: =SUMPRODUCT(('Sales Entry'!B5:B504=B9)*('Sales Entry'!L5:L504))
C10: =SUMPRODUCT(('Sales Entry'!B5:B504=B10)*('Sales Entry'!M5:M504)) | D10: =SUMPRODUCT(('Sales Entry'!B5:B504=B10)*1) | E10: =IFERROR(C10/D10,0) | F10: =SUMPRODUCT(('Sales Entry'!B5:B504=B10)*('Sales Entry'!I5:I504="Cash")*('Sales Entry'!M5:M504)) | G10: =SUMPRODUCT(('Sales Entry'!B5:B504=B10)*('Sales Entry'!I5:I504="Card")*('Sales Entry'!M5:M504)) | H10: =SUMPRODUCT(('Sales Entry'!B5:B504=B10)*('Sales Entry'!I5:I504="Online")*('Sales Entry'!M5:M504)) | I10: =SUMPRODUCT(('Sales Entry'!B5:B504=B10)*('Sales Entry'!I5:I504="Bank Transfer")*('Sales Entry'!M5:M504)) | J10: =SUMPRODUCT(('Sales Entry'!B5:B504=B10)*('Sales Entry'!F5:F504)) | K10: =SUMPRODUCT(('Sales Entry'!B5:B504=B10)*('Sales Entry'!L5:L504))
C11: =SUMPRODUCT(('Sales Entry'!B5:B504=B11)*('Sales Entry'!M5:M504)) | D11: =SUMPRODUCT(('Sales Entry'!B5:B504=B11)*1) | E11: =IFERROR(C11/D11,0) | F11: =SUMPRODUCT(('Sales Entry'!B5:B504=B11)*('Sales Entry'!I5:I504="Cash")*('Sales Entry'!M5:M504)) | G11: =SUMPRODUCT(('Sales Entry'!B5:B504=B11)*('Sales Entry'!I5:I504="Card")*('Sales Entry'!M5:M504)) | H11: =SUMPRODUCT(('Sales Entry'!B5:B504=B11)*('Sales Entry'!I5:I504="Online")*('Sales Entry'!M5:M504)) | I11: =SUMPRODUCT(('Sales Entry'!B5:B504=B11)*('Sales Entry'!I5:I504="Bank Transfer")*('Sales Entry'!M5:M504)) | J11: =SUMPRODUCT(('Sales Entry'!B5:B504=B11)*('Sales Entry'!F5:F504)) | K11: =SUMPRODUCT(('Sales Entry'!B5:B504=B11)*('Sales Entry'!L5:L504))
C12: =SUMPRODUCT(('Sales Entry'!B5:B504=B12)*('Sales Entry'!M5:M504)) | D12: =SUMPRODUCT(('Sales Entry'!B5:B504=B12)*1) | E12: =IFERROR(C12/D12,0) | F12: =SUMPRODUCT(('Sales Entry'!B5:B504=B12)*('Sales Entry'!I5:I504="Cash")*('Sales Entry'!M5:M504)) | G12: =SUMPRODUCT(('Sales Entry'!B5:B504=B12)*('Sales Entry'!I5:I504="Card")*('Sales Entry'!M5:M504)) | H12: =SUMPRODUCT(('Sales Entry'!B5:B504=B12)*('Sales Entry'!I5:I504="Online")*('Sales Entry'!M5:M504)) | I12: =SUMPRODUCT(('Sales Entry'!B5:B504=B12)*('Sales Entry'!I5:I504="Bank Transfer")*('Sales Entry'!M5:M504)) | J12: =SUMPRODUCT(('Sales Entry'!B5:B504=B12)*('Sales Entry'!F5:F504)) | K12: =SUMPRODUCT(('Sales Entry'!B5:B504=B12)*('Sales Entry'!L5:L504))
C13: =SUMPRODUCT(('Sales Entry'!B5:B504=B13)*('Sales Entry'!M5:M504)) | D13: =SUMPRODUCT(('Sales Entry'!B5:B504=B13)*1) | E13: =IFERROR(C13/D13,0) | F13: =SUMPRODUCT(('Sales Entry'!B5:B504=B13)*('Sales Entry'!I5:I504="Cash")*('Sales Entry'!M5:M504)) | G13: =SUMPRODUCT(('Sales Entry'!B5:B504=B13)*('Sales Entry'!I5:I504="Card")*('Sales Entry'!M5:M504)) | H13: =SUMPRODUCT(('Sales Entry'!B5:B504=B13)*('Sales Entry'!I5:I504="Online")*('Sales Entry'!M5:M504)) | I13: =SUMPRODUCT(('Sales Entry'!B5:B504=B13)*('Sales Entry'!I5:I504="Bank Transfer")*('Sales Entry'!M5:M504)) | J13: =SUMPRODUCT(('Sales Entry'!B5:B504=B13)*('Sales Entry'!F5:F504)) | K13: =SUMPRODUCT(('Sales Entry'!B5:B504=B13)*('Sales Entry'!L5:L504))
C14: =SUMPRODUCT(('Sales Entry'!B5:B504=B14)*('Sales Entry'!M5:M504)) | D14: =SUMPRODUCT(('Sales Entry'!B5:B504=B14)*1) | E14: =IFERROR(C14/D14,0) | F14: =SUMPRODUCT(('Sales Entry'!B5:B504=B14)*('Sales Entry'!I5:I504="Cash")*('Sales Entry'!M5:M504)) | G14: =SUMPRODUCT(('Sales Entry'!B5:B504=B14)*('Sales Entry'!I5:I504="Card")*('Sales Entry'!M5:M504)) | H14: =SUMPRODUCT(('Sales Entry'!B5:B504=B14)*('Sales Entry'!I5:I504="Online")*('Sales Entry'!M5:M504)) | I14: =SUMPRODUCT(('Sales Entry'!B5:B504=B14)*('Sales Entry'!I5:I504="Bank Transfer")*('Sales Entry'!M5:M504)) | J14: =SUMPRODUCT(('Sales Entry'!B5:B504=B14)*('Sales Entry'!F5:F504)) | K14: =SUMPRODUCT(('Sales Entry'!B5:B504=B14)*('Sales Entry'!L5:L504))
C15: =SUMPRODUCT(('Sales Entry'!B5:B504=B15)*('Sales Entry'!M5:M504)) | D15: =SUMPRODUCT(('Sales Entry'!B5:B504=B15)*1) | E15: =IFERROR(C15/D15,0) | F15: =SUMPRODUCT(('Sales Entry'!B5:B504=B15)*('Sales Entry'!I5:I504="Cash")*('Sales Entry'!M5:M504)) | G15: =SUMPRODUCT(('Sales Entry'!B5:B504=B15)*('Sales Entry'!I5:I504="Card")*('Sales Entry'!M5:M504)) | H15: =SUMPRODUCT(('Sales Entry'!B5:B504=B15)*('Sales Entry'!I5:I504="Online")*('Sales Entry'!M5:M504)) | I15: =SUMPRODUCT(('Sales Entry'!B5:B504=B15)*('Sales Entry'!I5:I504="Bank Transfer")*('Sales Entry'!M5:M504)) | J15: =SUMPRODUCT(('Sales Entry'!B5:B504=B15)*('Sales Entry'!F5:F504)) | K15: =SUMPRODUCT(('Sales Entry'!B5:B504=B15)*('Sales Entry'!L5:L504))
C16: =SUMPRODUCT(('Sales Entry'!B5:B504=B16)*('Sales Entry'!M5:M504)) | D16: =SUMPRODUCT(('Sales Entry'!B5:B504=B16)*1) | E16: =IFERROR(C16/D16,0) | F16: =SUMPRODUCT(('Sales Entry'!B5:B504=B16)*('Sales Entry'!I5:I504="Cash")*('Sales Entry'!M5:M504)) | G16: =SUMPRODUCT(('Sales Entry'!B5:B504=B16)*('Sales Entry'!I5:I504="Card")*('Sales Entry'!M5:M504)) | H16: =SUMPRODUCT(('Sales Entry'!B5:B504=B16)*('Sales Entry'!I5:I504="Online")*('Sales Entry'!M5:M504)) | I16: =SUMPRODUCT(('Sales Entry'!B5:B504=B16)*('Sales Entry'!I5:I504="Bank Transfer")*('Sales Entry'!M5:M504)) | J16: =SUMPRODUCT(('Sales Entry'!B5:B504=B16)*('Sales Entry'!F5:F504)) | K16: =SUMPRODUCT(('Sales Entry'!B5:B504=B16)*('Sales Entry'!L5:L504))
C17: =SUMPRODUCT(('Sales Entry'!B5:B504=B17)*('Sales Entry'!M5:M504)) | D17: =SUMPRODUCT(('Sales Entry'!B5:B504=B17)*1) | E17: =IFERROR(C17/D17,0) | F17: =SUMPRODUCT(('Sales Entry'!B5:B504=B17)*('Sales Entry'!I5:I504="Cash")*('Sales Entry'!M5:M504)) | G17: =SUMPRODUCT(('Sales Entry'!B5:B504=B17)*('Sales Entry'!I5:I504="Card")*('Sales Entry'!M5:M504)) | H17: =SUMPRODUCT(('Sales Entry'!B5:B504=B17)*('Sales Entry'!I5:I504="Online")*('Sales Entry'!M5:M504)) | I17: =SUMPRODUCT(('Sales Entry'!B5:B504=B17)*('Sales Entry'!I5:I504="Bank Transfer")*('Sales Entry'!M5:M504)) | J17: =SUMPRODUCT(('Sales Entry'!B5:B504=B17)*('Sales Entry'!F5:F504)) | K17: =SUMPRODUCT(('Sales Entry'!B5:B504=B17)*('Sales Entry'!L5:L504))
C18: =SUMPRODUCT(('Sales Entry'!B5:B504=B18)*('Sales Entry'!M5:M504)) | D18: =SUMPRODUCT(('Sales Entry'!B5:B504=B18)*1) | E18: =IFERROR(C18/D18,0) | F18: =SUMPRODUCT(('Sales Entry'!B5:B504=B18)*('Sales Entry'!I5:I504="Cash")*('Sales Entry'!M5:M504)) | G18: =SUMPRODUCT(('Sales Entry'!B5:B504=B18)*('Sales Entry'!I5:I504="Card")*('Sales Entry'!M5:M504)) | H18: =SUMPRODUCT(('Sales Entry'!B5:B504=B18)*('Sales Entry'!I5:I504="Online")*('Sales Entry'!M5:M504)) | I18: =SUMPRODUCT(('Sales Entry'!B5:B504=B18)*('Sales Entry'!I5:I504="Bank Transfer")*('Sales Entry'!M5:M504)) | J18: =SUMPRODUCT(('Sales Entry'!B5:B504=B18)*('Sales Entry'!F5:F504)) | K18: =SUMPRODUCT(('Sales Entry'!B5:B504=B18)*('Sales Entry'!L5:L504))
C19: =SUMPRODUCT(('Sales Entry'!B5:B504=B19)*('Sales Entry'!M5:M504)) | D19: =SUMPRODUCT(('Sales Entry'!B5:B504=B19)*1) | E19: =IFERROR(C19/D19,0) | F19: =SUMPRODUCT(('Sales Entry'!B5:B504=B19)*('Sales Entry'!I5:I504="Cash")*('Sales Entry'!M5:M504)) | G19: =SUMPRODUCT(('Sales Entry'!B5:B504=B19)*('Sales Entry'!I5:I504="Card")*('Sales Entry'!M5:M504)) | H19: =SUMPRODUCT(('Sales Entry'!B5:B504=B19)*('Sales Entry'!I5:I504="Online")*('Sales Entry'!M5:M504)) | I19: =SUMPRODUCT(('Sales Entry'!B5:B504=B19)*('Sales Entry'!I5:I504="Bank Transfer")*('Sales Entry'!M5:M504)) | J19: =SUMPRODUCT(('Sales Entry'!B5:B504=B19)*('Sales Entry'!F5:F504)) | K19: =SUMPRODUCT(('Sales Entry'!B5:B504=B19)*('Sales Entry'!L5:L504))
C20: =SUMPRODUCT(('Sales Entry'!B5:B504=B20)*('Sales Entry'!M5:M504)) | D20: =SUMPRODUCT(('Sales Entry'!B5:B504=B20)*1) | E20: =IFERROR(C20/D20,0) | F20: =SUMPRODUCT(('Sales Entry'!B5:B504=B20)*('Sales Entry'!I5:I504="Cash")*('Sales Entry'!M5:M504)) | G20: =SUMPRODUCT(('Sales Entry'!B5:B504=B20)*('Sales Entry'!I5:I504="Card")*('Sales Entry'!M5:M504)) | H20: =SUMPRODUCT(('Sales Entry'!B5:B504=B20)*('Sales Entry'!I5:I504="Online")*('Sales Entry'!M5:M504)) | I20: =SUMPRODUCT(('Sales Entry'!B5:B504=B20)*('Sales Entry'!I5:I504="Bank Transfer")*('Sales Entry'!M5:M504)) | J20: =SUMPRODUCT(('Sales Entry'!B5:B504=B20)*('Sales Entry'!F5:F504)) | K20: =SUMPRODUCT(('Sales Entry'!B5:B504=B20)*('Sales Entry'!L5:L504))
C21: =SUMPRODUCT(('Sales Entry'!B5:B504=B21)*('Sales Entry'!M5:M504)) | D21: =SUMPRODUCT(('Sales Entry'!B5:B504=B21)*1) | E21: =IFERROR(C21/D21,0) | F21: =SUMPRODUCT(('Sales Entry'!B5:B504=B21)*('Sales Entry'!I5:I504="Cash")*('Sales Entry'!M5:M504)) | G21: =SUMPRODUCT(('Sales Entry'!B5:B504=B21)*('Sales Entry'!I5:I504="Card")*('Sales Entry'!M5:M504)) | H21: =SUMPRODUCT(('Sales Entry'!B5:B504=B21)*('Sales Entry'!I5:I504="Online")*('Sales Entry'!M5:M504)) | I21: =SUMPRODUCT(('Sales Entry'!B5:B504=B21)*('Sales Entry'!I5:I504="Bank Transfer")*('Sales Entry'!M5:M504)) | J21: =SUMPRODUCT(('Sales Entry'!B5:B504=B21)*('Sales Entry'!F5:F504)) | K21: =SUMPRODUCT(('Sales Entry'!B5:B504=B21)*('Sales Entry'!L5:L504))
C22: =SUMPRODUCT(('Sales Entry'!B5:B504=B22)*('Sales Entry'!M5:M504)) | D22: =SUMPRODUCT(('Sales Entry'!B5:B504=B22)*1) | E22: =IFERROR(C22/D22,0) | F22: =SUMPRODUCT(('Sales Entry'!B5:B504=B22)*('Sales Entry'!I5:I504="Cash")*('Sales Entry'!M5:M504)) | G22: =SUMPRODUCT(('Sales Entry'!B5:B504=B22)*('Sales Entry'!I5:I504="Card")*('Sales Entry'!M5:M504)) | H22: =SUMPRODUCT(('Sales Entry'!B5:B504=B22)*('Sales Entry'!I5:I504="Online")*('Sales Entry'!M5:M504)) | I22: =SUMPRODUCT(('Sales Entry'!B5:B504=B22)*('Sales Entry'!I5:I504="Bank Transfer")*('Sales Entry'!M5:M504)) | J22: =SUMPRODUCT(('Sales Entry'!B5:B504=B22)*('Sales Entry'!F5:F504)) | K22: =SUMPRODUCT(('Sales Entry'!B5:B504=B22)*('Sales Entry'!L5:L504))
C23: =SUMPRODUCT(('Sales Entry'!B5:B504=B23)*('Sales Entry'!M5:M504)) | D23: =SUMPRODUCT(('Sales Entry'!B5:B504=B23)*1) | E23: =IFERROR(C23/D23,0) | F23: =SUMPRODUCT(('Sales Entry'!B5:B504=B23)*('Sales Entry'!I5:I504="Cash")*('Sales Entry'!M5:M504)) | G23: =SUMPRODUCT(('Sales Entry'!B5:B504=B23)*('Sales Entry'!I5:I504="Card")*('Sales Entry'!M5:M504)) | H23: =SUMPRODUCT(('Sales Entry'!B5:B504=B23)*('Sales Entry'!I5:I504="Online")*('Sales Entry'!M5:M504)) | I23: =SUMPRODUCT(('Sales Entry'!B5:B504=B23)*('Sales Entry'!I5:I504="Bank Transfer")*('Sales Entry'!M5:M504)) | J23: =SUMPRODUCT(('Sales Entry'!B5:B504=B23)*('Sales Entry'!F5:F504)) | K23: =SUMPRODUCT(('Sales Entry'!B5:B504=B23)*('Sales Entry'!L5:L504))
C24: =SUMPRODUCT(('Sales Entry'!B5:B504=B24)*('Sales Entry'!M5:M504)) | D24: =SUMPRODUCT(('Sales Entry'!B5:B504=B24)*1) | E24: =IFERROR(C24/D24,0) | F24: =SUMPRODUCT(('Sales Entry'!B5:B504=B24)*('Sales Entry'!I5:I504="Cash")*('Sales Entry'!M5:M504)) | G24: =SUMPRODUCT(('Sales Entry'!B5:B504=B24)*('Sales Entry'!I5:I504="Card")*('Sales Entry'!M5:M504)) | H24: =SUMPRODUCT(('Sales Entry'!B5:B504=B24)*('Sales Entry'!I5:I504="Online")*('Sales Entry'!M5:M504)) | I24: =SUMPRODUCT(('Sales Entry'!B5:B504=B24)*('Sales Entry'!I5:I504="Bank Transfer")*('Sales Entry'!M5:M504)) | J24: =SUMPRODUCT(('Sales Entry'!B5:B504=B24)*('Sales Entry'!F5:F504)) | K24: =SUMPRODUCT(('Sales Entry'!B5:B504=B24)*('Sales Entry'!L5:L504))
C25: =SUMPRODUCT(('Sales Entry'!B5:B504=B25)*('Sales Entry'!M5:M504)) | D25: =SUMPRODUCT(('Sales Entry'!B5:B504=B25)*1) | E25: =IFERROR(C25/D25,0) | F25: =SUMPRODUCT(('Sales Entry'!B5:B504=B25)*('Sales Entry'!I5:I504="Cash")*('Sales Entry'!M5:M504)) | G25: =SUMPRODUCT(('Sales Entry'!B5:B504=B25)*('Sales Entry'!I5:I504="Card")*('Sales Entry'!M5:M504)) | H25: =SUMPRODUCT(('Sales Entry'!B5:B504=B25)*('Sales Entry'!I5:I504="Online")*('Sales Entry'!M5:M504)) | I25: =SUMPRODUCT(('Sales Entry'!B5:B504=B25)*('Sales Entry'!I5:I504="Bank Transfer")*('Sales Entry'!M5:M504)) | J25: =SUMPRODUCT(('Sales Entry'!B5:B504=B25)*('Sales Entry'!F5:F504)) | K25: =SUMPRODUCT(('Sales Entry'!B5:B504=B25)*('Sales Entry'!L5:L504))
C26: =SUMPRODUCT(('Sales Entry'!B5:B504=B26)*('Sales Entry'!M5:M504)) | D26: =SUMPRODUCT(('Sales Entry'!B5:B504=B26)*1) | E26: =IFERROR(C26/D26,0) | F26: =SUMPRODUCT(('Sales Entry'!B5:B504=B26)*('Sales Entry'!I5:I504="Cash")*('Sales Entry'!M5:M504)) | G26: =SUMPRODUCT(('Sales Entry'!B5:B504=B26)*('Sales Entry'!I5:I504="Card")*('Sales Entry'!M5:M504)) | H26: =SUMPRODUCT(('Sales Entry'!B5:B504=B26)*('Sales Entry'!I5:I504="Online")*('Sales Entry'!M5:M504)) | I26: =SUMPRODUCT(('Sales Entry'!B5:B504=B26)*('Sales Entry'!I5:I504="Bank Transfer")*('Sales Entry'!M5:M504)) | J26: =SUMPRODUCT(('Sales Entry'!B5:B504=B26)*('Sales Entry'!F5:F504)) | K26: =SUMPRODUCT(('Sales Entry'!B5:B504=B26)*('Sales Entry'!L5:L504))
C27: =SUMPRODUCT(('Sales Entry'!B5:B504=B27)*('Sales Entry'!M5:M504)) | D27: =SUMPRODUCT(('Sales Entry'!B5:B504=B27)*1) | E27: =IFERROR(C27/D27,0) | F27: =SUMPRODUCT(('Sales Entry'!B5:B504=B27)*('Sales Entry'!I5:I504="Cash")*('Sales Entry'!M5:M504)) | G27: =SUMPRODUCT(('Sales Entry'!B5:B504=B27)*('Sales Entry'!I5:I504="Card")*('Sales Entry'!M5:M504)) | H27: =SUMPRODUCT(('Sales Entry'!B5:B504=B27)*('Sales Entry'!I5:I504="Online")*('Sales Entry'!M5:M504)) | I27: =SUMPRODUCT(('Sales Entry'!B5:B504=B27)*('Sales Entry'!I5:I504="Bank Transfer")*('Sales Entry'!M5:M504)) | J27: =SUMPRODUCT(('Sales Entry'!B5:B504=B27)*('Sales Entry'!F5:F504)) | K27: =SUMPRODUCT(('Sales Entry'!B5:B504=B27)*('Sales Entry'!L5:L504))
C28: =SUMPRODUCT(('Sales Entry'!B5:B504=B28)*('Sales Entry'!M5:M504)) | D28: =SUMPRODUCT(('Sales Entry'!B5:B504=B28)*1) | E28: =IFERROR(C28/D28,0) | F28: =SUMPRODUCT(('Sales Entry'!B5:B504=B28)*('Sales Entry'!I5:I504="Cash")*('Sales Entry'!M5:M504)) | G28: =SUMPRODUCT(('Sales Entry'!B5:B504=B28)*('Sales Entry'!I5:I504="Card")*('Sales Entry'!M5:M504)) | H28: =SUMPRODUCT(('Sales Entry'!B5:B504=B28)*('Sales Entry'!I5:I504="Online")*('Sales Entry'!M5:M504)) | I28: =SUMPRODUCT(('Sales Entry'!B5:B504=B28)*('Sales Entry'!I5:I504="Bank Transfer")*('Sales Entry'!M5:M504)) | J28: =SUMPRODUCT(('Sales Entry'!B5:B504=B28)*('Sales Entry'!F5:F504)) | K28: =SUMPRODUCT(('Sales Entry'!B5:B504=B28)*('Sales Entry'!L5:L504))
C29: =SUMPRODUCT(('Sales Entry'!B5:B504=B29)*('Sales Entry'!M5:M504)) | D29: =SUMPRODUCT(('Sales Entry'!B5:B504=B29)*1) | E29: =IFERROR(C29/D29,0) | F29: =SUMPRODUCT(('Sales Entry'!B5:B504=B29)*('Sales Entry'!I5:I504="Cash")*('Sales Entry'!M5:M504)) | G29: =SUMPRODUCT(('Sales Entry'!B5:B504=B29)*('Sales Entry'!I5:I504="Card")*('Sales Entry'!M5:M504)) | H29: =SUMPRODUCT(('Sales Entry'!B5:B504=B29)*('Sales Entry'!I5:I504="Online")*('Sales Entry'!M5:M504)) | I29: =SUMPRODUCT(('Sales Entry'!B5:B504=B29)*('Sales Entry'!I5:I504="Bank Transfer")*('Sales Entry'!M5:M504)) | J29: =SUMPRODUCT(('Sales Entry'!B5:B504=B29)*('Sales Entry'!F5:F504)) | K29: =SUMPRODUCT(('Sales Entry'!B5:B504=B29)*('Sales Entry'!L5:L504))
C30: =SUMPRODUCT(('Sales Entry'!B5:B504=B30)*('Sales Entry'!M5:M504)) | D30: =SUMPRODUCT(('Sales Entry'!B5:B504=B30)*1) | E30: =IFERROR(C30/D30,0) | F30: =SUMPRODUCT(('Sales Entry'!B5:B504=B30)*('Sales Entry'!I5:I504="Cash")*('Sales Entry'!M5:M504)) | G30: =SUMPRODUCT(('Sales Entry'!B5:B504=B30)*('Sales Entry'!I5:I504="Card")*('Sales Entry'!M5:M504)) | H30: =SUMPRODUCT(('Sales Entry'!B5:B504=B30)*('Sales Entry'!I5:I504="Online")*('Sales Entry'!M5:M504)) | I30: =SUMPRODUCT(('Sales Entry'!B5:B504=B30)*('Sales Entry'!I5:I504="Bank Transfer")*('Sales Entry'!M5:M504)) | J30: =SUMPRODUCT(('Sales Entry'!B5:B504=B30)*('Sales Entry'!F5:F504)) | K30: =SUMPRODUCT(('Sales Entry'!B5:B504=B30)*('Sales Entry'!L5:L504))
C31: =SUMPRODUCT(('Sales Entry'!B5:B504=B31)*('Sales Entry'!M5:M504)) | D31: =SUMPRODUCT(('Sales Entry'!B5:B504=B31)*1) | E31: =IFERROR(C31/D31,0) | F31: =SUMPRODUCT(('Sales Entry'!B5:B504=B31)*('Sales Entry'!I5:I504="Cash")*('Sales Entry'!M5:M504)) | G31: =SUMPRODUCT(('Sales Entry'!B5:B504=B31)*('Sales Entry'!I5:I504="Card")*('Sales Entry'!M5:M504)) | H31: =SUMPRODUCT(('Sales Entry'!B5:B504=B31)*('Sales Entry'!I5:I504="Online")*('Sales Entry'!M5:M504)) | I31: =SUMPRODUCT(('Sales Entry'!B5:B504=B31)*('Sales Entry'!I5:I504="Bank Transfer")*('Sales Entry'!M5:M504)) | J31: =SUMPRODUCT(('Sales Entry'!B5:B504=B31)*('Sales Entry'!F5:F504)) | K31: =SUMPRODUCT(('Sales Entry'!B5:B504=B31)*('Sales Entry'!L5:L504))
C32: =SUMPRODUCT(('Sales Entry'!B5:B504=B32)*('Sales Entry'!M5:M504)) | D32: =SUMPRODUCT(('Sales Entry'!B5:B504=B32)*1) | E32: =IFERROR(C32/D32,0) | F32: =SUMPRODUCT(('Sales Entry'!B5:B504=B32)*('Sales Entry'!I5:I504="Cash")*('Sales Entry'!M5:M504)) | G32: =SUMPRODUCT(('Sales Entry'!B5:B504=B32)*('Sales Entry'!I5:I504="Card")*('Sales Entry'!M5:M504)) | H32: =SUMPRODUCT(('Sales Entry'!B5:B504=B32)*('Sales Entry'!I5:I504="Online")*('Sales Entry'!M5:M504)) | I32: =SUMPRODUCT(('Sales Entry'!B5:B504=B32)*('Sales Entry'!I5:I504="Bank Transfer")*('Sales Entry'!M5:M504)) | J32: =SUMPRODUCT(('Sales Entry'!B5:B504=B32)*('Sales Entry'!F5:F504)) | K32: =SUMPRODUCT(('Sales Entry'!B5:B504=B32)*('Sales Entry'!L5:L504))
C33: =SUMPRODUCT(('Sales Entry'!B5:B504=B33)*('Sales Entry'!M5:M504)) | D33: =SUMPRODUCT(('Sales Entry'!B5:B504=B33)*1) | E33: =IFERROR(C33/D33,0) | F33: =SUMPRODUCT(('Sales Entry'!B5:B504=B33)*('Sales Entry'!I5:I504="Cash")*('Sales Entry'!M5:M504)) | G33: =SUMPRODUCT(('Sales Entry'!B5:B504=B33)*('Sales Entry'!I5:I504="Card")*('Sales Entry'!M5:M504)) | H33: =SUMPRODUCT(('Sales Entry'!B5:B504=B33)*('Sales Entry'!I5:I504="Online")*('Sales Entry'!M5:M504)) | I33: =SUMPRODUCT(('Sales Entry'!B5:B504=B33)*('Sales Entry'!I5:I504="Bank Transfer")*('Sales Entry'!M5:M504)) | J33: =SUMPRODUCT(('Sales Entry'!B5:B504=B33)*('Sales Entry'!F5:F504)) | K33: =SUMPRODUCT(('Sales Entry'!B5:B504=B33)*('Sales Entry'!L5:L504))
C34: =SUMPRODUCT(('Sales Entry'!B5:B504=B34)*('Sales Entry'!M5:M504)) | D34: =SUMPRODUCT(('Sales Entry'!B5:B504=B34)*1) | E34: =IFERROR(C34/D34,0) | F34: =SUMPRODUCT(('Sales Entry'!B5:B504=B34)*('Sales Entry'!I5:I504="Cash")*('Sales Entry'!M5:M504)) | G34: =SUMPRODUCT(('Sales Entry'!B5:B504=B34)*('Sales Entry'!I5:I504="Card")*('Sales Entry'!M5:M504)) | H34: =SUMPRODUCT(('Sales Entry'!B5:B504=B34)*('Sales Entry'!I5:I504="Online")*('Sales Entry'!M5:M504)) | I34: =SUMPRODUCT(('Sales Entry'!B5:B504=B34)*('Sales Entry'!I5:I504="Bank Transfer")*('Sales Entry'!M5:M504)) | J34: =SUMPRODUCT(('Sales Entry'!B5:B504=B34)*('Sales Entry'!F5:F504)) | K34: =SUMPRODUCT(('Sales Entry'!B5:B504=B34)*('Sales Entry'!L5:L504))
C35: =SUMPRODUCT(('Sales Entry'!B5:B504=B35)*('Sales Entry'!M5:M504)) | D35: =SUMPRODUCT(('Sales Entry'!B5:B504=B35)*1) | E35: =IFERROR(C35/D35,0) | F35: =SUMPRODUCT(('Sales Entry'!B5:B504=B35)*('Sales Entry'!I5:I504="Cash")*('Sales Entry'!M5:M504)) | G35: =SUMPRODUCT(('Sales Entry'!B5:B504=B35)*('Sales Entry'!I5:I504="Card")*('Sales Entry'!M5:M504)) | H35: =SUMPRODUCT(('Sales Entry'!B5:B504=B35)*('Sales Entry'!I5:I504="Online")*('Sales Entry'!M5:M504)) | I35: =SUMPRODUCT(('Sales Entry'!B5:B504=B35)*('Sales Entry'!I5:I504="Bank Transfer")*('Sales Entry'!M5:M504)) | J35: =SUMPRODUCT(('Sales Entry'!B5:B504=B35)*('Sales Entry'!F5:F504)) | K35: =SUMPRODUCT(('Sales Entry'!B5:B504=B35)*('Sales Entry'!L5:L504))
B36: TOTAL | C36: =SUM(C5:C35) | D36: =SUM(D5:D35) | E36: =IFERROR(C36/D36,0) | F36: =SUM(F5:F35) | G36: =SUM(G5:G35) | H36: =SUM(H5:H35) | I36: =SUM(I5:I35) | J36: =SUM(J5:J35) | K36: =SUM(K5:K35)

Sheet Weekly Summary
B2: Weekly Summary — 52 Weeks
B4: Week # | C4: Week Start | D4: Week End | E4: Total Sales | F4: # Transactions | G4: Avg Transaction | H4: Top Staff | I4: Profit Estimate
B5: 1 | E5: =SUMPRODUCT(('Daily Summary'!B5:B35>=C5)*('Daily Summary'!B5:B35<=D5)*('Daily Summary'!C5:C35)) | F5: =SUMPRODUCT(('Daily Summary'!B5:B35>=C5)*('Daily Summary'!B5:B35<=D5)*('Daily Summary'!D5:D35)) | G5: =IFERROR(E5/F5,0) | I5: =E5*0.3
B6: 2 | E6: =SUMPRODUCT(('Daily Summary'!B5:B35>=C6)*('Daily Summary'!B5:B35<=D6)*('Daily Summary'!C5:C35)) | F6: =SUMPRODUCT(('Daily Summary'!B5:B35>=C6)*('Daily Summary'!B5:B35<=D6)*('Daily Summary'!D5:D35)) | G6: =IFERROR(E6/F6,0) | I6: =E6*0.3
B7: 3 | E7: =SUMPRODUCT(('Daily Summary'!B5:B35>=C7)*('Daily Summary'!B5:B35<=D7)*('Daily Summary'!C5:C35)) | F7: =SUMPRODUCT(('Daily Summary'!B5:B35>=C7)*('Daily Summary'!B5:B35<=D7)*('Daily Summary'!D5:D35)) | G7: =IFERROR(E7/F7,0) | I7: =E7*0.3
B8: 4 | E8: =SUMPRODUCT(('Daily Summary'!B5:B35>=C8)*('Daily Summary'!B5:B35<=D8)*('Daily Summary'!C5:C35)) | F8: =SUMPRODUCT(('Daily Summary'!B5:B35>=C8)*('Daily Summary'!B5:B35<=D8)*('Daily Summary'!D5:D35)) | G8: =IFERROR(E8/F8,0) | I8: =E8*0.3
B9: 5 | E9: =SUMPRODUCT(('Daily Summary'!B5:B35>=C9)*('Daily Summary'!B5:B35<=D9)*('Daily Summary'!C5:C35)) | F9: =SUMPRODUCT(('Daily Summary'!B5:B35>=C9)*('Daily Summary'!B5:B35<=D9)*('Daily Summary'!D5:D35)) | G9: =IFERROR(E9/F9,0) | I9: =E9*0.3
B10: 6 | E10: =SUMPRODUCT(('Daily Summary'!B5:B35>=C10)*('Daily Summary'!B5:B35<=D10)*('Daily Summary'!C5:C35)) | F10: =SUMPRODUCT(('Daily Summary'!B5:B35>=C10)*('Daily Summary'!B5:B35<=D10)*('Daily Summary'!D5:D35)) | G10: =IFERROR(E10/F10,0) | I10: =E10*0.3
B11: 7 | E11: =SUMPRODUCT(('Daily Summary'!B5:B35>=C11)*('Daily Summary'!B5:B35<=D11)*('Daily Summary'!C5:C35)) | F11: =SUMPRODUCT(('Daily Summary'!B5:B35>=C11)*('Daily Summary'!B5:B35<=D11)*('Daily Summary'!D5:D35)) | G11: =IFERROR(E11/F11,0) | I11: =E11*0.3
B12: 8 | E12: =SUMPRODUCT(('Daily Summary'!B5:B35>=C12)*('Daily Summary'!B5:B35<=D12)*('Daily Summary'!C5:C35)) | F12: =SUMPRODUCT(('Daily Summary'!B5:B35>=C12)*('Daily Summary'!B5:B35<=D12)*('Daily Summary'!D5:D35)) | G12: =IFERROR(E12/F12,0) | I12: =E12*0.3
B13: 9 | E13: =SUMPRODUCT(('Daily Summary'!B5:B35>=C13)*('Daily Summary'!B5:B35<=D13)*('Daily Summary'!C5:C35)) | F13: =SUMPRODUCT(('Daily Summary'!B5:B35>=C13)*('Daily Summary'!B5:B35<=D13)*('Daily Summary'!D5:D35)) | G13: =IFERROR(E13/F13,0) | I13: =E13*0.3
B14: 10 | E14: =SUMPRODUCT(('Daily Summary'!B5:B35>=C14)*('Daily Summary'!B5:B35<=D14)*('Daily Summary'!C5:C35)) | F14: =SUMPRODUCT(('Daily Summary'!B5:B35>=C14)*('Daily Summary'!B5:B35<=D14)*('Daily Summary'!D5:D35)) | G14: =IFERROR(E14/F14,0) | I14: =E14*0.3
B15: 11 | E15: =SUMPRODUCT(('Daily Summary'!B5:B35>=C15)*('Daily Summary'!B5:B35<=D15)*('Daily Summary'!C5:C35)) | F15: =SUMPRODUCT(('Daily Summary'!B5:B35>=C15)*('Daily Summary'!B5:B35<=D15)*('Daily Summary'!D5:D35)) | G15: =IFERROR(E15/F15,0) | I15: =E15*0.3
B16: 12 | E16: =SUMPRODUCT(('Daily Summary'!B5:B35>=C16)*('Daily Summary'!B5:B35<=D16)*('Daily Summary'!C5:C35)) | F16: =SUMPRODUCT(('Daily Summary'!B5:B35>=C16)*('Daily Summary'!B5:B35<=D16)*('Daily Summary'!D5:D35)) | G16: =IFERROR(E16/F16,0) | I16: =E16*0.3
B17: 13 | E17: =SUMPRODUCT(('Daily Summary'!B5:B35>=C17)*('Daily Summary'!B5:B35<=D17)*('Daily Summary'!C5:C35)) | F17: =SUMPRODUCT(('Daily Summary'!B5:B35>=C17)*('Daily Summary'!B5:B35<=D17)*('Daily Summary'!D5:D35)) | G17: =IFERROR(E17/F17,0) | I17: =E17*0.3
B18: 14 | E18: =SUMPRODUCT(('Daily Summary'!B5:B35>=C18)*('Daily Summary'!B5:B35<=D18)*('Daily Summary'!C5:C35)) | F18: =SUMPRODUCT(('Daily Summary'!B5:B35>=C18)*('Daily Summary'!B5:B35<=D18)*('Daily Summary'!D5:D35)) | G18: =IFERROR(E18/F18,0) | I18: =E18*0.3
B19: 15 | E19: =SUMPRODUCT(('Daily Summary'!B5:B35>=C19)*('Daily Summary'!B5:B35<=D19)*('Daily Summary'!C5:C35)) | F19: =SUMPRODUCT(('Daily Summary'!B5:B35>=C19)*('Daily Summary'!B5:B35<=D19)*('Daily Summary'!D5:D35)) | G19: =IFERROR(E19/F19,0) | I19: =E19*0.3
B20: 16 | E20: =SUMPRODUCT(('Daily Summary'!B5:B35>=C20)*('Daily Summary'!B5:B35<=D20)*('Daily Summary'!C5:C35)) | F20: =SUMPRODUCT(('Daily Summary'!B5:B35>=C20)*('Daily Summary'!B5:B35<=D20)*('Daily Summary'!D5:D35)) | G20: =IFERROR(E20/F20,0) | I20: =E20*0.3
B21: 17 | E21: =SUMPRODUCT(('Daily Summary'!B5:B35>=C21)*('Daily Summary'!B5:B35<=D21)*('Daily Summary'!C5:C35)) | F21: =SUMPRODUCT(('Daily Summary'!B5:B35>=C21)*('Daily Summary'!B5:B35<=D21)*('Daily Summary'!D5:D35)) | G21: =IFERROR(E21/F21,0) | I21: =E21*0.3
B22: 18 | E22: =SUMPRODUCT(('Daily Summary'!B5:B35>=C22)*('Daily Summary'!B5:B35<=D22)*('Daily Summary'!C5:C35)) | F22: =SUMPRODUCT(('Daily Summary'!B5:B35>=C22)*('Daily Summary'!B5:B35<=D22)*('Daily Summary'!D5:D35)) | G22: =IFERROR(E22/F22,0) | I22: =E22*0.3
B23: 19 | E23: =SUMPRODUCT(('Daily Summary'!B5:B35>=C23)*('Daily Summary'!B5:B35<=D23)*('Daily Summary'!C5:C35)) | F23: =SUMPRODUCT(('Daily Summary'!B5:B35>=C23)*('Daily Summary'!B5:B35<=D23)*('Daily Summary'!D5:D35)) | G23: =IFERROR(E23/F23,0) | I23: =E23*0.3
B24: 20 | E24: =SUMPRODUCT(('Daily Summary'!B5:B35>=C24)*('Daily Summary'!B5:B35<=D24)*('Daily Summary'!C5:C35)) | F24: =SUMPRODUCT(('Daily Summary'!B5:B35>=C24)*('Daily Summary'!B5:B35<=D24)*('Daily Summary'!D5:D35)) | G24: =IFERROR(E24/F24,0) | I24: =E24*0.3
B25: 21 | E25: =SUMPRODUCT(('Daily Summary'!B5:B35>=C25)*('Daily Summary'!B5:B35<=D25)*('Daily Summary'!C5:C35)) | F25: =SUMPRODUCT(('Daily Summary'!B5:B35>=C25)*('Daily Summary'!B5:B35<=D25)*('Daily Summary'!D5:D35)) | G25: =IFERROR(E25/F25,0) | I25: =E25*0.3
B26: 22 | E26: =SUMPRODUCT(('Daily Summary'!B5:B35>=C26)*('Daily Summary'!B5:B35<=D26)*('Daily Summary'!C5:C35)) | F26: =SUMPRODUCT(('Daily Summary'!B5:B35>=C26)*('Daily Summary'!B5:B35<=D26)*('Daily Summary'!D5:D35)) | G26: =IFERROR(E26/F26,0) | I26: =E26*0.3
B27: 23 | E27: =SUMPRODUCT(('Daily Summary'!B5:B35>=C27)*('Daily Summary'!B5:B35<=D27)*('Daily Summary'!C5:C35)) | F27: =SUMPRODUCT(('Daily Summary'!B5:B35>=C27)*('Daily Summary'!B5:B35<=D27)*('Daily Summary'!D5:D35)) | G27: =IFERROR(E27/F27,0) | I27: =E27*0.3
B28: 24 | E28: =SUMPRODUCT(('Daily Summary'!B5:B35>=C28)*('Daily Summary'!B5:B35<=D28)*('Daily Summary'!C5:C35)) | F28: =SUMPRODUCT(('Daily Summary'!B5:B35>=C28)*('Daily Summary'!B5:B35<=D28)*('Daily Summary'!D5:D35)) | G28: =IFERROR(E28/F28,0) | I28: =E28*0.3
B29: 25 | E29: =SUMPRODUCT(('Daily Summary'!B5:B35>=C29)*('Daily Summary'!B5:B35<=D29)*('Daily Summary'!C5:C35)) | F29: =SUMPRODUCT(('Daily Summary'!B5:B35>=C29)*('Daily Summary'!B5:B35<=D29)*('Daily Summary'!D5:D35)) | G29: =IFERROR(E29/F29,0) | I29: =E29*0.3
B30: 26 | E30: =SUMPRODUCT(('Daily Summary'!B5:B35>=C30)*('Daily Summary'!B5:B35<=D30)*('Daily Summary'!C5:C35)) | F30: =SUMPRODUCT(('Daily Summary'!B5:B35>=C30)*('Daily Summary'!B5:B35<=D30)*('Daily Summary'!D5:D35)) | G30: =IFERROR(E30/F30,0) | I30: =E30*0.3
B31: 27 | E31: =SUMPRODUCT(('Daily Summary'!B5:B35>=C31)*('Daily Summary'!B5:B35<=D31)*('Daily Summary'!C5:C35)) | F31: =SUMPRODUCT(('Daily Summary'!B5:B35>=C31)*('Daily Summary'!B5:B35<=D31)*('Daily Summary'!D5:D35)) | G31: =IFERROR(E31/F31,0) | I31: =E31*0.3
B32: 28 | E32: =SUMPRODUCT(('Daily Summary'!B5:B35>=C32)*('Daily Summary'!B5:B35<=D32)*('Daily Summary'!C5:C35)) | F32: =SUMPRODUCT(('Daily Summary'!B5:B35>=C32)*('Daily Summary'!B5:B35<=D32)*('Daily Summary'!D5:D35)) | G32: =IFERROR(E32/F32,0) | I32: =E32*0.3
B33: 29 | E33: =SUMPRODUCT(('Daily Summary'!B5:B35>=C33)*('Daily Summary'!B5:B35<=D33)*('Daily Summary'!C5:C35)) | F33: =SUMPRODUCT(('Daily Summary'!B5:B35>=C33)*('Daily Summary'!B5:B35<=D33)*('Daily Summary'!D5:D35)) | G33: =IFERROR(E33/F33,0) | I33: =E33*0.3
B34: 30 | E34: =SUMPRODUCT(('Daily Summary'!B5:B35>=C34)*('Daily Summary'!B5:B35<=D34)*('Daily Summary'!C5:C35)) | F34: =SUMPRODUCT(('Daily Summary'!B5:B35>=C34)*('Daily Summary'!B5:B35<=D34)*('Daily Summary'!D5:D35)) | G34: =IFERROR(E34/F34,0) | I34: =E34*0.3
B35: 31 | E35: =SUMPRODUCT(('Daily Summary'!B5:B35>=C35)*('Daily Summary'!B5:B35<=D35)*('Daily Summary'!C5:C35)) | F35: =SUMPRODUCT(('Daily Summary'!B5:B35>=C35)*('Daily Summary'!B5:B35<=D35)*('Daily Summary'!D5:D35)) | G35: =IFERROR(E35/F35,0) | I35: =E35*0.3
B36: 32 | E36: =SUMPRODUCT(('Daily Summary'!B5:B35>=C36)*('Daily Summary'!B5:B35<=D36)*('Daily Summary'!C5:C35)) | F36: =SUMPRODUCT(('Daily Summary'!B5:B35>=C36)*('Daily Summary'!B5:B35<=D36)*('Daily Summary'!D5:D35)) | G36: =IFERROR(E36/F36,0) | I36: =E36*0.3
B37: 33 | E37: =SUMPRODUCT(('Daily Summary'!B5:B35>=C37)*('Daily Summary'!B5:B35<=D37)*('Daily Summary'!C5:C35)) | F37: =SUMPRODUCT(('Daily Summary'!B5:B35>=C37)*('Daily Summary'!B5:B35<=D37)*('Daily Summary'!D5:D35)) | G37: =IFERROR(E37/F37,0) | I37: =E37*0.3
B38: 34 | E38: =SUMPRODUCT(('Daily Summary'!B5:B35>=C38)*('Daily Summary'!B5:B35<=D38)*('Daily Summary'!C5:C35)) | F38: =SUMPRODUCT(('Daily Summary'!B5:B35>=C38)*('Daily Summary'!B5:B35<=D38)*('Daily Summary'!D5:D35)) | G38: =IFERROR(E38/F38,0) | I38: =E38*0.3
B39: 35 | E39: =SUMPRODUCT(('Daily Summary'!B5:B35>=C39)*('Daily Summary'!B5:B35<=D39)*('Daily Summary'!C5:C35)) | F39: =SUMPRODUCT(('Daily Summary'!B5:B35>=C39)*('Daily Summary'!B5:B35<=D39)*('Daily Summary'!D5:D35)) | G39: =IFERROR(E39/F39,0) | I39: =E39*0.3
B40: 36 | E40: =SUMPRODUCT(('Daily Summary'!B5:B35>=C40)*('Daily Summary'!B5:B35<=D40)*('Daily Summary'!C5:C35)) | F40: =SUMPRODUCT(('Daily Summary'!B5:B35>=C40)*('Daily Summary'!B5:B35<=D40)*('Daily Summary'!D5:D35)) | G40: =IFERROR(E40/F40,0) | I40: =E40*0.3
B41: 37 | E41: =SUMPRODUCT(('Daily Summary'!B5:B35>=C41)*('Daily Summary'!B5:B35<=D41)*('Daily Summary'!C5:C35)) | F41: =SUMPRODUCT(('Daily Summary'!B5:B35>=C41)*('Daily Summary'!B5:B35<=D41)*('Daily Summary'!D5:D35)) | G41: =IFERROR(E41/F41,0) | I41: =E41*0.3
B42: 38 | E42: =SUMPRODUCT(('Daily Summary'!B5:B35>=C42)*('Daily Summary'!B5:B35<=D42)*('Daily Summary'!C5:C35)) | F42: =SUMPRODUCT(('Daily Summary'!B5:B35>=C42)*('Daily Summary'!B5:B35<=D42)*('Daily Summary'!D5:D35)) | G42: =IFERROR(E42/F42,0) | I42: =E42*0.3
...

Sheet Monthly Summary
B2: Monthly Summary — 12 Months
B4: Month | C4: Total Sales | D4: # Transactions | E4: Avg Transaction | F4: Best Day Sales | G4: Best Day Date | H4: Total Expenses | I4: Net Profit
B5: January | C5: =SUMPRODUCT((MONTH('Daily Summary'!B5:B35)=1)*('Daily Summary'!C5:C35)) | D5: =SUMPRODUCT((MONTH('Daily Summary'!B5:B35)=1)*('Daily Summary'!D5:D35)) | E5: =IFERROR(C5/D5,0) | F5: =IFERROR(MAX(IF(MONTH('Daily Summary'!B5:B35)=1,'Daily Summary'!C5:C35)),0) | G5: =IFERROR(INDEX('Daily Summary'!B5:B35,MATCH(F5,IF(MONTH('Daily Summary'!B5:B35)=1,'Daily Summary'!C5:C35),0)),"") | H5: =SUMPRODUCT((MONTH('Expenses'!B5:B304)=1)*('Expenses'!E5:E304)) | I5: =C5-H5
B6: February | C6: =SUMPRODUCT((MONTH('Daily Summary'!B5:B35)=2)*('Daily Summary'!C5:C35)) | D6: =SUMPRODUCT((MONTH('Daily Summary'!B5:B35)=2)*('Daily Summary'!D5:D35)) | E6: =IFERROR(C6/D6,0) | F6: =IFERROR(MAX(IF(MONTH('Daily Summary'!B5:B35)=2,'Daily Summary'!C5:C35)),0) | G6: =IFERROR(INDEX('Daily Summary'!B5:B35,MATCH(F6,IF(MONTH('Daily Summary'!B5:B35)=2,'Daily Summary'!C5:C35),0)),"") | H6: =SUMPRODUCT((MONTH('Expenses'!B5:B304)=2)*('Expenses'!E5:E304)) | I6: =C6-H6
B7: March | C7: =SUMPRODUCT((MONTH('Daily Summary'!B5:B35)=3)*('Daily Summary'!C5:C35)) | D7: =SUMPRODUCT((MONTH('Daily Summary'!B5:B35)=3)*('Daily Summary'!D5:D35)) | E7: =IFERROR(C7/D7,0) | F7: =IFERROR(MAX(IF(MONTH('Daily Summary'!B5:B35)=3,'Daily Summary'!C5:C35)),0) | G7: =IFERROR(INDEX('Daily Summary'!B5:B35,MATCH(F7,IF(MONTH('Daily Summary'!B5:B35)=3,'Daily Summary'!C5:C35),0)),"") | H7: =SUMPRODUCT((MONTH('Expenses'!B5:B304)=3)*('Expenses'!E5:E304)) | I7: =C7-H7
B8: April | C8: =SUMPRODUCT((MONTH('Daily Summary'!B5:B35)=4)*('Daily Summary'!C5:C35)) | D8: =SUMPRODUCT((MONTH('Daily Summary'!B5:B35)=4)*('Daily Summary'!D5:D35)) | E8: =IFERROR(C8/D8,0) | F8: =IFERROR(MAX(IF(MONTH('Daily Summary'!B5:B35)=4,'Daily Summary'!C5:C35)),0) | G8: =IFERROR(INDEX('Daily Summary'!B5:B35,MATCH(F8,IF(MONTH('Daily Summary'!B5:B35)=4,'Daily Summary'!C5:C35),0)),"") | H8: =SUMPRODUCT((MONTH('Expenses'!B5:B304)=4)*('Expenses'!E5:E304)) | I8: =C8-H8
B9: May | C9: =SUMPRODUCT((MONTH('Daily Summary'!B5:B35)=5)*('Daily Summary'!C5:C35)) | D9: =SUMPRODUCT((MONTH('Daily Summary'!B5:B35)=5)*('Daily Summary'!D5:D35)) | E9: =IFERROR(C9/D9,0) | F9: =IFERROR(MAX(IF(MONTH('Daily Summary'!B5:B35)=5,'Daily Summary'!C5:C35)),0) | G9: =IFERROR(INDEX('Daily Summary'!B5:B35,MATCH(F9,IF(MONTH('Daily Summary'!B5:B35)=5,'Daily Summary'!C5:C35),0)),"") | H9: =SUMPRODUCT((MONTH('Expenses'!B5:B304)=5)*('Expenses'!E5:E304)) | I9: =C9-H9
B10: June | C10: =SUMPRODUCT((MONTH('Daily Summary'!B5:B35)=6)*('Daily Summary'!C5:C35)) | D10: =SUMPRODUCT((MONTH('Daily Summary'!B5:B35)=6)*('Daily Summary'!D5:D35)) | E10: =IFERROR(C10/D10,0) | F10: =IFERROR(MAX(IF(MONTH('Daily Summary'!B5:B35)=6,'Daily Summary'!C5:C35)),0) | G10: =IFERROR(INDEX('Daily Summary'!B5:B35,MATCH(F10,IF(MONTH('Daily Summary'!B5:B35)=6,'Daily Summary'!C5:C35),0)),"") | H10: =SUMPRODUCT((MONTH('Expenses'!B5:B304)=6)*('Expenses'!E5:E304)) | I10: =C10-H10
B11: July | C11: =SUMPRODUCT((MONTH('Daily Summary'!B5:B35)=7)*('Daily Summary'!C5:C35)) | D11: =SUMPRODUCT((MONTH('Daily Summary'!B5:B35)=7)*('Daily Summary'!D5:D35)) | E11: =IFERROR(C11/D11,0) | F11: =IFERROR(MAX(IF(MONTH('Daily Summary'!B5:B35)=7,'Daily Summary'!C5:C35)),0) | G11: =IFERROR(INDEX('Daily Summary'!B5:B35,MATCH(F11,IF(MONTH('Daily Summary'!B5:B35)=7,'Daily Summary'!C5:C35),0)),"") | H11: =SUMPRODUCT((MONTH('Expenses'!B5:B304)=7)*('Expenses'!E5:E304)) | I11: =C11-H11
B12: August | C12: =SUMPRODUCT((MONTH('Daily Summary'!B5:B35)=8)*('Daily Summary'!C5:C35)) | D12: =SUMPRODUCT((MONTH('Daily Summary'!B5:B35)=8)*('Daily Summary'!D5:D35)) | E12: =IFERROR(C12/D12,0) | F12: =IFERROR(MAX(IF(MONTH('Daily Summary'!B5:B35)=8,'Daily Summary'!C5:C35)),0) | G12: =IFERROR(INDEX('Daily Summary'!B5:B35,MATCH(F12,IF(MONTH('Daily Summary'!B5:B35)=8,'Daily Summary'!C5:C35),0)),"") | H12: =SUMPRODUCT((MONTH('Expenses'!B5:B304)=8)*('Expenses'!E5:E304)) | I12: =C12-H12
B13: September | C13: =SUMPRODUCT((MONTH('Daily Summary'!B5:B35)=9)*('Daily Summary'!C5:C35)) | D13: =SUMPRODUCT((MONTH('Daily Summary'!B5:B35)=9)*('Daily Summary'!D5:D35)) | E13: =IFERROR(C13/D13,0) | F13: =IFERROR(MAX(IF(MONTH('Daily Summary'!B5:B35)=9,'Daily Summary'!C5:C35)),0) | G13: =IFERROR(INDEX('Daily Summary'!B5:B35,MATCH(F13,IF(MONTH('Daily Summary'!B5:B35)=9,'Daily Summary'!C5:C35),0)),"") | H13: =SUMPRODUCT((MONTH('Expenses'!B5:B304)=9)*('Expenses'!E5:E304)) | I13: =C13-H13
B14: October | C14: =SUMPRODUCT((MONTH('Daily Summary'!B5:B35)=10)*('Daily Summary'!C5:C35)) | D14: =SUMPRODUCT((MONTH('Daily Summary'!B5:B35)=10)*('Daily Summary'!D5:D35)) | E14: =IFERROR(C14/D14,0) | F14: =IFERROR(MAX(IF(MONTH('Daily Summary'!B5:B35)=10,'Daily Summary'!C5:C35)),0) | G14: =IFERROR(INDEX('Daily Summary'!B5:B35,MATCH(F14,IF(MONTH('Daily Summary'!B5:B35)=10,'Daily Summary'!C5:C35),0)),"") | H14: =SUMPRODUCT((MONTH('Expenses'!B5:B304)=10)*('Expenses'!E5:E304)) | I14: =C14-H14
B15: November | C15: =SUMPRODUCT((MONTH('Daily Summary'!B5:B35)=11)*('Daily Summary'!C5:C35)) | D15: =SUMPRODUCT((MONTH('Daily Summary'!B5:B35)=11)*('Daily Summary'!D5:D35)) | E15: =IFERROR(C15/D15,0) | F15: =IFERROR(MAX(IF(MONTH('Daily Summary'!B5:B35)=11,'Daily Summary'!C5:C35)),0) | G15: =IFERROR(INDEX('Daily Summary'!B5:B35,MATCH(F15,IF(MONTH('Daily Summary'!B5:B35)=11,'Daily Summary'!C5:C35),0)),"") | H15: =SUMPRODUCT((MONTH('Expenses'!B5:B304)=11)*('Expenses'!E5:E304)) | I15: =C15-H15
B16: December | C16: =SUMPRODUCT((MONTH('Daily Summary'!B5:B35)=12)*('Daily Summary'!C5:C35)) | D16: =SUMPRODUCT((MONTH('Daily Summary'!B5:B35)=12)*('Daily Summary'!D5:D35)) | E16: =IFERROR(C16/D16,0) | F16: =IFERROR(MAX(IF(MONTH('Daily Summary'!B5:B35)=12,'Daily Summary'!C5:C35)),0) | G16: =IFERROR(INDEX('Daily Summary'!B5:B35,MATCH(F16,IF(MONTH('Daily Summary'!B5:B35)=12,'Daily Summary'!C5:C35),0)),"") | H16: =SUMPRODUCT((MONTH('Expenses'!B5:B304)=12)*('Expenses'!E5:E304)) | I16: =C16-H16
B17: TOTAL | C17: =SUM(C5:C16) | D17: =SUM(D5:D16) | E17: =IFERROR(C17/D17,0) | H17: =SUM(H5:H16) | I17: =SUM(I5:I16)

Sheet Invoice
B2: [Your Company Name]
B3: [Address Line 1 | City, Country]
B4: Tel: [Phone] | VAT: [VAT Number]
B7: Invoice #: | F7: Date:
B8: Customer: | F8: Staff:
B10: Item | C10: Qty | D10: Price | E10: Discount | F10: Total
F11: =IFERROR(C11*D11-IFERROR(E11,0),0)
F12: =IFERROR(C12*D12-IFERROR(E12,0),0)
F13: =IFERROR(C13*D13-IFERROR(E13,0),0)
F14: =IFERROR(C14*D14-IFERROR(E14,0),0)
F15: =IFERROR(C15*D15-IFERROR(E15,0),0)
F16: =IFERROR(C16*D16-IFERROR(E16,0),0)
F17: =IFERROR(C17*D17-IFERROR(E17,0),0)
F18: =IFERROR(C18*D18-IFERROR(E18,0),0)
F19: =IFERROR(C19*D19-IFERROR(E19,0),0)
F20: =IFERROR(C20*D20-IFERROR(E20,0),0)
F21: =IFERROR(C21*D21-IFERROR(E21,0),0)
F22: =IFERROR(C22*D22-IFERROR(E22,0),0)
... F25: =IFERROR(C25*D25-IFERROR(E25,0),0)
D27: Subtotal: | F27: =SUM(F11:F25)
D28: Discount:
D29: VAT (5%): | F29: =IFERROR((F27-IFERROR(F28,0))*0.05,0)
D30: Grand Total: | F30: =F27-IFERROR(F28,0)+F29
B32: Thank you for your business!

Sheet Inventory
B2: Inventory — Stock Tracking
B4: Product ID | C4: Item Name | D4: Category | E4: Unit Price | F4: Cost Price | G4: Margin | H4: Stock Qty | I4: Reorder Level | J4: Status | K4: Supplier | L4: Last Restocked | M4: Days Since Restock
G5: =IFERROR((E5-F5)/E5,0) | J5: =IF(H5<=I5,"LOW STOCK","In Stock") | M5: =IFERROR(TODAY()-L5,"")
G6: =IFERROR((E6-F6)/E6,0) | J6: =IF(H6<=I6,"LOW STOCK","In Stock") | M6: =IFERROR(TODAY()-L6,"")
G7: =IFERROR((E7-F7)/E7,0) | J7: =IF(H7<=I7,"LOW STOCK","In Stock") | M7: =IFERROR(TODAY()-L7,"")
G8: =IFERROR((E8-F8)/E8,0) | J8: =IF(H8<=I8,"LOW STOCK","In Stock") | M8: =IFERROR(TODAY()-L8,"")
G9: =IFERROR((E9-F9)/E9,0) | J9: =IF(H9<=I9,"LOW STOCK","In Stock") | M9: =IFERROR(TODAY()-L9,"")
G10: =IFERROR((E10-F10)/E10,0) | J10: =IF(H10<=I10,"LOW STOCK","In Stock") | M10: =IFERROR(TODAY()-L10,"")
G11: =IFERROR((E11-F11)/E11,0) | J11: =IF(H11<=I11,"LOW STOCK","In Stock") | M11: =IFERROR(TODAY()-L11,"")
G12: =IFERROR((E12-F12)/E12,0) | J12: =IF(H12<=I12,"LOW STOCK","In Stock") | M12: =IFERROR(TODAY()-L12,"")
G13: =IFERROR((E13-F13)/E13,0) | J13: =IF(H13<=I13,"LOW STOCK","In Stock") | M13: =IFERROR(TODAY()-L13,"")
G14: =IFERROR((E14-F14)/E14,0) | J14: =IF(H14<=I14,"LOW STOCK","In Stock") | M14: =IFERROR(TODAY()-L14,"")
G15: =IFERROR((E15-F15)/E15,0) | J15: =IF(H15<=I15,"LOW STOCK","In Stock") | M15: =IFERROR(TODAY()-L15,"")
G16: =IFERROR((E16-F16)/E16,0) | J16: =IF(H16<=I16,"LOW STOCK","In Stock") | M16: =IFERROR(TODAY()-L16,"")
... G204: =IFERROR((E204-F204)/E204,0) | J204: =IF(H204<=I204,"LOW STOCK","In Stock") | M204: =IFERROR(TODAY()-L204,"")

Sheet Staff Performance
B2: Staff Performance — Employee Tracking
B4: Staff Name | C4: Total Sales | D4: # Transactions | E4: Avg Transaction | F4: Top Category | G4: Shift | H4: Commission (5%) | I4: Sales Target | J4: Target Achievement %
C5: =SUMPRODUCT(('Sales Entry'!J5:J504=B5)*('Sales Entry'!M5:M504)) | D5: =SUMPRODUCT(('Sales Entry'!J5:J504=B5)*1) | E5: =IFERROR(C5/D5,0) | F5: =IF(SUMPRODUCT(('Sales Entry'!J5:J504=B5)*('Sales Entry'!E5:E504="Grains")*('Sales Entry'!M5:M504))>=SUMPRODUCT(('Sales Entry'!J5:J504=B5)*('Sales Entry'!E5:E504="Dairy")*('Sales Entry'!M5:M504)),"Grains",IF(SUMPRODUCT(('Sales Entry'!J5:J504=B5)*('Sales Entry'!E5:E504="Dairy")*('Sales Entry'!M5:M504))>=SUMPRODUCT(('Sales Entry'!J5:J504=B5)*('Sales Entry'!E5:E504="Bakery")*('Sales Entry'!M5:M504)),"Dairy","Bakery")) | H5: =C5*0.05 | J5: =IFERROR(C5/I5,0)
C6: =SUMPRODUCT(('Sales Entry'!J5:J504=B6)*('Sales Entry'!M5:M504)) | D6: =SUMPRODUCT(('Sales Entry'!J5:J504=B6)*1) | E6: =IFERROR(C6/D6,0) | F6: =IF(SUMPRODUCT(('Sales Entry'!J5:J504=B6)*('Sales Entry'!E5:E504="Grains")*('Sales Entry'!M5:M504))>=SUMPRODUCT(('Sales Entry'!J5:J504=B6)*('Sales Entry'!E5:E504="Dairy")*('Sales Entry'!M5:M504)),"Grains",IF(SUMPRODUCT(('Sales Entry'!J5:J504=B6)*('Sales Entry'!E5:E504="Dairy")*('Sales Entry'!M5:M504))>=SUMPRODUCT(('Sales Entry'!J5:J504=B6)*('Sales Entry'!E5:E504="Bakery")*('Sales Entry'!M5:M504)),"Dairy","Bakery")) | H6: =C6*0.05 | J6: =IFERROR(C6/I6,0)
C7: =SUMPRODUCT(('Sales Entry'!J5:J504=B7)*('Sales Entry'!M5:M504)) | D7: =SUMPRODUCT(('Sales Entry'!J5:J504=B7)*1) | E7: =IFERROR(C7/D7,0) | F7: =IF(SUMPRODUCT(('Sales Entry'!J5:J504=B7)*('Sales Entry'!E5:E504="Grains")*('Sales Entry'!M5:M504))>=SUMPRODUCT(('Sales Entry'!J5:J504=B7)*('Sales Entry'!E5:E504="Dairy")*('Sales Entry'!M5:M504)),"Grains",IF(SUMPRODUCT(('Sales Entry'!J5:J504=B7)*('Sales Entry'!E5:E504="Dairy")*('Sales Entry'!M5:M504))>=SUMPRODUCT(('Sales Entry'!J5:J504=B7)*('Sales Entry'!E5:E504="Bakery")*('Sales Entry'!M5:M504)),"Dairy","Bakery")) | H7: =C7*0.05 | J7: =IFERROR(C7/I7,0)
C8: =SUMPRODUCT(('Sales Entry'!J5:J504=B8)*('Sales Entry'!M5:M504)) | D8: =SUMPRODUCT(('Sales Entry'!J5:J504=B8)*1) | E8: =IFERROR(C8/D8,0) | F8: =IF(SUMPRODUCT(('Sales Entry'!J5:J504=B8)*('Sales Entry'!E5:E504="Grains")*('Sales Entry'!M5:M504))>=SUMPRODUCT(('Sales Entry'!J5:J504=B8)*('Sales Entry'!E5:E504="Dairy")*('Sales Entry'!M5:M504)),"Grains",IF(SUMPRODUCT(('Sales Entry'!J5:J504=B8)*('Sales Entry'!E5:E504="Dairy")*('Sales Entry'!M5:M504))>=SUMPRODUCT(('Sales Entry'!J5:J504=B8)*('Sales Entry'!E5:E504="Bakery")*('Sales Entry'!M5:M504)),"Dairy","Bakery")) | H8: =C8*0.05 | J8: =IFERROR(C8/I8,0)
C9: =SUMPRODUCT(('Sales Entry'!J5:J504=B9)*('Sales Entry'!M5:M504)) | D9: =SUMPRODUCT(('Sales Entry'!J5:J504=B9)*1) | E9: =IFERROR(C9/D9,0) | F9: =IF(SUMPRODUCT(('Sales Entry'!J5:J504=B9)*('Sales Entry'!E5:E504="Grains")*('Sales Entry'!M5:M504))>=SUMPRODUCT(('Sales Entry'!J5:J504=B9)*('Sales Entry'!E5:E504="Dairy")*('Sales Entry'!M5:M504)),"Grains",IF(SUMPRODUCT(('Sales Entry'!J5:J504=B9)*('Sales Entry'!E5:E504="Dairy")*('Sales Entry'!M5:M504))>=SUMPRODUCT(('Sales Entry'!J5:J504=B9)*('Sales Entry'!E5:E504="Bakery")*('Sales Entry'!M5:M504)),"Dairy","Bakery")) | H9: =C9*0.05 | J9: =IFERROR(C9/I9,0)
C10: =SUMPRODUCT(('Sales Entry'!J5:J504=B10)*('Sales Entry'!M5:M504)) | D10: =SUMPRODUCT(('Sales Entry'!J5:J504=B10)*1) | E10: =IFERROR(C10/D10,0) | F10: =IF(SUMPRODUCT(('Sales Entry'!J5:J504=B10)*('Sales Entry'!E5:E504="Grains")*('Sales Entry'!M5:M504))>=SUMPRODUCT(('Sales Entry'!J5:J504=B10)*('Sales Entry'!E5:E504="Dairy")*('Sales Entry'!M5:M504)),"Grains",IF(SUMPRODUCT(('Sales Entry'!J5:J504=B10)*('Sales Entry'!E5:E504="Dairy")*('Sales Entry'!M5:M504))>=SUMPRODUCT(('Sales Entry'!J5:J504=B10)*('Sales Entry'!E5:E504="Bakery")*('Sales Entry'!M5:M504)),"Dairy","Bakery")) | H10: =C10*0.05 | J10: =IFERROR(C10/I10,0)
C11: =SUMPRODUCT(('Sales Entry'!J5:J504=B11)*('Sales Entry'!M5:M504)) | D11: =SUMPRODUCT(('Sales Entry'!J5:J504=B11)*1) | E11: =IFERROR(C11/D11,0) | F11: =IF(SUMPRODUCT(('Sales Entry'!J5:J504=B11)*('Sales Entry'!E5:E504="Grains")*('Sales Entry'!M5:M504))>=SUMPRODUCT(('Sales Entry'!J5:J504=B11)*('Sales Entry'!E5:E504="Dairy")*('Sales Entry'!M5:M504)),"Grains",IF(SUMPRODUCT(('Sales Entry'!J5:J504=B11)*('Sales Entry'!E5:E504="Dairy")*('Sales Entry'!M5:M504))>=SUMPRODUCT(('Sales Entry'!J5:J504=B11)*('Sales Entry'!E5:E504="Bakery")*('Sales Entry'!M5:M504)),"Dairy","Bakery")) | H11: =C11*0.05 | J11: =IFERROR(C11/I11,0)
C12: =SUMPRODUCT(('Sales Entry'!J5:J504=B12)*('Sales Entry'!M5:M504)) | D12: =SUMPRODUCT(('Sales Entry'!J5:J504=B12)*1) | E12: =IFERROR(C12/D12,0) | F12: =IF(SUMPRODUCT(('Sales Entry'!J5:J504=B12)*('Sales Entry'!E5:E504="Grains")*('Sales Entry'!M5:M504))>=SUMPRODUCT(('Sales Entry'!J5:J504=B12)*('Sales Entry'!E5:E504="Dairy")*('Sales Entry'!M5:M504)),"Grains",IF(SUMPRODUCT(('Sales Entry'!J5:J504=B12)*('Sales Entry'!E5:E504="Dairy")*('Sales Entry'!M5:M504))>=SUMPRODUCT(('Sales Entry'!J5:J504=B12)*('Sales Entry'!E5:E504="Bakery")*('Sales Entry'!M5:M504)),"Dairy","Bakery")) | H12: =C12*0.05 | J12: =IFERROR(C12/I12,0)
C13: =SUMPRODUCT(('Sales Entry'!J5:J504=B13)*('Sales Entry'!M5:M504)) | D13: =SUMPRODUCT(('Sales Entry'!J5:J504=B13)*1) | E13: =IFERROR(C13/D13,0) | F13: =IF(SUMPRODUCT(('Sales Entry'!J5:J504=B13)*('Sales Entry'!E5:E504="Grains")*('Sales Entry'!M5:M504))>=SUMPRODUCT(('Sales Entry'!J5:J504=B13)*('Sales Entry'!E5:E504="Dairy")*('Sales Entry'!M5:M504)),"Grains",IF(SUMPRODUCT(('Sales Entry'!J5:J504=B13)*('Sales Entry'!E5:E504="Dairy")*('Sales Entry'!M5:M504))>=SUMPRODUCT(('Sales Entry'!J5:J504=B13)*('Sales Entry'!E5:E504="Bakery")*('Sales Entry'!M5:M504)),"Dairy","Bakery")) | H13: =C13*0.05 | J13: =IFERROR(C13/I13,0)
C14: =SUMPRODUCT(('Sales Entry'!J5:J504=B14)*('Sales Entry'!M5:M504)) | D14: =SUMPRODUCT(('Sales Entry'!J5:J504=B14)*1) | E14: =IFERROR(C14/D14,0) | F14: =IF(SUMPRODUCT(('Sales Entry'!J5:J504=B14)*('Sales Entry'!E5:E504="Grains")*('Sales Entry'!M5:M504))>=SUMPRODUCT(('Sales Entry'!J5:J504=B14)*('Sales Entry'!E5:E504="Dairy")*('Sales Entry'!M5:M504)),"Grains",IF(SUMPRODUCT(('Sales Entry'!J5:J504=B14)*('Sales Entry'!E5:E504="Dairy")*('Sales Entry'!M5:M504))>=SUMPRODUCT(('Sales Entry'!J5:J504=B14)*('Sales Entry'!E5:E504="Bakery")*('Sales Entry'!M5:M504)),"Dairy","Bakery")) | H14: =C14*0.05 | J14: =IFERROR(C14/I14,0)
C15: =SUMPRODUCT(('Sales Entry'!J5:J504=B15)*('Sales Entry'!M5:M504)) | D15: =SUMPRODUCT(('Sales Entry'!J5:J504=B15)*1) | E15: =IFERROR(C15/D15,0) | F15: =IF(SUMPRODUCT(('Sales Entry'!J5:J504=B15)*('Sales Entry'!E5:E504="Grains")*('Sales Entry'!M5:M504))>=SUMPRODUCT(('Sales Entry'!J5:J504=B15)*('Sales Entry'!E5:E504="Dairy")*('Sales Entry'!M5:M504)),"Grains",IF(SUMPRODUCT(('Sales Entry'!J5:J504=B15)*('Sales Entry'!E5:E504="Dairy")*('Sales Entry'!M5:M504))>=SUMPRODUCT(('Sales Entry'!J5:J504=B15)*('Sales Entry'!E5:E504="Bakery")*('Sales Entry'!M5:M504)),"Dairy","Bakery")) | H15: =C15*0.05 | J15: =IFERROR(C15/I15,0)
C16: =SUMPRODUCT(('Sales Entry'!J5:J504=B16)*('Sales Entry'!M5:M504)) | D16: =SUMPRODUCT(('Sales Entry'!J5:J504=B16)*1) | E16: =IFERROR(C16/D16,0) | F16: =IF(SUMPRODUCT(('Sales Entry'!J5:J504=B16)*('Sales Entry'!E5:E504="Grains")*('Sales Entry'!M5:M504))>=SUMPRODUCT(('Sales Entry'!J5:J504=B16)*('Sales Entry'!E5:E504="Dairy")*('Sales Entry'!M5:M504)),"Grains",IF(SUMPRODUCT(('Sales Entry'!J5:J504=B16)*('Sales Entry'!E5:E504="Dairy")*('Sales Entry'!M5:M504))>=SUMPRODUCT(('Sales Entry'!J5:J504=B16)*('Sales Entry'!E5:E504="Bakery")*('Sales Entry'!M5:M504)),"Dairy","Bakery")) | H16: =C16*0.05 | J16: =IFERROR(C16/I16,0)
C17: =SUMPRODUCT(('Sales Entry'!J5:J504=B17)*('Sales Entry'!M5:M504)) | D17: =SUMPRODUCT(('Sales Entry'!J5:J504=B17)*1) | E17: =IFERROR(C17/D17,0) | F17: =IF(SUMPRODUCT(('Sales Entry'!J5:J504=B17)*('Sales Entry'!E5:E504="Grains")*('Sales Entry'!M5:M504))>=SUMPRODUCT(('Sales Entry'!J5:J504=B17)*('Sales Entry'!E5:E504="Dairy")*('Sales Entry'!M5:M504)),"Grains",IF(SUMPRODUCT(('Sales Entry'!J5:J504=B17)*('Sales Entry'!E5:E504="Dairy")*('Sales Entry'!M5:M504))>=SUMPRODUCT(('Sales Entry'!J5:J504=B17)*('Sales Entry'!E5:E504="Bakery")*('Sales Entry'!M5:M504)),"Dairy","Bakery")) | H17: =C17*0.05 | J17: =IFERROR(C17/I17,0)
C18: =SUMPRODUCT(('Sales Entry'!J5:J504=B18)*('Sales Entry'!M5:M504)) | D18: =SUMPRODUCT(('Sales Entry'!J5:J504=B18)*1) | E18: =IFERROR(C18/D18,0) | F18: =IF(SUMPRODUCT(('Sales Entry'!J5:J504=B18)*('Sales Entry'!E5:E504="Grains")*('Sales Entry'!M5:M504))>=SUMPRODUCT(('Sales Entry'!J5:J504=B18)*('Sales Entry'!E5:E504="Dairy")*('Sales Entry'!M5:M504)),"Grains",IF(SUMPRODUCT(('Sales Entry'!J5:J504=B18)*('Sales Entry'!E5:E504="Dairy")*('Sales Entry'!M5:M504))>=SUMPRODUCT(('Sales Entry'!J5:J504=B18)*('Sales Entry'!E5:E504="Bakery")*('Sales Entry'!M5:M504)),"Dairy","Bakery")) | H18: =C18*0.05 | J18: =IFERROR(C18/I18,0)
C19: =SUMPRODUCT(('Sales Entry'!J5:J504=B19)*('Sales Entry'!M5:M504)) | D19: =SUMPRODUCT(('Sales Entry'!J5:J504=B19)*1) | E19: =IFERROR(C19/D19,0) | F19: =IF(SUMPRODUCT(('Sales Entry'!J5:J504=B19)*('Sales Entry'!E5:E504="Grains")*('Sales Entry'!M5:M504))>=SUMPRODUCT(('Sales Entry'!J5:J504=B19)*('Sales Entry'!E5:E504="Dairy")*('Sales Entry'!M5:M504)),"Grains",IF(SUMPRODUCT(('Sales Entry'!J5:J504=B19)*('Sales Entry'!E5:E504="Dairy")*('Sales Entry'!M5:M504))>=SUMPRODUCT(('Sales Entry'!J5:J504=B19)*('Sales Entry'!E5:E504="Bakery")*('Sales Entry'!M5:M504)),"Dairy","Bakery")) | H19: =C19*0.05 | J19: =IFERROR(C19/I19,0)
C20: =SUMPRODUCT(('Sales Entry'!J5:J504=B20)*('Sales Entry'!M5:M504)) | D20: =SUMPRODUCT(('Sales Entry'!J5:J504=B20)*1) | E20: =IFERROR(C20/D20,0) | F20: =IF(SUMPRODUCT(('Sales Entry'!J5:J504=B20)*('Sales Entry'!E5:E504="Grains")*('Sales Entry'!M5:M504))>=SUMPRODUCT(('Sales Entry'!J5:J504=B20)*('Sales Entry'!E5:E504="Dairy")*('Sales Entry'!M5:M504)),"Grains",IF(SUMPRODUCT(('Sales Entry'!J5:J504=B20)*('Sales Entry'!E5:E504="Dairy")*('Sales Entry'!M5:M504))>=SUMPRODUCT(('Sales Entry'!J5:J504=B20)*('Sales Entry'!E5:E504="Bakery")*('Sales Entry'!M5:M504)),"Dairy","Bakery")) | H20: =C20*0.05 | J20: =IFERROR(C20/I20,0)
C21: =SUMPRODUCT(('Sales Entry'!J5:J504=B21)*('Sales Entry'!M5:M504)) | D21: =SUMPRODUCT(('Sales Entry'!J5:J504=B21)*1) | E21: =IFERROR(C21/D21,0) | F21: =IF(SUMPRODUCT(('Sales Entry'!J5:J504=B21)*('Sales Entry'!E5:E504="Grains")*('Sales Entry'!M5:M504))>=SUMPRODUCT(('Sales Entry'!J5:J504=B21)*('Sales Entry'!E5:E504="Dairy")*('Sales Entry'!M5:M504)),"Grains",IF(SUMPRODUCT(('Sales Entry'!J5:J504=B21)*('Sales Entry'!E5:E504="Dairy")*('Sales Entry'!M5:M504))>=SUMPRODUCT(('Sales Entry'!J5:J504=B21)*('Sales Entry'!E5:E504="Bakery")*('Sales Entry'!M5:M504)),"Dairy","Bakery")) | H21: =C21*0.05 | J21: =IFERROR(C21/I21,0)
C22: =SUMPRODUCT(('Sales Entry'!J5:J504=B22)*('Sales Entry'!M5:M504)) | D22: =SUMPRODUCT(('Sales Entry'!J5:J504=B22)*1) | E22: =IFERROR(C22/D22,0) | F22: =IF(SUMPRODUCT(('Sales Entry'!J5:J504=B22)*('Sales Entry'!E5:E504="Grains")*('Sales Entry'!M5:M504))>=SUMPRODUCT(('Sales Entry'!J5:J504=B22)*('Sales Entry'!E5:E504="Dairy")*('Sales Entry'!M5:M504)),"Grains",IF(SUMPRODUCT(('Sales Entry'!J5:J504=B22)*('Sales Entry'!E5:E504="Dairy")*('Sales Entry'!M5:M504))>=SUMPRODUCT(('Sales Entry'!J5:J504=B22)*('Sales Entry'!E5:E504="Bakery")*('Sales Entry'!M5:M504)),"Dairy","Bakery")) | H22: =C22*0.05 | J22: =IFERROR(C22/I22,0)
C23: =SUMPRODUCT(('Sales Entry'!J5:J504=B23)*('Sales Entry'!M5:M504)) | D23: =SUMPRODUCT(('Sales Entry'!J5:J504=B23)*1) | E23: =IFERROR(C23/D23,0) | F23: =IF(SUMPRODUCT(('Sales Entry'!J5:J504=B23)*('Sales Entry'!E5:E504="Grains")*('Sales Entry'!M5:M504))>=SUMPRODUCT(('Sales Entry'!J5:J504=B23)*('Sales Entry'!E5:E504="Dairy")*('Sales Entry'!M5:M504)),"Grains",IF(SUMPRODUCT(('Sales Entry'!J5:J504=B23)*('Sales Entry'!E5:E504="Dairy")*('Sales Entry'!M5:M504))>=SUMPRODUCT(('Sales Entry'!J5:J504=B23)*('Sales Entry'!E5:E504="Bakery")*('Sales Entry'!M5:M504)),"Dairy","Bakery")) | H23: =C23*0.05 | J23: =IFERROR(C23/I23,0)
C24: =SUMPRODUCT(('Sales Entry'!J5:J504=B24)*('Sales Entry'!M5:M504)) | D24: =SUMPRODUCT(('Sales Entry'!J5:J504=B24)*1) | E24: =IFERROR(C24/D24,0) | F24: =IF(SUMPRODUCT(('Sales Entry'!J5:J504=B24)*('Sales Entry'!E5:E504="Grains")*('Sales Entry'!M5:M504))>=SUMPRODUCT(('Sales Entry'!J5:J504=B24)*('Sales Entry'!E5:E504="Dairy")*('Sales Entry'!M5:M504)),"Grains",IF(SUMPRODUCT(('Sales Entry'!J5:J504=B24)*('Sales Entry'!E5:E504="Dairy")*('Sales Entry'!M5:M504))>=SUMPRODUCT(('Sales Entry'!J5:J504=B24)*('Sales Entry'!E5:E504="Bakery")*('Sales Entry'!M5:M504)),"Dairy","Bakery")) | H24: =C24*0.05 | J24: =IFERROR(C24/I24,0)
C25: =SUMPRODUCT(('Sales Entry'!J5:J504=B25)*('Sales Entry'!M5:M504)) | D25: =SUMPRODUCT(('Sales Entry'!J5:J504=B25)*1) | E25: =IFERROR(C25/D25,0) | F25: =IF(SUMPRODUCT(('Sales Entry'!J5:J504=B25)*('Sales Entry'!E5:E504="Grains")*('Sales Entry'!M5:M504))>=SUMPRODUCT(('Sales Entry'!J5:J504=B25)*('Sales Entry'!E5:E504="Dairy")*('Sales Entry'!M5:M504)),"Grains",IF(SUMPRODUCT(('Sales Entry'!J5:J504=B25)*('Sales Entry'!E5:E504="Dairy")*('Sales Entry'!M5:M504))>=SUMPRODUCT(('Sales Entry'!J5:J504=B25)*('Sales Entry'!E5:E504="Bakery")*('Sales Entry'!M5:M504)),"Dairy","Bakery")) | H25: =C25*0.05 | J25: =IFERROR(C25/I25,0)
C26: =SUMPRODUCT(('Sales Entry'!J5:J504=B26)*('Sales Entry'!M5:M504)) | D26: =SUMPRODUCT(('Sales Entry'!J5:J504=B26)*1) | E26: =IFERROR(C26/D26,0) | F26: =IF(SUMPRODUCT(('Sales Entry'!J5:J504=B26)*('Sales Entry'!E5:E504="Grains")*('Sales Entry'!M5:M504))>=SUMPRODUCT(('Sales Entry'!J5:J504=B26)*('Sales Entry'!E5:E504="Dairy")*('Sales Entry'!M5:M504)),"Grains",IF(SUMPRODUCT(('Sales Entry'!J5:J504=B26)*('Sales Entry'!E5:E504="Dairy")*('Sales Entry'!M5:M504))>=SUMPRODUCT(('Sales Entry'!J5:J504=B26)*('Sales Entry'!E5:E504="Bakery")*('Sales Entry'!M5:M504)),"Dairy","Bakery")) | H26: =C26*0.05 | J26: =IFERROR(C26/I26,0)
C27: =SUMPRODUCT(('Sales Entry'!J5:J504=B27)*('Sales Entry'!M5:M504)) | D27: =SUMPRODUCT(('Sales Entry'!J5:J504=B27)*1) | E27: =IFERROR(C27/D27,0) | F27: =IF(SUMPRODUCT(('Sales Entry'!J5:J504=B27)*('Sales Entry'!E5:E504="Grains")*('Sales Entry'!M5:M504))>=SUMPRODUCT(('Sales Entry'!J5:J504=B27)*('Sales Entry'!E5:E504="Dairy")*('Sales Entry'!M5:M504)),"Grains",IF(SUMPRODUCT(('Sales Entry'!J5:J504=B27)*('Sales Entry'!E5:E504="Dairy")*('Sales Entry'!M5:M504))>=SUMPRODUCT(('Sales Entry'!J5:J504=B27)*('Sales Entry'!E5:E504="Bakery")*('Sales Entry'!M5:M504)),"Dairy","Bakery")) | H27: =C27*0.05 | J27: =IFERROR(C27/I27,0)
C28: =SUMPRODUCT(('Sales Entry'!J5:J504=B28)*('Sales Entry'!M5:M504)) | D28: =SUMPRODUCT(('Sales Entry'!J5:J504=B28)*1) | E28: =IFERROR(C28/D28,0) | F28: =IF(SUMPRODUCT(('Sales Entry'!J5:J504=B28)*('Sales Entry'!E5:E504="Grains")*('Sales Entry'!M5:M504))>=SUMPRODUCT(('Sales Entry'!J5:J504=B28)*('Sales Entry'!E5:E504="Dairy")*('Sales Entry'!M5:M504)),"Grains",IF(SUMPRODUCT(('Sales Entry'!J5:J504=B28)*('Sales Entry'!E5:E504="Dairy")*('Sales Entry'!M5:M504))>=SUMPRODUCT(('Sales Entry'!J5:J504=B28)*('Sales Entry'!E5:E504="Bakery")*('Sales Entry'!M5:M504)),"Dairy","Bakery")) | H28: =C28*0.05 | J28: =IFERROR(C28/I28,0)
C29: =SUMPRODUCT(('Sales Entry'!J5:J504=B29)*('Sales Entry'!M5:M504)) | D29: =SUMPRODUCT(('Sales Entry'!J5:J504=B29)*1) | E29: =IFERROR(C29/D29,0) | F29: =IF(SUMPRODUCT(('Sales Entry'!J5:J504=B29)*('Sales Entry'!E5:E504="Grains")*('Sales Entry'!M5:M504))>=SUMPRODUCT(('Sales Entry'!J5:J504=B29)*('Sales Entry'!E5:E504="Dairy")*('Sales Entry'!M5:M504)),"Grains",IF(SUMPRODUCT(('Sales Entry'!J5:J504=B29)*('Sales Entry'!E5:E504="Dairy")*('Sales Entry'!M5:M504))>=SUMPRODUCT(('Sales Entry'!J5:J504=B29)*('Sales Entry'!E5:E504="Bakery")*('Sales Entry'!M5:M504)),"Dairy","Bakery")) | H29: =C29*0.05 | J29: =IFERROR(C29/I29,0)
B30: TOTAL | C30: =SUM(C5:C29) | D30: =SUM(D5:D29) | E30: =IFERROR(C30/D30,0) | H30: =SUM(H5:H29)

Sheet Expenses
B2: Expenses — Expense Tracking
B4: Date | C4: Expense Category | D4: Description | E4: Amount | F4: Payment Method | G4: Vendor | H4: Receipt # | I4: Notes
B305: TOTAL | E305: =SUM(E5:E304)
B308: Totals by Category
B309: Category | C309: Total Amount
B310: Rent | C310: =SUMPRODUCT((C5:C304="Rent")*(E5:E304))
B311: Salaries | C311: =SUMPRODUCT((C5:C304="Salaries")*(E5:E304))
B312: Utilities | C312: =SUMPRODUCT((C5:C304="Utilities")*(E5:E304))
B313: Supplies | C313: =SUMPRODUCT((C5:C304="Supplies")*(E5:E304))
B314: Maintenance | C314: =SUMPRODUCT((C5:C304="Maintenance")*(E5:E304))
B315: Marketing | C315: =SUMPRODUCT((C5:C304="Marketing")*(E5:E304))
B316: Transport | C316: =SUMPRODUCT((C5:C304="Transport")*(E5:E304))
B317: Insurance | C317: =SUMPRODUCT((C5:C304="Insurance")*(E5:E304))
B318: Miscellaneous | C318: =SUMPRODUCT((C5:C304="Miscellaneous")*(E5:E304))
B319: GRAND TOTAL | C319: =SUM(C310:C318)

Sheet Profit Analysis
B2: Profit Analysis — P&L Statement
B4: REVENUE
B5: Month | C5: Revenue | D5: COGS (est. 70%) | E5: Gross Profit | F5: Operating Expenses | G5: Net Profit | H5: Profit Margin %
B6: January | C6: ='Monthly Summary'!C5 | D6: =C6*0.7 | E6: =C6-D6 | F6: ='Monthly Summary'!H5 | G6: =E6-F6 | H6: =IFERROR(G6/C6,0)
B7: February | C7: ='Monthly Summary'!C6 | D7: =C7*0.7 | E7: =C7-D7 | F7: ='Monthly Summary'!H6 | G7: =E7-F7 | H7: =IFERROR(G7/C7,0)
B8: March | C8: ='Monthly Summary'!C7 | D8: =C8*0.7 | E8: =C8-D8 | F8: ='Monthly Summary'!H7 | G8: =E8-F8 | H8: =IFERROR(G8/C8,0)
B9: April | C9: ='Monthly Summary'!C8 | D9: =C9*0.7 | E9: =C9-D9 | F9: ='Monthly Summary'!H8 | G9: =E9-F9 | H9: =IFERROR(G9/C9,0)
B10: May | C10: ='Monthly Summary'!C9 | D10: =C10*0.7 | E10: =C10-D10 | F10: ='Monthly Summary'!H9 | G10: =E10-F10 | H10: =IFERROR(G10/C10,0)
B11: June | C11: ='Monthly Summary'!C10 | D11: =C11*0.7 | E11: =C11-D11 | F11: ='Monthly Summary'!H10 | G11: =E11-F11 | H11: =IFERROR(G11/C11,0)
