Workbook

Sheet Sales Entry
B2: Sales Entry
B4: Date | C4: Invoice # | D4: Item / Service | E4: Category | F4: Qty | G4: Unit Price | H4: Total | I4: Payment Method | J4: Customer Name | K4: Notes
B5: 45659 | C5: INV-0026 | D5: Smoothie | E5: Beverages | F5: 1 | G5: 22 | H5: =IFERROR(F5*G5,"") | I5: Cash | J5: Noor Abdullah | K5: Regular customer
B6: 45660 | C6: INV-0009 | D6: Salad | E6: Appetizers | F6: 1 | G6: 30 | H6: =IFERROR(F6*G6,"") | I6: Online | J6: Khalid Ibrahim | K6: Online order
B7: 45660 | C7: INV-0038 | D7: Cheesecake | E7: Desserts | F7: 3 | G7: 28 | H7: =IFERROR(F7*G7,"") | I7: Cash | J7: Aisha Al Sayed | K7: Bulk order
B8: 45660 | C8: INV-0043 | D8: Shawarma | E8: Main Course | F8: 1 | G8: 30 | H8: =IFERROR(F8*G8,"") | I8: Card | J8: Khalid Ibrahim | K8: Regular customer
B9: 45660 | C9: INV-0045 | D9: Tea | E9: Beverages | F9: 4 | G9: 10 | H9: =IFERROR(F9*G9,"") | I9: Cash | J9: Sarah Johnson | K9: Bulk order
B10: 45661 | C10: INV-0049 | D10: Mojito Mocktail | E10: Beverages | F10: 2 | G10: 24 | H10: =IFERROR(F10*G10,"") | I10: Online | J10: Fatima Hassan | K10: Online order
B11: 45662 | C11: INV-0008 | D11: Sandwich | E11: Main Course | F11: 4 | G11: 25 | H11: =IFERROR(F11*G11,"") | I11: Online | J11: Walk-in | K11: Bulk order
B12: 45662 | C12: INV-0047 | D12: Manakish | E12: Appetizers | F12: 4 | G12: 16 | H12: =IFERROR(F12*G12,"") | I12: Cheque | J12: Walk-in | K12: Bulk order
B13: 45663 | C13: INV-0053 | D13: Pasta | E13: Main Course | F13: 2 | G13: 45 | H13: =IFERROR(F13*G13,"") | I13: Cash | J13: Mohammed Al Rashid | K13: Regular customer
B14: 45664 | C14: INV-0012 | D14: Mandi | E14: Main Course | F14: 1 | G14: 50 | H14: =IFERROR(F14*G14,"") | I14: Card | J14: Noor Abdullah | K14: Regular customer
B15: 45664 | C15: INV-0052 | D15: Sandwich | E15: Main Course | F15: 2 | G15: 25 | H15: =IFERROR(F15*G15,"") | I15: Cash | J15: Fatima Hassan | K15: Regular customer
B16: 45665 | C16: INV-0002 | D16: Water | E16: Beverages | F16: 3 | G16: 5 | H16: =IFERROR(F16*G16,"") | I16: Cash | J16: Khalid Ibrahim | K16: Bulk order
B17: 45665 | C17: INV-0025 | D17: Water | E17: Beverages | F17: 2 | G17: 5 | H17: =IFERROR(F17*G17,"") | I17: Cash | J17: Noor Abdullah | K17: Regular customer
B18: 45665 | C18: INV-0044 | D18: Coffee | E18: Beverages | F18: 1 | G18: 15 | H18: =IFERROR(F18*G18,"") | I18: Cash | J18: Walk-in
B19: 45665 | C19: INV-0046 | D19: Pasta | E19: Main Course | F19: 2 | G19: 45 | H19: =IFERROR(F19*G19,"") | I19: Card | J19: Sarah Johnson | K19: Regular customer
B20: 45666 | C20: INV-0010 | D20: Tea | E20: Beverages | F20: 3 | G20: 10 | H20: =IFERROR(F20*G20,"") | I20: Cash | J20: Layla Khalil | K20: Bulk order
B21: 45666 | C21: INV-0014 | D21: Fries | E21: Appetizers | F21: 2 | G21: 15 | H21: =IFERROR(F21*G21,"") | I21: Online | J21: Walk-in | K21: Online order
B22: 45666 | C22: INV-0023 | D22: Water | E22: Beverages | F22: 1 | G22: 5 | H22: =IFERROR(F22*G22,"") | I22: Card | J22: Omar Farooq | K22: Regular customer
B23: 45667 | C23: INV-0013 | D23: Fresh Juice | E23: Beverages | F23: 3 | G23: 18 | H23: =IFERROR(F23*G23,"") | I23: Cash | J23: Fatima Hassan | K23: Bulk order
B24: 45667 | C24: INV-0041 | D24: Salad | E24: Appetizers | F24: 4 | G24: 30 | H24: =IFERROR(F24*G24,"") | I24: Online | J24: Mohammed Al Rashid | K24: Bulk order
B25: 45668 | C25: INV-0019 | D25: Tea | E25: Beverages | F25: 1 | G25: 10 | H25: =IFERROR(F25*G25,"") | I25: Cash | J25: Noor Abdullah | K25: Regular customer
B26: 45668 | C26: INV-0020 | D26: Salad | E26: Appetizers | F26: 1 | G26: 30 | H26: =IFERROR(F26*G26,"") | I26: Card | J26: Layla Khalil | K26: Regular customer
B27: 45668 | C27: INV-0035 | D27: Hummus | E27: Appetizers | F27: 1 | G27: 18 | H27: =IFERROR(F27*G27,"") | I27: Online | J27: Layla Khalil | K27: Online order
B28: 45669 | C28: INV-0015 | D28: Biryani | E28: Main Course | F28: 1 | G28: 40 | H28: =IFERROR(F28*G28,"") | I28: Card | J28: Omar Farooq | K28: Regular customer
B29: 45669 | C29: INV-0034 | D29: Soft Drink | E29: Beverages | F29: 2 | G29: 8 | H29: =IFERROR(F29*G29,"") | I29: Cash | J29: Khalid Ibrahim | K29: Regular customer
B30: 45670 | C30: INV-0011 | D30: Fresh Juice | E30: Beverages | F30: 2 | G30: 18 | H30: =IFERROR(F30*G30,"") | I30: Online | J30: Khalid Ibrahim | K30: Online order
B31: 45670 | C31: INV-0051 | D31: Manakish | E31: Appetizers | F31: 1 | G31: 16 | H31: =IFERROR(F31*G31,"") | I31: Cash | J31: Walk-in
B32: 45671 | C32: INV-0003 | D32: Tea | E32: Beverages | F32: 1 | G32: 10 | H32: =IFERROR(F32*G32,"") | I32: Card | J32: Walk-in
B33: 45672 | C33: INV-0031 | D33: Coffee | E33: Beverages | F33: 4 | G33: 15 | H33: =IFERROR(F33*G33,"") | I33: Card | J33: Sarah Johnson | K33: Bulk order
B34: 45672 | C34: INV-0050 | D34: Manakish | E34: Appetizers | F34: 1 | G34: 16 | H34: =IFERROR(F34*G34,"") | I34: Cash | J34: Walk-in
B35: 45673 | C35: INV-0039 | D35: Cheesecake | E35: Desserts | F35: 1 | G35: 28 | H35: =IFERROR(F35*G35,"") | I35: Online | J35: Walk-in | K35: Online order
B36: 45674 | C36: INV-0004 | D36: Kunafa | E36: Desserts | F36: 1 | G36: 25 | H36: =IFERROR(F36*G36,"") | I36: Card | J36: Omar Farooq | K36: Regular customer
B37: 45676 | C37: INV-0006 | D37: Pasta | E37: Main Course | F37: 3 | G37: 45 | H37: =IFERROR(F37*G37,"") | I37: Cash | J37: Noor Abdullah | K37: Bulk order
B38: 45676 | C38: INV-0024 | D38: Soup | E38: Appetizers | F38: 4 | G38: 20 | H38: =IFERROR(F38*G38,"") | I38: Online | J38: Ahmed Al Maktoum | K38: Bulk order
B39: 45676 | C39: INV-0037 | D39: Fresh Juice | E39: Beverages | F39: 1 | G39: 18 | H39: =IFERROR(F39*G39,"") | I39: Cheque | J39: Yusuf Ali | K39: Regular customer
B40: 45677 | C40: INV-0028 | D40: Fries | E40: Appetizers | F40: 2 | G40: 15 | H40: =IFERROR(F40*G40,"") | I40: Cash | J40: Aisha Al Sayed | K40: Regular customer
B41: 45678 | C41: INV-0001 | D41: Smoothie | E41: Beverages | F41: 1 | G41: 22 | H41: =IFERROR(F41*G41,"") | I41: Card | J41: Walk-in
B42: 45678 | C42: INV-0005 | D42: Mandi | E42: Main Course | F42: 2 | G42: 50 | H42: =IFERROR(F42*G42,"") | I42: Card | J42: Mohammed Al Rashid | K42: Regular customer
...

Sheet Daily Summary
B2: Daily Summary
B4: Date | C4: Total Sales | D4: # Transactions | E4: Avg Transaction | F4: Cash Total | G4: Card Total | H4: Online Total
B5: 45658 | C5: =IFERROR(SUMPRODUCT(('Sales Entry'!B$5:B$59=B5)*('Sales Entry'!H$5:H$59)),"") | D5: =IFERROR(SUMPRODUCT(('Sales Entry'!B$5:B$59=B5)*1),"") | E5: =IFERROR(C5/D5,"") | F5: =IFERROR(SUMPRODUCT(('Sales Entry'!B$5:B$59=B5)*('Sales Entry'!I$5:I$59="Cash")*('Sales Entry'!H$5:H$59)),"") | G5: =IFERROR(SUMPRODUCT(('Sales Entry'!B$5:B$59=B5)*('Sales Entry'!I$5:I$59="Card")*('Sales Entry'!H$5:H$59)),"") | H5: =IFERROR(SUMPRODUCT(('Sales Entry'!B$5:B$59=B5)*('Sales Entry'!I$5:I$59="Online")*('Sales Entry'!H$5:H$59)),"")
B6: 45659 | C6: =IFERROR(SUMPRODUCT(('Sales Entry'!B$5:B$59=B6)*('Sales Entry'!H$5:H$59)),"") | D6: =IFERROR(SUMPRODUCT(('Sales Entry'!B$5:B$59=B6)*1),"") | E6: =IFERROR(C6/D6,"") | F6: =IFERROR(SUMPRODUCT(('Sales Entry'!B$5:B$59=B6)*('Sales Entry'!I$5:I$59="Cash")*('Sales Entry'!H$5:H$59)),"") | G6: =IFERROR(SUMPRODUCT(('Sales Entry'!B$5:B$59=B6)*('Sales Entry'!I$5:I$59="Card")*('Sales Entry'!H$5:H$59)),"") | H6: =IFERROR(SUMPRODUCT(('Sales Entry'!B$5:B$59=B6)*('Sales Entry'!I$5:I$59="Online")*('Sales Entry'!H$5:H$59)),"")
B7: 45660 | C7: =IFERROR(SUMPRODUCT(('Sales Entry'!B$5:B$59=B7)*('Sales Entry'!H$5:H$59)),"") | D7: =IFERROR(SUMPRODUCT(('Sales Entry'!B$5:B$59=B7)*1),"") | E7: =IFERROR(C7/D7,"") | F7: =IFERROR(SUMPRODUCT(('Sales Entry'!B$5:B$59=B7)*('Sales Entry'!I$5:I$59="Cash")*('Sales Entry'!H$5:H$59)),"") | G7: =IFERROR(SUMPRODUCT(('Sales Entry'!B$5:B$59=B7)*('Sales Entry'!I$5:I$59="Card")*('Sales Entry'!H$5:H$59)),"") | H7: =IFERROR(SUMPRODUCT(('Sales Entry'!B$5:B$59=B7)*('Sales Entry'!I$5:I$59="Online")*('Sales Entry'!H$5:H$59)),"")
B8: 45661 | C8: =IFERROR(SUMPRODUCT(('Sales Entry'!B$5:B$59=B8)*('Sales Entry'!H$5:H$59)),"") | D8: =IFERROR(SUMPRODUCT(('Sales Entry'!B$5:B$59=B8)*1),"") | E8: =IFERROR(C8/D8,"") | F8: =IFERROR(SUMPRODUCT(('Sales Entry'!B$5:B$59=B8)*('Sales Entry'!I$5:I$59="Cash")*('Sales Entry'!H$5:H$59)),"") | G8: =IFERROR(SUMPRODUCT(('Sales Entry'!B$5:B$59=B8)*('Sales Entry'!I$5:I$59="Card")*('Sales Entry'!H$5:H$59)),"") | H8: =IFERROR(SUMPRODUCT(('Sales Entry'!B$5:B$59=B8)*('Sales Entry'!I$5:I$59="Online")*('Sales Entry'!H$5:H$59)),"")
B9: 45662 | C9: =IFERROR(SUMPRODUCT(('Sales Entry'!B$5:B$59=B9)*('Sales Entry'!H$5:H$59)),"") | D9: =IFERROR(SUMPRODUCT(('Sales Entry'!B$5:B$59=B9)*1),"") | E9: =IFERROR(C9/D9,"") | F9: =IFERROR(SUMPRODUCT(('Sales Entry'!B$5:B$59=B9)*('Sales Entry'!I$5:I$59="Cash")*('Sales Entry'!H$5:H$59)),"") | G9: =IFERROR(SUMPRODUCT(('Sales Entry'!B$5:B$59=B9)*('Sales Entry'!I$5:I$59="Card")*('Sales Entry'!H$5:H$59)),"") | H9: =IFERROR(SUMPRODUCT(('Sales Entry'!B$5:B$59=B9)*('Sales Entry'!I$5:I$59="Online")*('Sales Entry'!H$5:H$59)),"")
B10: 45663 | C10: =IFERROR(SUMPRODUCT(('Sales Entry'!B$5:B$59=B10)*('Sales Entry'!H$5:H$59)),"") | D10: =IFERROR(SUMPRODUCT(('Sales Entry'!B$5:B$59=B10)*1),"") | E10: =IFERROR(C10/D10,"") | F10: =IFERROR(SUMPRODUCT(('Sales Entry'!B$5:B$59=B10)*('Sales Entry'!I$5:I$59="Cash")*('Sales Entry'!H$5:H$59)),"") | G10: =IFERROR(SUMPRODUCT(('Sales Entry'!B$5:B$59=B10)*('Sales Entry'!I$5:I$59="Card")*('Sales Entry'!H$5:H$59)),"") | H10: =IFERROR(SUMPRODUCT(('Sales Entry'!B$5:B$59=B10)*('Sales Entry'!I$5:I$59="Online")*('Sales Entry'!H$5:H$59)),"")
B11: 45664 | C11: =IFERROR(SUMPRODUCT(('Sales Entry'!B$5:B$59=B11)*('Sales Entry'!H$5:H$59)),"") | D11: =IFERROR(SUMPRODUCT(('Sales Entry'!B$5:B$59=B11)*1),"") | E11: =IFERROR(C11/D11,"") | F11: =IFERROR(SUMPRODUCT(('Sales Entry'!B$5:B$59=B11)*('Sales Entry'!I$5:I$59="Cash")*('Sales Entry'!H$5:H$59)),"") | G11: =IFERROR(SUMPRODUCT(('Sales Entry'!B$5:B$59=B11)*('Sales Entry'!I$5:I$59="Card")*('Sales Entry'!H$5:H$59)),"") | H11: =IFERROR(SUMPRODUCT(('Sales Entry'!B$5:B$59=B11)*('Sales Entry'!I$5:I$59="Online")*('Sales Entry'!H$5:H$59)),"")
B12: 45665 | C12: =IFERROR(SUMPRODUCT(('Sales Entry'!B$5:B$59=B12)*('Sales Entry'!H$5:H$59)),"") | D12: =IFERROR(SUMPRODUCT(('Sales Entry'!B$5:B$59=B12)*1),"") | E12: =IFERROR(C12/D12,"") | F12: =IFERROR(SUMPRODUCT(('Sales Entry'!B$5:B$59=B12)*('Sales Entry'!I$5:I$59="Cash")*('Sales Entry'!H$5:H$59)),"") | G12: =IFERROR(SUMPRODUCT(('Sales Entry'!B$5:B$59=B12)*('Sales Entry'!I$5:I$59="Card")*('Sales Entry'!H$5:H$59)),"") | H12: =IFERROR(SUMPRODUCT(('Sales Entry'!B$5:B$59=B12)*('Sales Entry'!I$5:I$59="Online")*('Sales Entry'!H$5:H$59)),"")
B13: 45666 | C13: =IFERROR(SUMPRODUCT(('Sales Entry'!B$5:B$59=B13)*('Sales Entry'!H$5:H$59)),"") | D13: =IFERROR(SUMPRODUCT(('Sales Entry'!B$5:B$59=B13)*1),"") | E13: =IFERROR(C13/D13,"") | F13: =IFERROR(SUMPRODUCT(('Sales Entry'!B$5:B$59=B13)*('Sales Entry'!I$5:I$59="Cash")*('Sales Entry'!H$5:H$59)),"") | G13: =IFERROR(SUMPRODUCT(('Sales Entry'!B$5:B$59=B13)*('Sales Entry'!I$5:I$59="Card")*('Sales Entry'!H$5:H$59)),"") | H13: =IFERROR(SUMPRODUCT(('Sales Entry'!B$5:B$59=B13)*('Sales Entry'!I$5:I$59="Online")*('Sales Entry'!H$5:H$59)),"")
B14: 45667 | C14: =IFERROR(SUMPRODUCT(('Sales Entry'!B$5:B$59=B14)*('Sales Entry'!H$5:H$59)),"") | D14: =IFERROR(SUMPRODUCT(('Sales Entry'!B$5:B$59=B14)*1),"") | E14: =IFERROR(C14/D14,"") | F14: =IFERROR(SUMPRODUCT(('Sales Entry'!B$5:B$59=B14)*('Sales Entry'!I$5:I$59="Cash")*('Sales Entry'!H$5:H$59)),"") | G14: =IFERROR(SUMPRODUCT(('Sales Entry'!B$5:B$59=B14)*('Sales Entry'!I$5:I$59="Card")*('Sales Entry'!H$5:H$59)),"") | H14: =IFERROR(SUMPRODUCT(('Sales Entry'!B$5:B$59=B14)*('Sales Entry'!I$5:I$59="Online")*('Sales Entry'!H$5:H$59)),"")
B15: 45668 | C15: =IFERROR(SUMPRODUCT(('Sales Entry'!B$5:B$59=B15)*('Sales Entry'!H$5:H$59)),"") | D15: =IFERROR(SUMPRODUCT(('Sales Entry'!B$5:B$59=B15)*1),"") | E15: =IFERROR(C15/D15,"") | F15: =IFERROR(SUMPRODUCT(('Sales Entry'!B$5:B$59=B15)*('Sales Entry'!I$5:I$59="Cash")*('Sales Entry'!H$5:H$59)),"") | G15: =IFERROR(SUMPRODUCT(('Sales Entry'!B$5:B$59=B15)*('Sales Entry'!I$5:I$59="Card")*('Sales Entry'!H$5:H$59)),"") | H15: =IFERROR(SUMPRODUCT(('Sales Entry'!B$5:B$59=B15)*('Sales Entry'!I$5:I$59="Online")*('Sales Entry'!H$5:H$59)),"")
B16: 45669 | C16: =IFERROR(SUMPRODUCT(('Sales Entry'!B$5:B$59=B16)*('Sales Entry'!H$5:H$59)),"") | D16: =IFERROR(SUMPRODUCT(('Sales Entry'!B$5:B$59=B16)*1),"") | E16: =IFERROR(C16/D16,"") | F16: =IFERROR(SUMPRODUCT(('Sales Entry'!B$5:B$59=B16)*('Sales Entry'!I$5:I$59="Cash")*('Sales Entry'!H$5:H$59)),"") | G16: =IFERROR(SUMPRODUCT(('Sales Entry'!B$5:B$59=B16)*('Sales Entry'!I$5:I$59="Card")*('Sales Entry'!H$5:H$59)),"") | H16: =IFERROR(SUMPRODUCT(('Sales Entry'!B$5:B$59=B16)*('Sales Entry'!I$5:I$59="Online")*('Sales Entry'!H$5:H$59)),"")
... B35: 45688 | C35: =IFERROR(SUMPRODUCT(('Sales Entry'!B$5:B$59=B35)*('Sales Entry'!H$5:H$59)),"") | D35: =IFERROR(SUMPRODUCT(('Sales Entry'!B$5:B$59=B35)*1),"") | E35: =IFERROR(C35/D35,"") | F35: =IFERROR(SUMPRODUCT(('Sales Entry'!B$5:B$59=B35)*('Sales Entry'!I$5:I$59="Cash")*('Sales Entry'!H$5:H$59)),"") | G35: =IFERROR(SUMPRODUCT(('Sales Entry'!B$5:B$59=B35)*('Sales Entry'!I$5:I$59="Card")*('Sales Entry'!H$5:H$59)),"") | H35: =IFERROR(SUMPRODUCT(('Sales Entry'!B$5:B$59=B35)*('Sales Entry'!I$5:I$59="Online")*('Sales Entry'!H$5:H$59)),"")
B36: TOTALS | C36: =IFERROR(SUM(C5:C35),"") | D36: =IFERROR(SUM(D5:D35),"") | E36: =IFERROR(C36/D36,"") | F36: =IFERROR(SUM(F5:F35),"") | G36: =IFERROR(SUM(G5:G35),"") | H36: =IFERROR(SUM(H5:H35),"")

Sheet Weekly Summary
B2: Weekly Summary
B4: Week # | C4: Week Start Date | D4: Week End Date | E4: Total Sales | F4: # Transactions | G4: Avg Transaction
B5: 1 | C5: 45658 | D5: 45662 | E5: =IFERROR(SUMPRODUCT(('Daily Summary'!B$5:B$35>=C5)*('Daily Summary'!B$5:B$35<=D5)*('Daily Summary'!C$5:C$35)),"") | F5: =IFERROR(SUMPRODUCT(('Daily Summary'!B$5:B$35>=C5)*('Daily Summary'!B$5:B$35<=D5)*('Daily Summary'!D$5:D$35)),"") | G5: =IFERROR(E5/F5,"")
B6: 2 | C6: 45663 | D6: 45669 | E6: =IFERROR(SUMPRODUCT(('Daily Summary'!B$5:B$35>=C6)*('Daily Summary'!B$5:B$35<=D6)*('Daily Summary'!C$5:C$35)),"") | F6: =IFERROR(SUMPRODUCT(('Daily Summary'!B$5:B$35>=C6)*('Daily Summary'!B$5:B$35<=D6)*('Daily Summary'!D$5:D$35)),"") | G6: =IFERROR(E6/F6,"")
B7: 3 | C7: 45670 | D7: 45676 | E7: =IFERROR(SUMPRODUCT(('Daily Summary'!B$5:B$35>=C7)*('Daily Summary'!B$5:B$35<=D7)*('Daily Summary'!C$5:C$35)),"") | F7: =IFERROR(SUMPRODUCT(('Daily Summary'!B$5:B$35>=C7)*('Daily Summary'!B$5:B$35<=D7)*('Daily Summary'!D$5:D$35)),"") | G7: =IFERROR(E7/F7,"")
B8: 4 | C8: 45677 | D8: 45683 | E8: =IFERROR(SUMPRODUCT(('Daily Summary'!B$5:B$35>=C8)*('Daily Summary'!B$5:B$35<=D8)*('Daily Summary'!C$5:C$35)),"") | F8: =IFERROR(SUMPRODUCT(('Daily Summary'!B$5:B$35>=C8)*('Daily Summary'!B$5:B$35<=D8)*('Daily Summary'!D$5:D$35)),"") | G8: =IFERROR(E8/F8,"")
B9: 5 | C9: 45684 | D9: 45688 | E9: =IFERROR(SUMPRODUCT(('Daily Summary'!B$5:B$35>=C9)*('Daily Summary'!B$5:B$35<=D9)*('Daily Summary'!C$5:C$35)),"") | F9: =IFERROR(SUMPRODUCT(('Daily Summary'!B$5:B$35>=C9)*('Daily Summary'!B$5:B$35<=D9)*('Daily Summary'!D$5:D$35)),"") | G9: =IFERROR(E9/F9,"")
B10: TOTALS | E10: =IFERROR(SUM(E5:E9),"") | F10: =IFERROR(SUM(F5:F9),"") | G10: =IFERROR(E10/F10,"")

Sheet Monthly Summary
B2: Monthly Summary
B4: Month | C4: Total Sales | D4: # Transactions | E4: Avg Transaction | F4: Best Day Sales | G4: Best Day Date
B5: January 2025 | C5: =IFERROR(SUMPRODUCT(('Daily Summary'!C$5:C$35)),"") | D5: =IFERROR(SUMPRODUCT(('Daily Summary'!D$5:D$35)),"") | E5: =IFERROR(C5/D5,"") | F5: =IFERROR(MAX('Daily Summary'!C$5:C$35),"") | G5: =IFERROR(SUMPRODUCT(('Daily Summary'!C$5:C$35=F5)*('Daily Summary'!B$5:B$35)),"")
B6: TOTALS | C6: =IFERROR(SUM(C5:C5),"") | D6: =IFERROR(SUM(D5:D5),"") | E6: =IFERROR(C6/D6,"")

Sheet Invoice
B2: Al Madina Restaurant
B3: Al Quoz Industrial Area 3, Dubai, UAE | Tel: +971 4 123 4567 | info@almadina.ae
B5: INVOICE
B7: Invoice # | C7: INV-0025
B8: Date | C8: 45672
B9: Customer | C9: Walk-in
B10: Payment | C10: Cash
E12: Item | F12: Qty | G12: Price (AED) | H12: Total (AED)
E13: Coffee | F13: 2 | G13: 15 | H13: =IFERROR(F13*G13,"")
E14: Sandwich | F14: 1 | G14: 25 | H14: =IFERROR(F14*G14,"")
E15: Salad | F15: 1 | G15: 30 | H15: =IFERROR(F15*G15,"")
E16: Fresh Juice | F16: 2 | G16: 18 | H16: =IFERROR(F16*G16,"")
E17: Cake | F17: 1 | G17: 22 | H17: =IFERROR(F17*G17,"")
G19: Subtotal | H19: =IFERROR(SUM(H13:H17),"")
G20: VAT 5% | H20: =IFERROR(H19*0.05,"")
G21: Grand Total | H21: =IFERROR(H19+H20,"")
B23: Thank you for dining with us!
B24: TRN: 10001 23456 7890 1234 | VAT Registration No: AE123456789012345

Sheet Product List
B2: Product List
B4: Product ID | C4: Item Name | D4: Category | E4: Unit Price | F4: Description
B5: P001 | C5: Coffee | D5: Beverages | E5: 15 | F5: Freshly brewed Arabic coffee
B6: P002 | C6: Tea | D6: Beverages | E6: 10 | F6: Karak chai with spices
B7: P003 | C7: Fresh Juice | D7: Beverages | E7: 18 | F7: Freshly squeezed orange juice
B8: P004 | C8: Smoothie | D8: Beverages | E8: 22 | F8: Mixed berry smoothie
B9: P005 | C9: Water | D9: Beverages | E9: 5 | F9: Mineral water 500ml
B10: P006 | C10: Soft Drink | D10: Beverages | E10: 8 | F10: Carbonated soft drink
B11: P007 | C11: Sandwich | D11: Main Course | E11: 25 | F11: Grilled chicken sandwich
B12: P008 | C12: Burger | D12: Main Course | E12: 35 | F12: Classic beef burger with fries
B13: P009 | C13: Pasta | D13: Main Course | E13: 45 | F13: Creamy Alfredo pasta
B14: P010 | C14: Grilled Chicken | D14: Main Course | E14: 55 | F14: Herb-marinated grilled chicken
B15: P011 | C15: Shawarma | D15: Main Course | E15: 30 | F15: Chicken shawarma wrap
B16: P012 | C16: Biryani | D16: Main Course | E16: 40 | F16: Hyderabadi chicken biryani
... B28: P024 | C28: Manakish | D28: Appetizers | E28: 16 | F28: Zaatar and cheese manakish
B29: TOTALS | C29: =COUNTA(C5:C28)&" items" | E29: =IFERROR(SUM(E5:E28),"")
